Workbook
Name Augusttotalinfracash: Calculations!#REF!
Name BalAug: Calculations!#REF!
Name Excessinfracash2023: final!$H$1
Name FL: [1]Calculations!$G$43
Name FL_Total: 'Loan Applicants'!#REF!
Name FLAUGUST2024: Calculations!$D$32
Name INFINVEST: [1]Shares!$B$4:$Z$41
Name INFINVEST: Summary!$B$4:$Z$26
Name INFINVEST: Shares!$B$4:$Z$28
Name INFMO: [1]Shares!$B$4:$Z$41
Name INFMONEYSHARES: [1]Shares!$B$4:$Z$42
Name infracashexcess2024: 'REDLIST ALERT'!$D$38
Name INFRACASHshares2025: Shares!$B$4:$Z$29
Name INFRCASHTOTALSHARE2023: Shares!$Y$31
Name INFSHARES: Shares!$B$4:$X$29
Name INFSHARES: Summary!$B$4:$X$33
Name INFSHARES: Shares!$B$4:$X$28
Name INFTOTAL: Shares!$Y$31
Name INFTOTAL: Summary!$Y$34
Name INFTOTAL: Shares!$Y$30
Name loan: 'New Repayment Schedule'!$H$6:$DD$30
Name LOANTOTAL: #REF!
Name LOANTOTAL: #REF!
Name TotalFL: Summary!$Y$36
Name TotalFL: Shares!$Y$32
Name Totalinfracash2024: Shares!$Y$30-Shares!$Y$29
Name TOTALLOAN: 'LOAN BALANCE'!$B$3:$M$33

Sheet Shares
B2: MEETING | C2: NOVEMBER | E2: DECEMBER | G2: JANUARY | I2: FEBUARY | K2: MARCH | M2: APRIL | O2: MAY | Q2: JUNE | S2: JULY | U2: AUGUST
A3: No | B3: FULL NAMES | C3: SHARES | D3: TOTAL | E3: SHARES | F3: TOTAL | G3: SHARES | H3: TOTAL | I3: SHARES | J3: TOTAL | K3: SHARES | L3: TOTAL | M3: SHARES | N3: TOTAL | O3: SHARES | P3: TOTAL | Q3: SHARES | R3: TOTAL | S3: SHARES | T3: TOTAL | U3: SHARES | V3: TOTAL | X3: GRAND SHARES | Y3: GRAND TOTAL INVESTED | Z3: LOAN ELIGIBILTY
A4: 1 | B4: Abigail Mundia | C4: =D4/200 -> 1 | D4: 200 | E4: =F4/200 -> 75 | F4: 15000 | G4: =H4/200 -> 1 | H4: 200 | I4: =J4/200 -> 1 | J4: 200 | K4: =L4/200 -> 50 | L4: 10000 | M4: =N4/200 -> 1 | N4: 200 | O4: =P4/200 -> 1 | P4: 200 | Q4: =R4/200 -> 1 | R4: 200 | S4: =T4/200 -> 1 | T4: 200 | U4: =V4/200 -> 5 | V4: 1000 | Y4: =D4+F4+H4+J4+L4+N4+P4+R4+T4+V4 -> 27400 | Z4: =Y4*3 -> 82200 | AA4: {=Y4/Totalinfracash2024} -> 0.063455303
A5: 2 | B5: Abel Kunda | C5: =D5/200 -> 0 | E5: =F5/200 -> 0 | G5: =H5/200 -> 0 | I5: =J5/200 -> 0 | K5: =L5/200 -> 240 | L5: 48000 | M5: =N5/200 -> 1 | N5: 200 | O5: =P5/200 -> 1 | P5: 200 | Q5: =R5/200 -> 1 | R5: 200 | S5: =T5/200 -> 1 | T5: 200 | U5: =V5/200 -> 1 | V5: 200 | Y5: =D5+F5+H5+J5+L5+N5+P5+R5+T5+V5 -> 49000 | Z5: =Y5*3 -> 147000 | AA5: {=Y5/Totalinfracash2024} -> 0.11347846
A6: 3 | B6: Andrew | C6: =D6/200 -> 6 | D6: 1200 | E6: =F6/200 -> 1 | F6: 200 | G6: =H6/200 -> 1 | H6: 200 | I6: =J6/200 -> 1 | J6: 200 | K6: =L6/200 -> 15 | L6: 3000 | M6: =N6/200 -> 1 | N6: 200 | O6: =P6/200 -> 1 | P6: 200 | Q6: =R6/200 -> 1 | R6: 200 | S6: =T6/200 -> 1 | T6: 200 | U6: =V6/200 -> 1 | V6: 200 | Y6: =D6+F6+H6+J6+L6+N6+P6+R6+T6+V6 -> 5800 | Z6: =Y6*3 -> 17400 | AA6: {=Y6/Totalinfracash2024} -> 0.013432145
A7: 4 | B7: Arthur | C7: =D7/200 -> 1 | D7: 200 | E7: =F7/200 -> 1 | F7: 200 | G7: =H7/200 -> 2 | H7: 400 | I7: =J7/200 -> 1 | J7: 200 | K7: =L7/200 -> 2 | L7: 400 | M7: =N7/200 -> 2 | N7: 400 | O7: =P7/200 -> 5 | P7: 1000 | Q7: =R7/200 -> 15 | R7: 3000 | S7: =T7/200 -> 1 | T7: 200 | U7: =V7/200 -> 1 | V7: 200 | Y7: =D7+F7+H7+J7+L7+N7+P7+R7+T7+V7 -> 6200 | Z7: =Y7*3 -> 18600 | AA7: {=Y7/Totalinfracash2024} -> 0.014358499
A8: 5 | B8: Evans | C8: =D8/200 -> 25 | D8: 5000 | E8: =F8/200 -> 1 | F8: 200 | G8: =H8/200 -> 10 | H8: 2000 | I8: =J8/200 -> 1 | J8: 200 | K8: =L8/200 -> 1 | L8: 200 | M8: =N8/200 -> 10 | N8: 2000 | O8: =P8/200 -> 1 | P8: 200 | Q8: =R8/200 -> 1 | R8: 200 | S8: =T8/200 -> 1 | T8: 200 | U8: =V8/200 -> 1 | V8: 200 | Y8: =D8+F8+H8+J8+L8+N8+P8+R8+T8+V8 -> 10400 | Z8: =Y8*3 -> 31200 | AA8: {=Y8/Totalinfracash2024} -> 0.024085225
A9: 6 | B9: Jesper | C9: =D9/200 -> 1 | D9: 200 | E9: =F9/200 -> 1 | F9: 200 | G9: =H9/200 -> 1 | H9: 200 | I9: =J9/200 -> 1 | J9: 200 | K9: =L9/200 -> 1 | L9: 200 | M9: =N9/200 -> 1 | N9: 200 | O9: =P9/200 -> 1 | P9: 200 | Q9: =R9/200 -> 2 | R9: 400 | S9: =T9/200 -> 1 | T9: 200 | U9: =V9/200 -> 1 | V9: 200 | Y9: =D9+F9+H9+J9+L9+N9+P9+R9+T9+V9 -> 2200 | Z9: =Y9*3 -> 6600 | AA9: {=Y9/Totalinfracash2024} -> 0.0050949514
A10: 7 | B10: Joshua | C10: =D10/200 -> 1 | D10: 200 | E10: =F10/200 -> 1 | F10: 200 | G10: =H10/200 -> 1 | H10: 200 | I10: =J10/200 -> 1 | J10: 200 | K10: =L10/200 -> 1 | L10: 200 | M10: =N10/200 -> 1 | N10: 200 | O10: =P10/200 -> 1 | P10: 200 | Q10: =R10/200 -> 50 | R10: 10000 | S10: =T10/200 -> 5 | T10: 1000 | U10: =V10/200 -> 5 | V10: 1000 | Y10: =D10+F10+H10+J10+L10+N10+P10+R10+T10+V10 -> 13400 | Z10: =Y10*3 -> 40200 | AA10: {=Y10/Totalinfracash2024} -> 0.031032886
A11: 8 | B11: Kampamba | C11: =D11/200 -> 2 | D11: 400 | E11: =F11/200 -> 2 | F11: 400 | G11: =H11/200 -> 6 | H11: 1200 | I11: =J11/200 -> 2 | J11: 400 | K11: =L11/200 -> 2 | L11: 400 | M11: =N11/200 -> 18 | N11: 3600 | O11: =P11/200 -> 1 | P11: 200 | Q11: =R11/200 -> 1 | R11: 200 | S11: =T11/200 -> 1 | T11: 200 | U11: =V11/200 -> 2 | V11: 400 | Y11: =D11+F11+H11+J11+L11+N11+P11+R11+T11+V11 -> 7400 | Z11: =Y11*3 -> 22200 | AA11: {=Y11/Totalinfracash2024} -> 0.017137564
A12: 9 | B12: Karen Mwinga | C12: =D12/200 -> 5 | D12: 1000 | E12: =F12/200 -> 1 | F12: 200 | G12: =H12/200 -> 1 | H12: 200 | I12: =J12/200 -> 1 | J12: 200 | K12: =L12/200 -> 5 | L12: 1000 | M12: =N12/200 -> 1 | N12: 200 | O12: =P12/200 -> 5 | P12: 1000 | Q12: =R12/200 -> 5 | R12: 1000 | S12: =T12/200 -> 1 | T12: 200 | U12: =V12/200 -> 1 | V12: 200 | Y12: =D12+F12+H12+J12+L12+N12+P12+R12+T12+V12 -> 5200 | Z12: =Y12*3 -> 15600 | AA12: {=Y12/Totalinfracash2024} -> 0.012042612
A13: 10 | B13: Keji | C13: =D13/200 -> 1 | D13: 200 | E13: =F13/200 -> 1 | F13: 200 | G13: =H13/200 -> 1 | H13: 200 | I13: =J13/200 -> 24 | J13: 4800 | K13: =L13/200 -> 1 | L13: 200 | M13: =N13/200 -> 1 | N13: 200 | O13: =P13/200 -> 1 | P13: 200 | Q13: =R13/200 -> 1 | R13: 200 | S13: =T13/200 -> 1 | T13: 200 | U13: =V13/200 -> 1 | V13: 200 | Y13: =D13+F13+H13+J13+L13+N13+P13+R13+T13+V13 -> 6600 | Z13: =Y13*3 -> 19800 | AA13: {=Y13/Totalinfracash2024} -> 0.015284854
A14: 11 | B14: Kombe | C14: =D14/200 -> 1 | D14: 200 | E14: =F14/200 -> 1 | F14: 200 | G14: =H14/200 -> 1 | H14: 200 | I14: =J14/200 -> 1 | J14: 200 | K14: =L14/200 -> 75 | L14: 15000 | M14: =N14/200 -> 1 | N14: 200 | O14: =P14/200 -> 75 | P14: 15000 | Q14: =R14/200 -> 2 | R14: 400 | S14: =T14/200 -> 1 | T14: 200 | U14: =V14/200 -> 1 | V14: 200 | Y14: =D14+F14+H14+J14+L14+N14+P14+R14+T14+V14 -> 31800 | Z14: =Y14*3 -> 95400 | AA14: {=Y14/Totalinfracash2024} -> 0.073645206
A15: 12 | B15: Khucwayo | C15: =D15/200 -> 1 | D15: 200 | E15: =F15/200 -> 2 | F15: 400 | G15: =H15/200 -> 1 | H15: 200 | I15: =J15/200 -> 1 | J15: 200 | K15: =L15/200 -> 1 | L15: 200 | M15: =N15/200 -> 1 | N15: 200 | O15: =P15/200 -> 1 | P15: 200 | Q15: =R15/200 -> 2 | R15: 400 | S15: =T15/200 -> 5 | T15: 1000 | U15: =V15/200 -> 1 | V15: 200 | Y15: =D15+F15+H15+J15+L15+N15+P15+R15+T15+V15 -> 3200 | Z15: =Y15*3 -> 9600 | AA15: {=Y15/Totalinfracash2024} -> 0.0074108384
A16: 13 | B16: Kwibisa | C16: =D16/200 -> 25 | D16: 5000 | E16: =F16/200 -> 1 | F16: 200 | G16: =H16/200 -> 1 | H16: 200 | I16: =J16/200 -> 1 | J16: 200 | K16: =L16/200 -> 1 | L16: 200 | M16: =N16/200 -> 1 | N16: 200 | O16: =P16/200 -> 5 | P16: 1000 | Q16: =R16/200 -> 1 | R16: 200 | S16: =T16/200 -> 1 | T16: 200 | U16: =V16/200 -> 1 | V16: 200 | Y16: =D16+F16+H16+J16+L16+N16+P16+R16+T16+V16 -> 7600 | Z16: =Y16*3 -> 22800 | AA16: {=Y16/Totalinfracash2024} -> 0.017600741
A17: 14 | B17: Michael | C17: =D17/200 -> 25 | D17: 5000 | E17: =F17/200 -> 25 | F17: 5000 | G17: =H17/200 -> 25 | H17: 5000 | I17: =J17/200 -> 25 | J17: 5000 | K17: =L17/200 -> 50 | L17: 10000 | M17: =N17/200 -> 25 | N17: 5000 | O17: =P17/200 -> 25 | P17: 5000 | Q17: =R17/200 -> 25 | R17: 5000 | S17: =T17/200 -> 18 | T17: 3600 | U17: =V17/200 -> 1 | V17: 200 | Y17: =D17+F17+H17+J17+L17+N17+P17+R17+T17+V17 -> 48800 | Z17: =Y17*3 -> 146400 | AA17: {=Y17/Totalinfracash2024} -> 0.11301528
... A25: 22 | B25: Schuller | C25: =D25/200 -> 25 | D25: 5000 | E25: =F25/200 -> 50 | F25: 10000 | G25: =H25/200 -> 5 | H25: 1000 | I25: =J25/200 -> 25 | J25: 5000 | K25: =L25/200 -> 25 | L25: 5000 | M25: =N25/200 -> 5 | N25: 1000 | O25: =P25/200 -> 5 | P25: 1000 | Q25: =R25/200 -> 10 | R25: 2000 | S25: =T25/200 -> 10 | T25: 2000 | U25: =V25/200 -> 1 | V25: 200 | Y25: =D25+F25+H25+J25+L25+N25+P25+R25+T25+V25 -> 32200 | Z25: =Y25*3 -> 96600 | AA25: {=Y25/Totalinfracash2024} -> 0.074571561
A26: 23 | B26: Shubart | C26: =D26/200 -> 25 | D26: 5000 | E26: =F26/200 -> 5 | F26: 1000 | G26: =H26/200 -> 5 | H26: 1000 | I26: =J26/200 -> 10 | J26: 2000 | K26: =L26/200 -> 5 | L26: 1000 | M26: =N26/200 -> 1 | N26: 200 | O26: =P26/200 -> 1 | P26: 200 | Q26: =R26/200 -> 0 | S26: =T26/200 -> 1 | T26: 200 | U26: =V26/200 -> 2 | V26: 400 | Y26: =D26+F26+H26+J26+L26+N26+P26+R26+T26+V26 -> 11000 | Z26: =Y26*3 -> 33000 | AA26: {=Y26/Totalinfracash2024} -> 0.025474757
A27: 24 | B27: Solomon | C27: =D27/200 -> 10 | D27: 2000 | E27: =F27/200 -> 20 | F27: 4000 | G27: =H27/200 -> 5 | H27: 1000 | I27: =J27/200 -> 1 | J27: 200 | K27: =L27/200 -> 1 | L27: 200 | M27: =N27/200 -> 2 | N27: 400 | O27: =P27/200 -> 3 | P27: 600 | Q27: =R27/200 -> 3 | R27: 600 | S27: =T27/200 -> 1 | T27: 200 | U27: =V27/200 -> 1 | V27: 200 | Y27: =D27+F27+H27+J27+L27+N27+P27+R27+T27+V27 -> 9400 | Z27: =Y27*3 -> 28200 | AA27: {=Y27/Totalinfracash2024} -> 0.021769338
A28: 25 | B28: Tumelo | C28: =D28/200 -> 1 | D28: 200 | E28: =F28/200 -> 0 | I28: =J28/200 -> 0 | K28: =L28/200 -> 0 | M28: =N28/200 -> 0 | O28: =P28/200 -> 0 | Q28: =R28/200 -> 0 | S28: =T28/200 -> 0 | U28: =V28/200 -> 0 | Y28: =D28+F28+H28+J28+L28+N28+P28+R28+T28+V28 -> 200 | Z28: =Y28*3 -> 600 | AA28: {=Y28/Totalinfracash2024} -> 0.0004631774
A29: 26 | B29: INSURANCE | C29: =D29/200 -> 23 | D29: 4600 | E29: =F29/200 -> 23 | F29: 4600 | H29: 4600 | I29: =J29/200 -> 23 | J29: 4600 | K29: =L29/200 -> 24 | L29: 4800 | M29: =N29/200 -> 23 | N29: 4600 | O29: =P29/200 -> 0 | Q29: =R29/200 -> 0 | S29: =T29/200 -> 0 | U29: =V29/200 -> 0 | Y29: =D29+F29+H29+J29+L29+N29+P29+R29+T29+V29 -> 27800 | Z29: =Y29*3 -> 83400
B30: TOTAL | C30: =SUM(C4:C29) -> 238 | D30: =SUM(D4:D29) -> 47600 | E30: =SUM(E4:E28) -> 279 | F30: =SUM(F4:F29) -> 60400 | G30: =SUM(G4:G28) -> 168 | H30: =SUM(H4:H29) -> 38200 | I30: =J30/200 -> 259 | J30: =SUM(J4:J29) -> 51800 | K30: =SUM(K4:K27) -> 729 | L30: =SUM(L4:L29) -> 150600 | M30: =SUM(M4:M28) -> 85 | N30: =SUM(N4:N29) -> 21600 | O30: =SUM(O4:O27) -> 166 | P30: =SUM(P4:P28) -> 33200 | Q30: =SUM(Q4:Q27) -> 151 | R30: =SUM(R4:R28) -> 30200 | S30: =SUM(S4:S28) -> 80 | T30: =SUM(T4:T28) -> 16000 | U30: =SUM(U4:U27) -> 50 | V30: =SUM(V4:V28) -> 10000 | X30: =SUM(X4:X27) -> 0 | Y30: =SUM(Y4:Y29) -> 459600 | AA30: =SUM(AA4:AA28) -> 1

Sheet final
B1: MEETING | H1: =34916.9337259358-8200 -> 26716.934 | J1: =111201.71-1700 -> 109501.71 | K1: =22545-1200 -> 21345 | L1: =41125.2272078665-1700 -> 39425.227 | M1: =24813.2726452535-1200 -> 23613.273 | N1: =74495.0870519596-1200 -> 73295.087 | O1: =35832.9524290763-1200 -> 34632.952
A2: No | B2: FULL NAMES | C2: SHARES OUT | D2: TOTAL | E2: SHARE-LOAN | F2: PEOPLE GET SHAREOUT | G2: REDLIST | H2: Excess | I2: Total SHARE+ EXCESS | J2: Nyanyiwe | K2: Mwenya | L2: Evans | M2: Karen Mwinga | N2: Pamela | O2: Kwibisa
A3: 1 | B3: Abigail Mundia | C3: =Shareout!C85 -> 41458.426 | D3: ='New Repayment Schedule'!DC6 -> 75216.482 | E3: =C3-D3 -> -33758.056 | H3: =Excessinfracash2023*Shares!AA4 -> 1695.3311 | I3: =F3+H3 -> 1695.3311 | J3: =I3 -> 1695.3311 | P3: =SUM(J3:O3)-I3 -> 0
A4: 2 | B4: Andrew | C4: =Shareout!K85 -> 8404.5446 | D4: ='New Repayment Schedule'!DC8 -> 1141.2562 | E4: =C4-D4 -> 7263.2884 | F4: =E4 -> 7263.2884 | H4: =Excessinfracash2023*Shares!AA6 -> 358.86571 | I4: =F4+H4 -> 7622.1541 | K4: =I4 -> 7622.1541 | P4: =SUM(J4:O4)-I4 -> 0
A5: 3 | B5: Arthur | C5: =Shareout!O85 -> 8039.3018 | D5: ='New Repayment Schedule'!DC9 -> 5351.8097 | E5: =C5-D5 -> 2687.4921 | H5: =Excessinfracash2023*Shares!AA7 -> 383.61507 | I5: =F5+H5 -> 383.61507 | O5: =I5 -> 383.61507 | P5: =SUM(J5:O5)-I5 -> 0
A6: 4 | B6: Benson | C6: =Shareout!#REF! -> #REF! | D6: ='New Repayment Schedule'!DC10 -> 10566.477 | E6: =C6-D6 -> #REF! | H6: =Excessinfracash2023*Shares!AA8 -> 643.48335 | I6: =F6+H6 -> 643.48335 | N6: =I6 -> 643.48335 | P6: =SUM(J6:O6)-I6 -> 0
A7: 5 | B7: Davies | C7: =Shareout!#REF! -> #REF! | D7: ='New Repayment Schedule'!DC11 -> -4.1813014 | E7: =C7-D7 -> #REF! | G7: =E7*-1 -> #REF! | H7: =Excessinfracash2023*Shares!AA9 -> 136.12148 | I7: =F7+H7 -> 136.12148 | J7: =I7 -> 136.12148 | P7: =SUM(J7:O7)-I7 -> 0
A8: 7 | B8: Evans | C8: =Shareout!S85 -> 16150.911 | D8: ='New Repayment Schedule'!DC12 -> 12127.5 | E8: =C8-D8 -> 4023.4106 | H8: =Excessinfracash2023*Shares!AA10 -> 829.10355 | I8: =F8+H8 -> 829.10355 | J8: 210.21719 | K8: 219.87296 | L8: =I8 -> 829.10355 | M8: 215.65521 | N8: 21.688566 | O8: 117.26163 | P8: =SUM(J8:O8)-I8 -> 784.69557
A9: 8 | B9: Gilbert | C9: =Shareout!#REF! -> #REF! | D9: ='New Repayment Schedule'!DC13 -> 13494.111 | E9: =C9-D9 -> #REF! | H9: =Excessinfracash2023*Shares!AA11 -> 457.86315 | I9: =F9+H9 -> 457.86315 | L9: =I9 -> 457.86315 | P9: =SUM(J9:O9)-I9 -> 0
A10: 9 | B10: Jesper Chola | C10: =Shareout!X85 -> 3009.6864 | D10: ='New Repayment Schedule'!DC14 -> 4847.7509 | E10: =C10-D10 -> -1838.0646 | F10: =E10 -> -1838.0646 | H10: =Excessinfracash2023*Shares!AA12 -> 321.74168 | I10: =F10+H10 -> -1516.3229 | J10: =I10 -> -1516.3229 | P10: =SUM(J10:O10)-I10 -> 0
A11: 10 | B11: Joshua | C11: =Shareout!AB85 -> 16456.086 | D11: ='New Repayment Schedule'!DC15 -> 10586.081 | E11: =C11-D11 -> 5870.0057 | F11: =E11 -> 5870.0057 | H11: =Excessinfracash2023*Shares!AA13 -> 408.36443 | I11: =F11+H11 -> 6278.3702 | K11: =I11 -> 6278.3702 | P11: =SUM(J11:O11)-I11 -> 0
A12: 11 | B12: Kampamba | C12: =Shareout!AF85 -> 10322.876 | D12: ='New Repayment Schedule'!DC16 -> 83718.175 | E12: =C12-D12 -> -73395.3 | H12: =Excessinfracash2023*Shares!AA14 -> 1967.5741 | I12: =F12+H12 -> 1967.5741 | J12: =I12 -> 1967.5741 | P12: =SUM(J12:O12)-I12 -> 0
A13: 12 | B13: Karen Mwinga | C13: =Shareout!AJ85 -> 7244.343 | D13: ='New Repayment Schedule'!DC17 -> -416.72233 | E13: =C13-D13 -> 7661.0653 | F13: =E13 -> 7661.0653 | H13: =Excessinfracash2023*Shares!AA15 -> 197.99488 | I13: =F13+H13 -> 7859.0602 | M13: =I13 -> 7859.0602 | P13: =SUM(J13:O13)-I13 -> 0
A14: 13 | B14: Karen S | C14: =Shareout!#REF! -> #REF! | D14: ='New Repayment Schedule'!DC18 -> 11425.696 | E14: =C14-D14 -> #REF! | G14: =E14*-1 -> #REF! | H14: =Excessinfracash2023*Shares!AA16 -> 470.23783 | I14: =F14+H14 -> 470.23783 | N14: =I14 -> 470.23783 | P14: =SUM(J14:O14)-I14 -> 0
A15: 14 | B15: Kebby | C15: =Shareout!#REF! -> #REF! | D15: ='New Repayment Schedule'!DC19 -> -121.55418 | E15: =C15-D15 -> #REF! | F15: =E15 -> #REF! | H15: =Excessinfracash2023*Shares!AA17 -> 3019.4219 | I15: =F15+H15 -> #REF! | N15: =I15 -> #REF! | P15: =SUM(J15:O15)-I15 -> #REF!
A16: 15 | B16: Keji | C16: =Shareout!AN85 -> 9548.0203 | D16: ='New Repayment Schedule'!DC21 -> 1003.2706 | E16: =C16-D16 -> 8544.7497 | F16: =E16 -> 8544.7497 | H16: =Excessinfracash2023*Shares!AA19 -> 1559.2097 | I16: =F16+H16 -> 10103.959 | O16: =I16 -> 10103.959 | P16: =SUM(J16:O16)-I16 -> 0
A17: 16 | B17: Khucwayo | C17: =Shareout!AR85 -> 4258.7266 | D17: ='New Repayment Schedule'!DC22 -> -0.00030205479 | E17: =C17-D17 -> 4258.7269 | F17: =E17 -> 4258.7269 | H17: =Excessinfracash2023*Shares!AA20 -> 1559.2097 | I17: =F17+H17 -> 5817.9365 | N17: =I17 -> 5817.9365 | P17: =SUM(J17:O17)-I17 -> 0
A18: 17 | B18: Kombe | C18: =Shareout!AV85 -> 42633.685 | D18: ='New Repayment Schedule'!DC23 -> 6491.2086 | E18: =C18-D18 -> 36142.477 | H18: =Excessinfracash2023*Shares!AA21 -> 1670.5818 | I18: =F18+H18 -> 1670.5818 | N18: =I18 -> 1670.5818 | P18: =SUM(J18:O18)-I18 -> 0
A19: 18 | B19: Kwibisa | C19: =Shareout!AZ85 -> 11976.859 | D19: ='New Repayment Schedule'!DC25 -> 2044.6104 | E19: =C19-D19 -> 9932.2489 | H19: =Excessinfracash2023*Shares!AA23 -> 1546.835 | I19: =F19+H19 -> 1546.835 | O19: =I19 -> 1546.835 | P19: =SUM(J19:O19)-I19 -> 0
A20: 19 | B20: Michael | C20: =Shareout!BD85 -> 69300.958 | D20: ='New Repayment Schedule'!DC26 -> 19210.884 | E20: =C20-D20 -> 50090.074 | F20: =E20 -> 50090.074 | H20: =Excessinfracash2023*Shares!AA24 -> 878.60227 | I20: =F20+H20 -> 50968.676 | O20: =I20 -> 50968.676 | P20: =SUM(J20:O20)-I20 -> 0
A21: 20 | B21: Mike | C21: =Shareout!#REF! -> #REF! | D21: ='New Repayment Schedule'!DC27 -> 29574.557 | E21: =C21-D21 -> #REF! | H21: =Excessinfracash2023*Shares!AA25 -> 1992.3235 | I21: =F21+H21 -> 1992.3235 | O21: =I21 -> 1992.3235 | P21: =SUM(J21:O21)-I21 -> 0
A22: 21 | B22: Millie | C22: =Shareout!BH85 -> 5100.8299 | D22: ='New Repayment Schedule'!DC28 -> 16577.725 | E22: =C22-D22 -> -11476.895 | F22: =E22 -> -11476.895 | H22: =Excessinfracash2023*Shares!AA26 -> 680.60739 | I22: =F22+H22 -> -10796.288 | N22: =I22 -> -10796.288 | P22: =SUM(J22:O22)-I22 -> 0
A23: 22 | B23: Mofya | C23: =Shareout!#REF! -> #REF! | D23: ='New Repayment Schedule'!DC29 -> 0 | E23: =C23-D23 -> #REF! | F23: =E23 -> #REF! | H23: =Excessinfracash2023*Shares!AA27 -> 581.60995 | I23: =F23+H23 -> #REF! | J23: =I23 -> #REF! | P23: =SUM(J23:O23)-I23 -> #REF!
A24: 23 | B24: Mukuma | C24: =Shareout!BL85 -> 35608.031 | D24: ='New Repayment Schedule'!#REF! -> #REF! | E24: =C24-D24 -> #REF! | F24: =E24 -> #REF! | H24: =Excessinfracash2023*Shares!#REF! -> #REF! | I24: =F24+H24 -> #REF! | N24: =I24 -> #REF! | P24: =SUM(J24:O24)-I24 -> #REF!
A25: 24 | B25: Mumba | C25: =Shareout!BP85 -> 35718.613 | D25: ='New Repayment Schedule'!DC30 -> 0 | E25: =C25-D25 -> 35718.613 | F25: =E25 -> 35718.613 | H25: =Excessinfracash2023*Shares!AA28 -> 12.37468 | I25: =F25+H25 -> 35730.987 | O25: =I25 -> 35730.987 | P25: =SUM(J25:O25)-I25 -> 0
A26: 25 | B26: Mwenya | C26: =Shareout!#REF! -> #REF! | D26: ='New Repayment Schedule'!#REF! -> #REF! | E26: =C26-D26 -> #REF! | F26: =E26 -> #REF! | H26: =Excessinfracash2023*Shares!#REF! -> #REF! | I26: =F26+H26 -> #REF! | K26: =I26 -> #REF! | P26: =SUM(J26:O26)-I26 -> #REF!
A27: 26 | B27: Nancy Mwila | C27: =Shareout!#REF! -> #REF! | D27: ='New Repayment Schedule'!#REF! -> #REF! | E27: =C27-D27 -> #REF! | G27: =E27*-1 -> #REF! | H27: =Excessinfracash2023*Shares!#REF! -> #REF! | I27: =F27+H27 -> #REF! | J27: =I27 -> #REF! | P27: =SUM(J27:O27)-I27 -> #REF!
A28: 27 | B28: Nyanyiwe | C28: =Shareout!CB85 -> 39135.116 | D28: ='New Repayment Schedule'!#REF! -> #REF! | E28: =C28-D28 -> #REF! | F28: =E28 -> #REF! | H28: =Excessinfracash2023*Shares!#REF! -> #REF! | I28: =F28+H28 -> #REF! | J28: =I28 -> #REF! | P28: =SUM(J28:O28)-I28 -> #REF!
A29: 28 | B29: Pamela | C29: =Shareout!CF85 -> 20082.571 | D29: ='New Repayment Schedule'!#REF! -> #REF! | E29: =C29-D29 -> #REF! | F29: =E29 -> #REF! | H29: =Excessinfracash2023*Shares!#REF! -> #REF! | I29: =F29+H29 -> #REF! | N29: =I29 -> #REF! | P29: =SUM(J29:O29)-I29 -> #REF!
A30: 29 | B30: Paul | C30: =Shareout!#REF! -> #REF! | D30: ='New Repayment Schedule'!#REF! -> #REF! | E30: =C30-D30 -> #REF! | H30: =Excessinfracash2023*Shares!#REF! -> #REF! | I30: =F30+H30 -> #REF! | L30: =I30 -> #REF! | P30: =SUM(J30:O30)-I30 -> #REF!
A31: 30 | B31: Schuller | C31: =Shareout!CJ85 -> 48288.145 | D31: ='New Repayment Schedule'!#REF! -> #REF! | E31: =C31-D31 -> #REF! | F31: =E31 -> #REF! | H31: =Excessinfracash2023*Shares!#REF! -> #REF! | I31: =F31+H31 -> #REF! | N31: =I31 -> #REF! | P31: =SUM(J31:O31)-I31 -> #REF!
A32: 31 | B32: Shubart | C32: =Shareout!CN85 -> 17250.526 | D32: ='New Repayment Schedule'!#REF! -> #REF! | E32: =C32-D32 -> #REF! | F32: =E32 -> #REF! | H32: =Excessinfracash2023*Shares!#REF! -> #REF! | I32: =F32+H32 -> #REF! | N32: =I32 -> #REF! | P32: =SUM(J32:O32)-I32 -> #REF!
A33: 32 | B33: Solomon | C33: =Shareout!CR85 -> 14514.645 | D33: ='New Repayment Schedule'!#REF! -> #REF! | E33: =C33-D33 -> #REF! | F33: =E33 -> #REF! | H33: =Excessinfracash2023*Shares!#REF! -> #REF! | I33: =F33+H33 -> #REF! | M33: =I33 -> #REF! | P33: =SUM(J33:O33)-I33 -> #REF!
A34: 33 | B34: Tumelo | C34: =Shareout!CV85 -> 341.29221 | D34: ='New Repayment Schedule'!#REF! -> #REF! | E34: =C34-D34 -> #REF! | F34: =E34 -> #REF! | H34: =Excessinfracash2023*Shares!#REF! -> #REF! | I34: =F34+H34 -> #REF! | M34: =I34 -> #REF! | P34: =SUM(J34:O34)-I34 -> #REF!
A35: 34 | B35: Zeko | C35: =Shareout!#REF! -> #REF! | D35: ='New Repayment Schedule'!#REF! -> #REF! | E35: =C35-D35 -> #REF! | F35: =E35 -> #REF! | H35: =Excessinfracash2023*Shares!#REF! -> #REF! | I35: =F35+H35 -> #REF! | J35: 6646.36 | L35: 38000 | P35: =SUM(J35:O35)-I35 -> #REF!
A36: 35 | B36: INSURANCE | C36: =Shareout!CZ85 -> 42115.686 | E36: =C36-D36 -> 42115.686 | F36: =E36 -> 42115.686 | P36: =SUM(J36:O36)-I36 -> 0
B37: TOTAL | C37: =SUM(C3:C36) -> #REF! | D37: =SUM(D3:D36) -> #REF! | E37: =SUM(E3:E36) -> #REF! | F37: =SUM(F3:F35) -> #REF! | G37: =SUM(G3:G36) -> #REF! | H37: =SUM(H3:H36) -> #REF! | I37: =SUM(I3:I36) -> #REF! | J37: =SUM(J3:J35) -> #REF! | K37: =SUM(K3:K35) -> #REF! | L37: =SUM(L3:L35) -> #REF! | M37: =SUM(M3:M35) -> #REF! | N37: =SUM(N3:N35) -> #REF! | O37: =SUM(O3:O35) -> 100843.66 | P37: =SUM(J37:O37) -> #REF!
F38: =F37-F36 -> #REF! | J38: =J1-J37 -> #REF! | K38: =K1-K37 -> #REF! | L38: =L1-L37 -> #REF! | M38: =M1-M37 -> #REF! | N38: =N1-N37 -> #REF! | O38: =O1-O37 -> -66210.705 | P38: =P1-P37 -> #REF!
H40: =C46-8200 -> #REF!
B42: PEOPLE GETTING SHAREOUT | C42: =F37-F36 -> #REF!
...

Sheet Calculations
B4: MAY TRANSACTIONS
B5: Name | C5: Shares | D5: LR1 | E5: FLR | F5: Insurance | G5: LA | H5: Total | L5: Recipient > | M5: Nyanyiwe | N5: Karen Mwinga | O5: Kwibisa | P5: Pamela | Q5: Evans | R5: Total
A6: 1 | B6: Abigail Mundia | D6: 24000 | G6: =D6+E6 -> 24000 | H6: =SUM(C6:F6) -> 24000 | J6: ='New Repayment Schedule'!BV6 -> 105207.14 | K6: =Shares!Z156-J6 -> -105207.14 | M6: =M33 -> 52377.19 | N6: =N33 -> 0 | O6: =O33 -> 3345 | P6: =P33 -> 146573.59 | Q6: =Q33 -> 61138.561 | R6: =SUM(M6:Q6) -> 263434.34 | T6: =H30-R6 -> -9372.5092
A7: 2 | B7: Abel Kunda | D7: 15000 | E7: 806.44 | G7: =D7+E7 -> 15806.44 | H7: =SUM(C7:F7) -> 15806.44 | J7: ='New Repayment Schedule'!BV7 -> 15427.5 | K7: =Shares!Z157-J7 -> -15427.5 | R7: =SUM(M7:Q7) -> 0
A8: 3 | B8: Andrew | D8: 9560 | G8: =D8+E8 -> 9560 | H8: =SUM(C8:F8) -> 9560 | J8: ='New Repayment Schedule'!BV8 -> 22827.82 | K8: =Shares!Z158-J8 -> -22827.82 | L8: Sender | R8: =SUM(M8:Q8) -> 0 | S8: =H6-R8 -> 24000
A9: 4 | B9: Arthur | D9: 5000 | E9: 102.04 | G9: =D9+E9 -> 5102.04 | H9: =SUM(C9:F9) -> 5102.04 | J9: ='New Repayment Schedule'!BV9 -> 18700 | K9: =Shares!Z161-J9 -> -18700 | L9: Abigail Mundia | P9: 24000 | R9: =SUM(M9:Q9) -> 24000 | S9: =H6-R9 -> 0
A10: 5 | B10: Evans | D10: 46500 | G10: =D10+E10 -> 46500 | H10: =SUM(C10:F10) -> 46500 | J10: ='New Repayment Schedule'!BV10 -> 49431.042 | K10: =Shares!Z163-J10 -> -49431.042 | L10: Abel Kunda | P10: 15806.44 | R10: =SUM(M10:Q10) -> 15806.44 | S10: =H7-R10 -> 0 | V10: Nyanyiwe | W10: =O6 -> 3345 | X10: 18600 | Y10: 7400 | Z10: 6000 | AB10: 1200 | AC10: 200 | AD10: =W10-SUM(X10:AA10) -> -28655
A11: 6 | B11: Jesper | G11: =D11+E11 -> 0 | H11: =SUM(C11:F11) -> 0 | J11: ='New Repayment Schedule'!BV11 -> 0 | K11: =Shares!Z164-J11 -> 0 | L11: Andrew | M11: 9560 | R11: =SUM(M11:Q11) -> 9560 | S11: =H8-R11 -> 0 | V11: Kwibisa | W11: 22600 | Y11: 22600 | AD11: =W11-SUM(X11:AA11) -> 0
A12: 7 | B12: Joshua | D12: 1100 | G12: =D12+E12 -> 1100 | H12: =SUM(C12:F12) -> 1100 | J12: ='New Repayment Schedule'!BV12 -> 0 | K12: =Shares!Z165-J12 -> 0 | L12: Arthur | P12: 5103 | R12: =SUM(M12:Q12) -> 5103 | S12: =H9-R12 -> -0.96 | V12: Evans | W12: =Q6 -> 61138.561 | AA12: 2600 | AD12: =W12-SUM(X12:AA12) -> 58538.561
A13: 8 | B13: Kampamba | D13: 2500 | E13: 121.79 | G13: =D13+E13 -> 2621.79 | H13: =SUM(C13:F13) -> 2621.79 | J13: ='New Repayment Schedule'!BV13 -> 17845.404 | K13: =Shares!Z166-J13 -> -17845.404 | L13: Evans | Q13: 54482.281 | R13: =SUM(M13:Q13) -> 54482.281 | S13: =H10-R13 -> -7982.2809 | V13: Mwenya | W13: =#REF! -> #REF! | AA13: 7400 | AC13: 2300 | AD13: =W13-SUM(X13:AA13) -> #REF!
A14: 9 | B14: Karen Mwinga | D14: 44750 | G14: =D14+E14 -> 44750 | H14: =SUM(C14:F14) -> 44750 | J14: ='New Repayment Schedule'!BV14 -> 58024.011 | K14: =Shares!Z169-J14 -> -58024.011 | L14: Jesper | P14: 40 | R14: =SUM(M14:Q14) -> 40 | S14: =H11-R14 -> -40 | W14: =SUM(W10:W13) -> #REF! | X14: =SUM(X10:X13) -> 18600 | Y14: =SUM(Y10:Y13) -> 30000 | Z14: =SUM(Z10:Z13) -> 6000 | AA14: =SUM(AA10:AA13) -> 10000 | AB14: =SUM(AB10:AB13) -> 1200 | AC14: =SUM(AC10:AC13) -> 2500 | AD14: =W14-SUM(X14:AA14) -> #REF!
A15: 10 | B15: Keji | D15: 688.12 | E15: 108.62 | G15: =D15+E15 -> 796.74 | H15: =SUM(C15:F15) -> 796.74 | J15: ='New Repayment Schedule'!BV15 -> 16800.004 | L15: Joshua | Q15: 1100 | R15: =SUM(M15:Q15) -> 1100 | S15: =H12-R15 -> 0 | X15: =X14-48000 -> -29400 | Y15: =Y14-30000 -> 0 | Z15: =Z14-6000 -> 0 | AA15: =AA14-10000 -> 0 | AB15: =AB14-1200 -> 0 | AC15: =AC14-2500 -> 0
A16: 11 | B16: Kombe | D16: 40000 | G16: =D16+E16 -> 40000 | H16: =SUM(C16:F16) -> 40000 | J16: ='New Repayment Schedule'!BV16 -> 115443.53 | L16: Kampamba | P16: 2622 | R16: =SUM(M16:Q16) -> 2622 | S16: =H13-R16 -> -0.21
A17: 12 | B17: Khucwayo | G17: =D17+E17 -> 0 | H17: =SUM(C17:F17) -> 0 | J17: ='New Repayment Schedule'!BV17 -> -9.6551438 | K17: =Shares!Z173-J17 -> 9.6551438 | L17: Karen Mwinga | P17: 44750 | R17: =SUM(M17:Q17) -> 44750 | S17: =H14-R17 -> 0
A18: 13 | B18: Kwibisa | D18: 1500 | E18: 125 | G18: =D18+E18 -> 1625 | H18: =SUM(C18:F18) -> 1625 | J18: ='New Repayment Schedule'!BV18 -> 16117.562 | K18: =Shares!Z174-J18 -> -16117.562 | L18: Keji | M18: 796.74 | R18: =SUM(M18:Q18) -> 796.74 | S18: =H15-R18 -> 0
A19: 14 | B19: Michael | E19: 803.15 | G19: =D19+E19 -> 803.15 | H19: =SUM(C19:F19) -> 803.15 | J19: ='New Repayment Schedule'!BV19 -> 6300 | K19: =Shares!Z176-J19 -> -6300 | L19: Kombe | P19: 40000 | R19: =SUM(M19:Q19) -> 40000 | S19: =H16-R19 -> 0
A20: 15 | B20: Millie | D20: 2048 | E20: 60 | G20: =D20+E20 -> 2108 | H20: =SUM(C20:F20) -> 2108 | J20: ='New Repayment Schedule'!BV20 -> 10999.449 | K20: =Shares!Z177-J20 -> -10999.449 | L20: Khucwayo | R20: =SUM(M20:Q20) -> 0 | S20: =H17-R20 -> 0
A21: 16 | B21: Mukuma | D21: 2500 | G21: =D21+E21 -> 2500 | H21: =SUM(C21:F21) -> 2500 | J21: ='New Repayment Schedule'!BV21 -> 7402.5 | L21: Kwibisa | O21: 1625 | R21: =SUM(M21:Q21) -> 1625 | S21: =H18-R21 -> 0
A22: 17 | B22: Mumba | E22: 414.74 | G22: =D22+E22 -> 414.74 | H22: =SUM(C22:F22) -> 414.74 | J22: ='New Repayment Schedule'!BV22 -> 0 | K22: =Shares!Z180-J22 -> 0 | L22: Michael | P22: 803.15 | R22: =SUM(M22:Q22) -> 803.15 | S22: =H19-R22 -> 0
A23: 18 | B23: Mumbi | D23: 3000 | G23: =D23+E23 -> 3000 | H23: =SUM(C23:F23) -> 3000 | J23: ='New Repayment Schedule'!BV23 -> 11767.894 | K23: =Shares!Z181-J23 -> -11767.894 | L23: Millie | M23: 2108 | R23: =SUM(M23:Q23) -> 2108 | S23: =H20-R23 -> 0
A24: 19 | B24: Mwenya | D24: 5000 | E24: 556.28 | G24: =D24+E24 -> 5556.28 | H24: =SUM(C24:F24) -> 5556.28 | J24: ='New Repayment Schedule'!BV24 -> 0 | K24: =Shares!Z182-J24 -> 0 | L24: Mukuma | M24: 2500 | R24: =SUM(M24:Q24) -> 2500 | S24: =H21-R24 -> 0
A25: 20 | B25: Nyanyiwe | D25: 37000 | E25: 412.45 | G25: =D25+E25 -> 37412.45 | H25: =SUM(C25:F25) -> 37412.45 | J25: ='New Repayment Schedule'!BV25 -> 38195.486 | K25: =Shares!Z184-J25 -> -38195.486 | L25: Mumba | P25: 414.74 | R25: =SUM(M25:Q25) -> 414.74 | S25: =H22-R25 -> 0
A26: 21 | B26: Pamela | D26: 7155.2527 | G26: =D26+E26 -> 7155.2527 | H26: =SUM(C26:F26) -> 7155.2527 | J26: ='New Repayment Schedule'!BV26 -> 28163.625 | K26: =Shares!#REF!-J26 -> #REF! | L26: Mumbi | P26: 3000 | R26: =SUM(M26:Q26) -> 3000 | S26: =H23-R26 -> 0
A27: 22 | B27: Schuller | D27: 1000 | E27: 529.95 | G27: =D27+E27 -> 1529.95 | H27: =SUM(C27:F27) -> 1529.95 | J27: ='New Repayment Schedule'!BV27 -> 0 | K27: =Shares!#REF!-J27 -> #REF! | L27: Mwenya | Q27: 5556.28 | R27: =SUM(M27:Q27) -> 5556.28 | S27: =H24-R27 -> 0
A28: 23 | B28: Shubart | G28: =D28+E28 -> 0 | H28: =SUM(C28:F28) -> 0 | J28: ='New Repayment Schedule'!BV28 -> 15226.71 | K28: =Shares!#REF!-J28 -> #REF! | L28: Nyanyiwe | M28: 37412.45 | R28: =SUM(M28:Q28) -> 37412.45 | S28: =H25-R28 -> 0
A29: 24 | B29: Solomon | D29: 1720 | G29: =D29+E29 -> 1720 | H29: =SUM(C29:F29) -> 1720 | J29: ='New Repayment Schedule'!BV29 -> 0 | L29: Pamela | P29: 8504.261 | R29: =SUM(M29:Q29) -> 8504.261 | S29: =H26-R29 -> -1349.0083
B30: TOTAL LOAN | C30: =SUM(C6:C29) -> 0 | D30: =SUM(D6:D29) -> 250021.37 | E30: =SUM(E6:E29) -> 4040.46 | F30: =SUM(F6:F29) -> 0 | G30: =SUM(G6:G29) -> 254061.83 | H30: =SUM(C30:F30) -> 254061.83 | L30: Schuller | P30: 1530 | R30: =SUM(M30:Q30) -> 1530 | S30: =H27-R30 -> -0.05
H31: =H30-G30 -> 0 | J31: 57 | L31: Shubart | R31: =SUM(M31:Q31) -> 0 | S31: =H28-R31 -> 0
D32: =H31 -> 0 | L32: Solomon | O32: 1720 | R32: =SUM(M32:Q32) -> 1720 | S32: =H29-R32 -> 0
L33: TOTAL LOAN | M33: =SUM(M9:M32) -> 52377.19 | N33: =SUM(N9:N32) -> 0 | O33: =SUM(O9:O32) -> 3345 | P33: =SUM(P9:P32) -> 146573.59 | Q33: =SUM(Q9:Q32) -> 61138.561 | R33: =SUM(R9:R32) -> 263434.34 | S33: =H30-R33 -> -9372.5092
B34: Name | C34: FL | D34: FL Interest | E34: Total | M34: =M6-M33 -> 0 | N34: =N6-N33 -> 0 | O34: =O6-O33 -> 0 | P34: =P6-P33 -> 0 | Q34: =Q6-Q33 -> 0
B35: Abigail Mundia | C35: =FLAUGUST2024*G35 -> 0 | D35: =C35*0.1 -> 0 | E35: =C35+D35 -> 0 | F35: =Shares!Y4 -> 27400 | G35: =F35/F59 -> 0.06702544
B36: Abel Kunda | C36: =FLAUGUST2024*G36 -> 0 | D36: =C36*0.1 -> 0 | E36: =C36+D36 -> 0 | F36: =Shares!Y5 -> 49000 | G36: =F36/F59 -> 0.11986301
B37: Andrew | C37: =FLAUGUST2024*G37 -> 0 | D37: =C37*0.1 -> 0 | E37: =C37+D37 -> 0 | F37: =Shares!Y6 -> 5800 | G37: =F37/F59 -> 0.014187867
B38: Arthur | C38: =FLAUGUST2024*G38 -> 0 | D38: =C38*0.1 -> 0 | E38: =C38+D38 -> 0 | F38: =Shares!Y7 -> 6200 | G38: =F38/F59 -> 0.015166341
B39: Evans | C39: =FLAUGUST2024*G39 -> 0 | D39: =C39*0.1 -> 0 | E39: =C39+D39 -> 0 | F39: =Shares!Y8 -> 10400 | G39: =F39/F59 -> 0.025440313
B40: Jesper | C40: =FLAUGUST2024*G40 -> 0 | D40: =C40*0.1 -> 0 | E40: =C40+D40 -> 0 | F40: =Shares!Y9 -> 2200 | G40: =F40/F59 -> 0.0053816047
B41: Joshua | C41: 11000 | D41: =C41*0.1 -> 1100 | E41: =C41+D41 -> 12100
B42: Kampamba | C42: =FLAUGUST2024*G42 -> 0 | D42: =C42*0.1 -> 0 | E42: =C42+D42 -> 0 | F42: =Shares!Y11 -> 7400 | G42: =F42/F59 -> 0.018101761
B43: Karen Mwinga | C43: =FLAUGUST2024*G43 -> 0 | D43: =C43*0.1 -> 0 | E43: =C43+D43 -> 0 | F43: =Shares!Y12 -> 5200 | G43: =F43/F59 -> 0.012720157
...

Sheet Admins
A1: Recipient > | B1: Nyanyiwe | C1: Karen Mwinga | D1: Kwibisa | E1: Evans
B2: 25280 | C2: 20400 | D2: 9800 | E2: =E29 -> 23100 | F2: =SUM(B2:E2) -> 78580 | I2: August | J2: September | K2: October | L2: Total
H3: Nyanyiwe | I3: =36280-11000 -> 25280 | J3: 52156.28 | L3: =SUM(I3:K3) -> 77436.28
A4: Sender | H4: Evans | I4: 23100 | J4: 61138.561 | L4: =SUM(I4:K4) -> 84238.561
A5: Abigail Mundia | E5: 17500 | H5: Karen M | L5: =SUM(I5:K5) -> 0
A6: Abel Kunda | B6: 3700 | H6: Pamela | J6: =146573.591000908+20400 -> 166973.59 | L6: =SUM(I6:K6) -> 166973.59
A7: Andrew | B7: 1580 | H7: Kwibisa | I7: 9800 | J7: 3345 | L7: =SUM(I7:K7) -> 13145
A8: Arthur | B8: 5200 | H8: Total | I8: =SUM(I3:I7) -> 58180 | J8: =SUM(J3:J7) -> 283613.43 | L8: =SUM(L3:L7) -> 341793.43
A9: Evans | E9: 1300
A10: Jesper | D10: 200
A11: Joshua
A12: Kampamba | E12: 3100
A13: Karen Mwinga | C13: 10200
A14: Keji | B14: 5200
A15: Kombe | D15: 5200
A16: Khucwayo | B16: 700
A17: Kwibisa | D17: 3200
A18: Michael | D18: 200
A19: Millie | B19: 2700
A20: Mukuma | B20: 5000
A21: Mumba | D21: 1000
A22: Mumbi | C22: 4300
A23: Mwenya | E23: 1200
A24: Nyanyiwe | C24: 1200
A25: Pamela | C25: 3200
A26: Schuller | B26: 1200
A27: Shubart | C27: 1500
A28: Solomon
A29: TOTAL LOAN | B29: =SUM(B5:B28) -> 25280 | C29: =SUM(C5:C28) -> 20400 | D29: =SUM(D5:D28) -> 9800 | E29: =SUM(E5:E28) -> 23100
A30: Millie | B30: 1200
A31: Phyllis | B31: 7500 | D31: September
A32: Karen Mwinga | B32: =#REF! -> #REF! | D32: Chilombo | E32: 4000
D33: Evans | E33: 14000
A34: Total | B34: =SUM(B29:B33) -> #REF! | D34: Keji | E34: 164
D35: Mike | E35: 388
D36: Mukuma | E36: 754
A37: Grand Total | B37: =SUM(B6,B15,B25,B34) -> #REF! | D37: Mumba | E37: 395
D38: Mumbi | E38: 1000
D39: Solomon | E39: 223
E40: 10000
...

Sheet New Repayment Schedule
H1: INFRACash 2025
H2: LOAN TRANSACTIONS
H3: 1 | I3: 2 | J3: 3 | K3: 4 | L3: 5 | M3: 6 | N3: 7 | O3: 8 | P3: 9 | Q3: 10 | R3: 11 | S3: 12 | T3: 13 | U3: 14 | V3: 15 | W3: 16 | X3: 17 | Y3: 18 | Z3: 19 | AA3: 20 | AB3: 21 | AC3: 22 | AD3: 23 | AE3: 24 | AF3: 25 | AG3: 26 | AH3: 27 | AI3: 28 | AJ3: 29 | AK3: 30 | AL3: 31 | AM3: 32 | AN3: 33 | AO3: 34 | AP3: 35 | AQ3: 36 | AR3: 37 | AS3: 38 | AT3: 39 | AU3: 40 | AV3: 41 | AW3: 42 | AX3: 43 | AY3: 44 | AZ3: 45 | BA3: 46 | BB3: 47 | BC3: 48 | BD3: 49 | BE3: 50 | BF3: 51 | BG3: 52 | BH3: 53 | BI3: 54 | BJ3: 55 | BK3: 56 | BL3: 57 | BM3: 58 | BN3: 59 | BO3: 60 | BP3: 61 | BQ3: 62 | BS3: 63 | BT3: 64 | BU3: 65 | BV3: 66 | BW3: 67 | BX3: 68 | BY3: 69 | BZ3: 70 | CB3: 71 | CC3: 72 | CD3: 73 | CE3: 74 | CF3: 75 | CG3: 76 | CI3: 77 | CJ3: 78 | CL3: 79 | CM3: 80 | CN3: 81 | CO3: 82 | CP3: 83 | CQ3: 84 | CR3: 85 | CS3: 86 | CU3: 87 | CV3: 88 | CW3: 89 | CX3: 90 | CY3: 91 | CZ3: 92 | DA3: 93 | DB3: 94 | DC3: 95
I4: NOVEMBER | Q4: DECEMBER | Y4: JANUARY | AG4: FEBRUARY | AO4: MARCH | AW4: APRIL | BE4: MAY | BM4: JUNE | BV4: JULY | CE4: AUGUST | CO4: SEPTEMBER | CX4: OCTOBER
B5: Saving | C5: Loan Application | D5: Loan Repayment | E5: Credit Limit | H5: Member ID | I5: Opening Loan Balance | J5: Loan repayment | K5: Loan Application | L5: Interest 5% | M5: Interest 10% | N5: Closing Loan Balance | O5: Credit Limit | Q5: Opening Loan Balance | R5: Loan repayment | S5: Loan Application | T5: Interest 5% | U5: Interest 10% | V5: Closing Loan Balance | W5: Credit Limit | Y5: Opening Loan Balance | Z5: Loan repayment | AA5: Loan Application | AB5: Interest 5% | AC5: Interest 10% | AD5: Closing Loan Balance | AE5: Credit Limit | AG5: Opening Loan Balance | AH5: Loan repayment | AI5: Loan Application | AJ5: Interest 5% | AK5: Interest 10% | AL5: Closing Loan Balance | AM5: Credit Limit | AO5: Opening Loan Balance | AP5: Loan repayment | AQ5: Loan Application | AR5: Interest 5% | AS5: Interest 10% | AT5: Closing Loan Balance | AU5: Credit Limit | AW5: Opening Loan Balance | AX5: Loan repayment | AY5: Loan Application | AZ5: Interest 5% | BA5: Interest 10% | BB5: Closing Loan Balance | BC5: Credit Limit | BE5: Opening Loan Balance | BF5: Loan repayment | BG5: Loan Application | BH5: Interest 5% | BI5: Interest 10% | BJ5: Closing Loan Balance | BK5: Credit Limit | BM5: Opening Loan Balance | BN5: Loan repayment | BO5: Loan Application | BP5: Interest 5% | BQ5: Interest 10% | BR5: Penalt | BS5: Closing Loan Balance | BT5: Credit Limit | BV5: Opening Loan Balance | BW5: Loan repayment | BX5: Loan Application | BY5: Interest 5% | BZ5: Interest 10% | CA5: Penalt | CB5: Closing Loan Balance | CC5: Credit Limit | CE5: Opening Loan Balance | CF5: Loan repayment | CG5: Loan Application | CH5: Forced Loan | CI5: Interest 5% | CJ5: Interest 10% | CK5: Penalt | CL5: Closing Loan Balance | CM5: Credit Limit | CO5: Opening Loan Balance | CP5: Loan repayment | CQ5: Loan Application | CR5: Interest 5% | CS5: Interest 10% | CT5: Penalty | CU5: Closing Loan Balance | CV5: Credit Limit | CX5: Opening Loan Balance | CY5: Loan repayment | CZ5: Loan Application | DA5: Interest 5% | DB5: Interest 10% | DC5: Closing Loan Balance | DD5: Credit Limit
B6: Saving | C6: Loan Application | D6: Loan Repayment | E6: Fines/Penalties | G6: 1 | H6: Abigail Mundia | L6: =IF(J6>0,(I6-J6)*0.05,0) -> 0 | M6: =IF(K6>0,K6*0.1,0) -> 0 | N6: =I6-J6+K6+L6+M6 -> 0 | O6: =(VLOOKUP(H6,INFRACASHshares2025,25,0)-N6) -> 82200 | Q6: =N6 -> 0 | S6: 44800 | T6: =IF(R6>0,(Q6-R6)*0.05,0) -> 0 | U6: =IF(S6>0,S6*0.1,0) -> 4480 | V6: =(Q6-R6+S6+T6+U6) -> 49280 | W6: =(VLOOKUP(H6,INFRACASHshares2025,25,0)-V6) -> 32920 | Y6: =V6 -> 49280 | Z6: 2500 | AB6: =IF(Z6>0,(Y6-Z6)*0.05,0) -> 2339 | AC6: =IF(AA6>0,AA6*0.1,0) -> 0 | AD6: =(Y6-Z6+AA6+AB6+AC6) -> 49119 | AE6: =(VLOOKUP(H6,INFRACASHshares2025,25,0)-AD6) -> 33081 | AG6: =AD6 -> 49119 | AH6: 5000 | AJ6: =((AG6-AH6)*0.05) -> 2205.95 | AK6: =IF(AI6>0,AI6*0.1,0) -> 0 | AL6: =(AG6-AH6+AI6+AJ6+AK6) -> 46324.95 | AM6: =(VLOOKUP(H6,INFRACASHshares2025,25,0)-AL6) -> 35875.05 | AO6: =AL6 -> 46324.95 | AP6: 3000 | AQ6: 50000 | AR6: =((AO6-AP6)*0.05) -> 2166.2475 | AS6: =IF(AQ6>0,AQ6*0.1,0) -> 5000 | AT6: =(AO6-AP6+AQ6+AR6+AS6) -> 100491.2 | AU6: =(VLOOKUP(H6,INFRACASHshares2025,25,0)-AT6) -> -18291.197 | AW6: =AT6 -> 100491.2 | AX6: 5000 | AZ6: =((AW6-AX6)*0.05) -> 4774.5599 | BA6: =IF(AY6>0,AY6*0.1,0) -> 0 | BB6: =(AW6-AX6+AY6+AZ6+BA6) -> 100265.76 | BC6: =(VLOOKUP(H6,INFRACASHshares2025,25,0)-BB6) -> -18065.757 | BE6: =BB6 -> 100265.76 | BF6: 3500 | BG6: =3429+1019.39 -> 4448.39 | BH6: =(BE6-BF6)*0.05 -> 4838.2879 | BI6: =IF(BG6>0,BG6*0.1,0) -> 444.839 | BJ6: =(BE6-BF6+BG6+BH6+BI6) -> 106497.27 | BK6: =(VLOOKUP(H6,INFRACASHshares2025,25,0)-BJ6) -> -24297.274 | BM6: =BJ6 -> 106497.27 | BN6: 6300 | BP6: =(BM6-BN6)*0.05 -> 5009.8637 | BQ6: =IF(BO6>0,BO6*0.1,0) -> 0 | BS6: =(BM6-BN6+BO6+BP6+BQ6+BR6) -> 105207.14 | BT6: =(VLOOKUP(H6,INFRACASHshares2025,25,0)-BS6) -> -23007.138 | BV6: =BS6 -> 105207.14 | BW6: 5300 | BY6: =(BV6-BW6)*0.05 -> 4995.3569 | BZ6: =IF(BX6>0,BX6*0.1,0) -> 0 | CB6: =(BV6-BW6+BX6+BY6+BZ6) -> 104902.49 | CC6: =(VLOOKUP(H6,INFRACASHshares2025,25,0)-CB6) -> -22702.495 | CE6: =CB6 -> 104902.49 | CF6: 17500 | CH6: 4509.4716 | CI6: =(CE6-CF6)*0.05 -> 4370.1247 | CJ6: =IF((CG6+CH6)>0,((CG6+CH6)*0.1),0) -> 450.94716 | CL6: =(CE6-CF6+CG6+CI6+CJ6) -> 92223.567 | CM6: =(VLOOKUP(H6,INFRACASHshares2025,25,0)-CL6) -> -10023.567 | CO6: =CL6 -> 92223.567 | CP6: 24000 | CR6: =((CO6-CP6)*0.05) -> 3411.1783 | CS6: =IF(CQ6>0,CQ6*0.1,0) -> 0 | CU6: =(CO6-CP6+CQ6+CR6+CS6) -> 71634.745 | CV6: =(VLOOKUP(H6,INFRACASHshares2025,25,0)-CU6) -> 10565.255 | CX6: =CU6 -> 71634.745 | DA6: =((CX6-CY8)*0.05) -> 3581.7373 | DB6: =IF(CZ6>0,CZ6*0.1,0) -> 0 | DC6: =(CX6-CY6+CZ6+DA6+DB6) -> 75216.482 | DD6: =(VLOOKUP(H6,INFRACASHshares2025,25,0)-DC6) -> 6983.5176
B7: Saving | C7: Loan Application | D7: Loan Repayment | E7: Fines/Penalties | G7: 2 | H7: Abel Kunda | L7: =IF(J7>0,(I7-J7)*0.05,0) -> 0 | M7: =IF(K7>0,K7*0.1,0) -> 0 | N7: =I7-J7+K7+L7+M7 -> 0 | O7: =(VLOOKUP(H7,INFRACASHshares2025,25,0)-N7) -> 147000 | Q7: =N7 -> 0 | T7: =IF(R7>0,(Q7-R7)*0.05,0) -> 0 | U7: =IF(S7>0,S7*0.1,0) -> 0 | V7: =(Q7-R7+S7+T7+U7) -> 0 | W7: =(VLOOKUP(H7,INFRACASHshares2025,25,0)-V7) -> 147000 | Y7: =V7 -> 0 | AB7: =IF(Z7>0,(Y7-Z7)*0.05,0) -> 0 | AC7: =IF(AA7>0,AA7*0.1,0) -> 0 | AD7: =(Y7-Z7+AA7+AB7+AC7) -> 0 | AE7: =(VLOOKUP(H7,INFRACASHshares2025,25,0)-AD7) -> 147000 | AG7: =AD7 -> 0 | AJ7: =((AG7-AH7)*0.05) -> 0 | AK7: =IF(AI7>0,AI7*0.1,0) -> 0 | AL7: =(AG7-AH7+AI7+AJ7+AK7) -> 0 | AM7: =(VLOOKUP(H7,INFRACASHshares2025,25,0)-AL7) -> 147000 | AO7: =AL7 -> 0 | AR7: =((AO7-AP7)*0.05) -> 0 | AS7: =IF(AQ7>0,AQ7*0.1,0) -> 0 | AT7: =(AO7-AP7+AQ7+AR7+AS7) -> 0 | AU7: =(VLOOKUP(H7,INFRACASHshares2025,25,0)-AT7) -> 147000 | AW7: =AT7 -> 0 | AZ7: =((AW7-AX7)*0.05) -> 0 | BA7: =IF(AY7>0,AY7*0.1,0) -> 0 | BB7: =(AW7-AX7+AY7+AZ7+BA7) -> 0 | BC7: =(VLOOKUP(H7,INFRACASHshares2025,25,0)-BB7) -> 147000 | BE7: =BB7 -> 0 | BH7: =(BE7-BF7)*0.05 -> 0 | BI7: =IF(BG7>0,BG7*0.1,0) -> 0 | BJ7: =(BE7-BF7+BG7+BH7+BI7) -> 0 | BK7: =(VLOOKUP(H7,INFRACASHshares2025,25,0)-BJ7) -> 147000 | BM7: =BJ7 -> 0 | BO7: 14025 | BP7: =(BM7-BN7)*0.05 -> 0 | BQ7: =IF(BO7>0,BO7*0.1,0) -> 1402.5 | BS7: =(BM7-BN7+BO7+BP7+BQ7+BR7) -> 15427.5 | BT7: =(VLOOKUP(H7,INFRACASHshares2025,25,0)-BS7) -> 131572.5 | BV7: =BS7 -> 15427.5 | BW7: 3000 | BX7: 26090 | BY7: =(BV7-BW7)*0.05 -> 621.375 | BZ7: =IF(BX7>0,BX7*0.1,0) -> 2609 | CB7: =(BV7-BW7+BX7+BY7+BZ7) -> 41747.875 | CC7: =(VLOOKUP(H7,INFRACASHshares2025,25,0)-CB7) -> 105252.12 | CE7: =CB7 -> 41747.875 | CF7: 13500 | CH7: 8064.3836 | CI7: =(CE7-CF7)*0.05 -> 1412.3938 | CJ7: =IF((CG7+CH7)>0,((CG7+CH7)*0.1),0) -> 806.43836 | CL7: =(CE7-CF7+CG7+CI7+CJ7) -> 30466.707 | CM7: =(VLOOKUP(H7,INFRACASHshares2025,25,0)-CL7) -> 116533.29 | CO7: =CL7 -> 30466.707 | CP7: 15806.44 | CR7: =((CO7-CP7)*0.05) -> 733.01336 | CS7: =IF(CQ7>0,CQ7*0.1,0) -> 0 | CU7: =(CO7-CP7+CQ7+CR7+CS7) -> 15393.28 | CV7: =(VLOOKUP(H7,INFRACASHshares2025,25,0)-CU7) -> 131606.72 | CX7: =CU7 -> 15393.28 | DA7: =((CX7-CY8)*0.05) -> 769.66402 | DB7: =IF(CZ7>0,CZ7*0.1,0) -> 0 | DC7: =(CX7-CY7+CZ7+DA7+DB7) -> 16162.944 | DD7: =(VLOOKUP(H7,INFRACASHshares2025,25,0)-DC7) -> 130837.06
B8: Saving | C8: Loan Application | D8: Loan Repayment | E8: Fines/Penalties | G8: 3 | H8: Andrew | K8: 6400 | L8: =IF(J8>0,(I8-J8)*0.05,0) -> 0 | M8: =IF(K8>0,K8*0.1,0) -> 640 | N8: =I8-J8+K8+L8+M8 -> 7040 | O8: =(VLOOKUP(H8,INFRACASHshares2025,25,0)-N8) -> 10360 | Q8: =N8 -> 7040 | R8: 640 | T8: =IF(R8>0,(Q8-R8)*0.05,0) -> 320 | U8: =IF(S8>0,S8*0.1,0) -> 0 | V8: =(Q8-R8+S8+T8+U8) -> 6720 | W8: =(VLOOKUP(H8,INFRACASHshares2025,25,0)-V8) -> 10680 | Y8: =V8 -> 6720 | Z8: 1250 | AB8: =IF(Z8>0,(Y8-Z8)*0.05,0) -> 273.5 | AC8: =IF(AA8>0,AA8*0.1,0) -> 0 | AD8: =(Y8-Z8+AA8+AB8+AC8) -> 5743.5 | AE8: =(VLOOKUP(H8,INFRACASHshares2025,25,0)-AD8) -> 11656.5 | AG8: =AD8 -> 5743.5 | AH8: 3000 | AJ8: =((AG8-AH8)*0.05) -> 137.175 | AK8: =IF(AI8>0,AI8*0.1,0) -> 0 | AL8: =(AG8-AH8+AI8+AJ8+AK8) -> 2880.675 | AM8: =(VLOOKUP(H8,INFRACASHshares2025,25,0)-AL8) -> 14519.325 | AO8: =AL8 -> 2880.675 | AP8: 200 | AQ8: 24000 | AR8: =((AO8-AP8)*0.05) -> 134.03375 | AS8: =IF(AQ8>0,AQ8*0.1,0) -> 2400 | AT8: =(AO8-AP8+AQ8+AR8+AS8) -> 29214.709 | AU8: =(VLOOKUP(H8,INFRACASHshares2025,25,0)-AT8) -> -11814.709 | AW8: =AT8 -> 29214.709 | AX8: 5214 | AZ8: =((AW8-AX8)*0.05) -> 1200.0354 | BA8: =IF(AY8>0,AY8*0.1,0) -> 0 | BB8: =(AW8-AX8+AY8+AZ8+BA8) -> 25200.744 | BC8: =(VLOOKUP(H8,INFRACASHshares2025,25,0)-BB8) -> -7800.7442 | BE8: =BB8 -> 25200.744 | BF8: 2400 | BG8: 8000 | BH8: =(BE8-BF8)*0.05 -> 1140.0372 | BI8: =IF(BG8>0,BG8*0.1,0) -> 800 | BJ8: =(BE8-BF8+BG8+BH8+BI8) -> 32740.781 | BK8: =(VLOOKUP(H8,INFRACASHshares2025,25,0)-BJ8) -> -15340.781 | BM8: =BJ8 -> 32740.781 | BN8: 11000 | BP8: =(BM8-BN8)*0.05 -> 1087.0391 | BQ8: =IF(BO8>0,BO8*0.1,0) -> 0 | BS8: =(BM8-BN8+BO8+BP8+BQ8+BR8) -> 22827.82 | BT8: =(VLOOKUP(H8,INFRACASHshares2025,25,0)-BS8) -> -5427.8205 | BV8: =BS8 -> 22827.82 | BW8: 11990 | BY8: =(BV8-BW8)*0.05 -> 541.89102 | BZ8: =IF(BX8>0,BX8*0.1,0) -> 0 | CB8: =(BV8-BW8+BX8+BY8+BZ8) -> 11379.711 | CC8: =(VLOOKUP(H8,INFRACASHshares2025,25,0)-CB8) -> 6020.2885 | CE8: =CB8 -> 11379.711 | CF8: 1380 | CH8: 954.55969 | CI8: =(CE8-CF8)*0.05 -> 499.98557 | CJ8: =IF((CG8+CH8)>0,((CG8+CH8)*0.1),0) -> 95.455969 | CL8: =(CE8-CF8+CG8+CI8+CJ8) -> 10595.153 | CM8: =(VLOOKUP(H8,INFRACASHshares2025,25,0)-CL8) -> 6804.847 | CO8: =CL8 -> 10595.153 | CP8: 9560 | CR8: =((CO8-CP8)*0.05) -> 51.757652 | CS8: =IF(CQ8>0,CQ8*0.1,0) -> 0 | CU8: =(CO8-CP8+CQ8+CR8+CS8) -> 1086.9107 | CV8: =(VLOOKUP(H8,INFRACASHshares2025,25,0)-CU8) -> 16313.089 | CX8: =CU8 -> 1086.9107 | DA8: =((CX8-CY9)*0.05) -> 54.345534 | DB8: =IF(CZ8>0,CZ8*0.1,0) -> 0 | DC8: =(CX8-CY8+CZ8+DA8+DB8) -> 1141.2562 | DD8: =(VLOOKUP(H8,INFRACASHshares2025,25,0)-DC8) -> 16258.744
B9: Saving | C9: Loan Application | D9: Loan Repayment | E9: Fines/Penalties | G9: 4 | H9: Arthur | L9: =IF(J9>0,(I9-J9)*0.05,0) -> 0 | M9: =IF(K9>0,K9*0.1,0) -> 0 | N9: =I9-J9+K9+L9+M9 -> 0 | O9: =(VLOOKUP(H9,INFRACASHshares2025,25,0)-N9) -> 18600 | Q9: =N9 -> 0 | T9: =IF(R9>0,(Q9-R9)*0.05,0) -> 0 | U9: =IF(S9>0,S9*0.1,0) -> 0 | V9: =(Q9-R9+S9+T9+U9) -> 0 | W9: =(VLOOKUP(H9,INFRACASHshares2025,25,0)-V9) -> 18600 | Y9: =V9 -> 0 | AB9: =IF(Z9>0,(Y9-Z9)*0.05,0) -> 0 | AC9: =IF(AA9>0,AA9*0.1,0) -> 0 | AD9: =(Y9-Z9+AA9+AB9+AC9) -> 0 | AE9: =(VLOOKUP(H9,INFRACASHshares2025,25,0)-AD9) -> 18600 | AG9: =AD9 -> 0 | AJ9: =((AG9-AH9)*0.05) -> 0 | AK9: =IF(AI9>0,AI9*0.1,0) -> 0 | AL9: =(AG9-AH9+AI9+AJ9+AK9) -> 0 | AM9: =(VLOOKUP(H9,INFRACASHshares2025,25,0)-AL9) -> 18600 | AO9: =AL9 -> 0 | AR9: =((AO9-AP9)*0.05) -> 0 | AS9: =IF(AQ9>0,AQ9*0.1,0) -> 0 | AT9: =(AO9-AP9+AQ9+AR9+AS9) -> 0 | AU9: =(VLOOKUP(H9,INFRACASHshares2025,25,0)-AT9) -> 18600 | AW9: =AT9 -> 0 | AZ9: =((AW9-AX9)*0.05) -> 0 | BA9: =IF(AY9>0,AY9*0.1,0) -> 0 | BB9: =(AW9-AX9+AY9+AZ9+BA9) -> 0 | BC9: =(VLOOKUP(H9,INFRACASHshares2025,25,0)-BB9) -> 18600 | BE9: =BB9 -> 0 | BH9: =(BE9-BF9)*0.05 -> 0 | BI9: =IF(BG9>0,BG9*0.1,0) -> 0 | BJ9: =(BE9-BF9+BG9+BH9+BI9) -> 0 | BK9: =(VLOOKUP(H9,INFRACASHshares2025,25,0)-BJ9) -> 18600 | BM9: =BJ9 -> 0 | BO9: 17000 | BP9: =(BM9-BN9)*0.05 -> 0 | BQ9: =IF(BO9>0,BO9*0.1,0) -> 1700 | BS9: =(BM9-BN9+BO9+BP9+BQ9+BR9) -> 18700 | BT9: =(VLOOKUP(H9,INFRACASHshares2025,25,0)-BS9) -> -100 | BV9: =BS9 -> 18700 | BW9: 5000 | BY9: =(BV9-BW9)*0.05 -> 685 | BZ9: =IF(BX9>0,BX9*0.1,0) -> 0 | CB9: =(BV9-BW9+BX9+BY9+BZ9) -> 14385 | CC9: =(VLOOKUP(H9,INFRACASHshares2025,25,0)-CB9) -> 4215 | CE9: =CB9 -> 14385 | CF9: 5000 | CH9: 1020.3914 | CI9: =(CE9-CF9)*0.05 -> 469.25 | CJ9: =IF((CG9+CH9)>0,((CG9+CH9)*0.1),0) -> 102.03914 | CL9: =(CE9-CF9+CG9+CI9+CJ9) -> 9956.2891 | CM9: =(VLOOKUP(H9,INFRACASHshares2025,25,0)-CL9) -> 8643.7109 | CO9: =CL9 -> 9956.2891 | CP9: 5102.04 | CR9: =((CO9-CP9)*0.05) -> 242.71246 | CS9: =IF(CQ9>0,CQ9*0.1,0) -> 0 | CU9: =(CO9-CP9+CQ9+CR9+CS9) -> 5096.9616 | CV9: =(VLOOKUP(H9,INFRACASHshares2025,25,0)-CU9) -> 13503.038 | CX9: =CU9 -> 5096.9616 | DA9: =((CX9-CY10)*0.05) -> 254.84808 | DB9: =IF(CZ9>0,CZ9*0.1,0) -> 0 | DC9: =(CX9-CY9+CZ9+DA9+DB9) -> 5351.8097 | DD9: =(VLOOKUP(H9,INFRACASHshares2025,25,0)-DC9) -> 13248.19
B10: Saving | C10: Loan Application | D10: Loan Repayment | E10: Fines/Penalties | G10: 5 | H10: Evans | K10: 20000 | L10: =IF(J10>0,(I10-J10)*0.05,0) -> 0 | M10: =IF(K10>0,K10*0.1,0) -> 2000 | N10: =I10-J10+K10+L10+M10 -> 22000 | O10: =(VLOOKUP(H10,INFRACASHshares2025,25,0)-N10) -> 9200 | Q10: =N10 -> 22000 | R10: 1000 | S10: 11340 | T10: =IF(R10>0,(Q10-R10)*0.05,0) -> 1050 | U10: =IF(S10>0,S10*0.1,0) -> 1134 | V10: =(Q10-R10+S10+T10+U10) -> 34524 | W10: =(VLOOKUP(H10,INFRACASHshares2025,25,0)-V10) -> -3324 | Y10: =V10 -> 34524 | Z10: 2000 | AB10: =IF(Z10>0,(Y10-Z10)*0.05,0) -> 1626.2 | AC10: =IF(AA10>0,AA10*0.1,0) -> 0 | AD10: =(Y10-Z10+AA10+AC10) -> 32524 | AE10: =(VLOOKUP(H10,INFRACASHshares2025,25,0)-AD10) -> -1324 | AG10: =AD10 -> 32524 | AH10: 2000 | AJ10: =((AG10-AH10)*0.05) -> 1526.2 | AK10: =IF(AI10>0,AI10*0.1,0) -> 0 | AL10: =(AG10-AH10+AI10+AJ10+AK10) -> 32050.2 | AM10: =(VLOOKUP(H10,INFRACASHshares2025,25,0)-AL10) -> -850.2 | AO10: =AL10 -> 32050.2 | AP10: 2000 | AR10: =((AO10-AP10)*0.05) -> 1502.51 | AS10: =IF(AQ10>0,AQ10*0.1,0) -> 0 | AT10: =(AO10-AP10+AQ10+AR10+AS10) -> 31552.71 | AU10: =(VLOOKUP(H10,INFRACASHshares2025,25,0)-AT10) -> -352.71 | AW10: =AT10 -> 31552.71 | AX10: 1000 | AY10: 9967.81 | AZ10: =((AW10-AX10)*0.05) -> 1527.6355 | BA10: =IF(AY10>0,AY10*0.1,0) -> 996.781 | BB10: =(AW10-AX10+AY10+AZ10+BA10) -> 43044.936 | BC10: =(VLOOKUP(H10,INFRACASHshares2025,25,0)-BB10) -> -11844.936 | BE10: =BB10 -> 43044.936 | BF10: 3000 | BG10: 5300 | BH10: =(BE10-BF10)*0.05 -> 2002.2468 | BI10: =IF(BG10>0,BG10*0.1,0) -> 530 | BJ10: =(BE10-BF10+BG10+BH10+BI10) -> 47877.183 | BK10: =(VLOOKUP(H10,INFRACASHshares2025,25,0)-BJ10) -> -16677.183 | BM10: =BJ10 -> 47877.183 | BN10: 800 | BP10: =(BM10-BN10)*0.05 -> 2353.8592 | BQ10: =IF(BO10>0,BO10*0.1,0) -> 0 | BS10: =(BM10-BN10+BO10+BP10+BQ10+BR10) -> 49431.042 | BT10: =(VLOOKUP(H10,INFRACASHshares2025,25,0)-BS10) -> -18231.042 | BV10: =BS10 -> 49431.042 | BW10: 1000 | BX10: 10000 | BY10: =(BV10-BW10)*0.05 -> 2421.5521 | BZ10: =IF(BX10>0,BX10*0.1,0) -> 1000 | CB10: =(BV10-BW10+BX10+BY10+BZ10) -> 61852.595 | CC10: =(VLOOKUP(H10,INFRACASHshares2025,25,0)-CB10) -> -30652.595 | CE10: =CB10 -> 61852.595 | CF10: 1000 | CH10: 1711.6243 | CI10: =(CE10-CF10)*0.05 -> 3042.6297 | CJ10: =IF((CG10+CH10)>0,((CG10+CH10)*0.1),0) -> 171.16243 | CL10: =(CE10-CF10+CG10+CI10+CJ10) -> 64066.387 | CM10: =(VLOOKUP(H10,INFRACASHshares2025,25,0)-CL10) -> -32866.387 | CO10: =CL10 -> 64066.387 | CP10: 54482.281 | CR10: =((CO10-CP10)*0.05) -> 479.2053 | CS10: =IF(CQ10>0,CQ10*0.1,0) -> 0 | CU10: =(CO10-CP10+CQ10+CR10+CS10) -> 10063.311 | CV10: =(VLOOKUP(H10,INFRACASHshares2025,25,0)-CU10) -> 21136.689 | CX10: =CU10 -> 10063.311 | DA10: =((CX10-CY11)*0.05) -> 503.16556 | DB10: =IF(CZ10>0,CZ10*0.1,0) -> 0 | DC10: =(CX10-CY10+CZ10+DA10+DB10) -> 10566.477 | DD10: =(VLOOKUP(H10,INFRACASHshares2025,25,0)-DC10) -> 20633.523
B11: Saving | C11: Loan Application | D11: Loan Repayment | E11: Fines/Penalties | G11: 6 | H11: Jesper | L11: =IF(J11>0,(I11-J11)*0.05,0) -> 0 | M11: =IF(K11>0,K11*0.1,0) -> 0 | N11: =I11-J11+K11+L11+M11 -> 0 | O11: =(VLOOKUP(H11,INFRACASHshares2025,25,0)-N11) -> 6600 | Q11: =N11 -> 0 | T11: =IF(R11>0,(Q11-R11)*0.05,0) -> 0 | U11: =IF(S11>0,S11*0.1,0) -> 0 | V11: =(Q11-R11+S11+T11+U11) -> 0 | W11: =(VLOOKUP(H11,INFRACASHshares2025,25,0)-V11) -> 6600 | Y11: =V11 -> 0 | AB11: =IF(Z11>0,(Y11-Z11)*0.05,0) -> 0 | AC11: =IF(AA11>0,AA11*0.1,0) -> 0 | AD11: =(Y11-Z11+AA11+AB11+AC11) -> 0 | AE11: =(VLOOKUP(H11,INFRACASHshares2025,25,0)-AD11) -> 6600 | AG11: =AD11 -> 0 | AJ11: =((AG11-AH11)*0.05) -> 0 | AK11: =IF(AI11>0,AI11*0.1,0) -> 0 | AL11: =(AG11-AH11+AI11+AJ11+AK11) -> 0 | AM11: =(VLOOKUP(H11,INFRACASHshares2025,25,0)-AL11) -> 6600 | AO11: =AL11 -> 0 | AR11: =((AO11-AP11)*0.05) -> 0 | AS11: =IF(AQ11>0,AQ11*0.1,0) -> 0 | AT11: =(AO11-AP11+AQ11+AR11+AS11) -> 0 | AU11: =(VLOOKUP(H11,INFRACASHshares2025,25,0)-AT11) -> 6600 | AW11: =AT11 -> 0 | AZ11: =((AW11-AX11)*0.05) -> 0 | BA11: =IF(AY11>0,AY11*0.1,0) -> 0 | BB11: =(AW11-AX11+AY11+AZ11+BA11) -> 0 | BC11: =(VLOOKUP(H11,INFRACASHshares2025,25,0)-BB11) -> 6600 | BE11: =BB11 -> 0 | BH11: =(BE11-BF11)*0.05 -> 0 | BI11: =IF(BG11>0,BG11*0.1,0) -> 0 | BJ11: =(BE11-BF11+BG11+BH11+BI11) -> 0 | BK11: =(VLOOKUP(H11,INFRACASHshares2025,25,0)-BJ11) -> 6600 | BM11: =BJ11 -> 0 | BP11: =(BM11-BN11)*0.05 -> 0 | BQ11: =IF(BO11>0,BO11*0.1,0) -> 0 | BS11: =(BM11-BN11+BO11+BP11+BQ11+BR11) -> 0 | BT11: =(VLOOKUP(H11,INFRACASHshares2025,25,0)-BS11) -> 6600 | BV11: =BS11 -> 0 | BY11: =(BV11-BW11)*0.05 -> 0 | BZ11: =IF(BX11>0,BX11*0.1,0) -> 0 | CA11: =0.15*BX11 -> 0 | CB11: =(BV11-BW11+BX11+BY11+BZ11+CA11) -> 0 | CC11: =(VLOOKUP(H11,INFRACASHshares2025,25,0)-CB11) -> 6600 | CE11: =CB11 -> 0 | CH11: 362.07436 | CI11: =(CE11-CF11)*0.05 -> 0 | CJ11: =IF((CG11+CH11)>0,((CG11+CH11)*0.1),0) -> 36.207436 | CL11: =(CE11-CF11+CG11+CI11+CJ11) -> 36.207436 | CM11: =(VLOOKUP(H11,INFRACASHshares2025,25,0)-CL11) -> 6563.7926 | CO11: =CL11 -> 36.207436 | CP11: 40 | CR11: =((CO11-CP11)*0.05) -> -0.18962818 | CS11: =IF(CQ11>0,CQ11*0.1,0) -> 0 | CU11: =(CO11-CP11+CQ11+CR11+CS11) -> -3.9821918 | CV11: =(VLOOKUP(H11,INFRACASHshares2025,25,0)-CU11) -> 6603.9822 | CX11: =CU11 -> -3.9821918 | DA11: =((CX11-CY12)*0.05) -> -0.19910959 | DB11: =IF(CZ11>0,CZ11*0.1,0) -> 0 | DC11: =(CX11-CY11+CZ11+DA11+DB11) -> -4.1813014 | DD11: =(VLOOKUP(H11,INFRACASHshares2025,25,0)-DC11) -> 6604.1813
B12: Saving | C12: Loan Application | D12: Loan Repayment | E12: Fines/Penalties | G12: 7 | H12: Joshua | L12: =IF(J12>0,(I12-J12)*0.05,0) -> 0 | M12: =IF(K12>0,K12*0.1,0) -> 0 | N12: =I12-J12+K12+L12+M12 -> 0 | O12: =(VLOOKUP(H12,INFRACASHshares2025,25,0)-N12) -> 40200 | Q12: =N12 -> 0 | T12: =IF(R12>0,(Q12-R12)*0.05,0) -> 0 | U12: =IF(S12>0,S12*0.1,0) -> 0 | V12: =(Q12-R12+S12+T12+U12) -> 0 | W12: =(VLOOKUP(H12,INFRACASHshares2025,25,0)-V12) -> 40200 | Y12: =V12 -> 0 | AA12: 3400 | AB12: =IF(Z12>0,(Y12-Z12)*0.05,0) -> 0 | AC12: =IF(AA12>0,AA12*0.1,0) -> 340 | AD12: =(Y12-Z12+AA12+AB12+AC12) -> 3740 | AE12: =(VLOOKUP(H12,INFRACASHshares2025,25,0)-AD12) -> 36460 | AG12: =AD12 -> 3740 | AH12: 1000 | AJ12: =((AG12-AH12)*0.05) -> 137 | AK12: =IF(AI12>0,AI12*0.1,0) -> 0 | AL12: =(AG12-AH12+AI12+AJ12+AK12) -> 2877 | AM12: =(VLOOKUP(H12,INFRACASHshares2025,25,0)-AL12) -> 37323 | AO12: =AL12 -> 2877 | AP12: 1000 | AR12: =((AO12-AP12)*0.05) -> 93.85 | AS12: =IF(AQ12>0,AQ12*0.1,0) -> 0 | AT12: =(AO12-AP12+AQ12+AR12+AS12) -> 1970.85 | AU12: =(VLOOKUP(H12,INFRACASHshares2025,25,0)-AT12) -> 38229.15 | AW12: =AT12 -> 1970.85 | AX12: 1000 | AZ12: =((AW12-AX12)*0.05) -> 48.5425 | BA12: =IF(AY12>0,AY12*0.1,0) -> 0 | BB12: =(AW12-AX12+AY12+AZ12+BA12) -> 1019.3925 | BC12: =(VLOOKUP(H12,INFRACASHshares2025,25,0)-BB12) -> 39180.607 | BE12: =BB12 -> 1019.3925 | BF12: 1019.3925 | BH12: =(BE12-BF12)*0.05 -> 0 | BI12: =IF(BG12>0,BG12*0.1,0) -> 0 | BJ12: =(BE12-BF12+BG12+BH12+BI12) -> 0 | BK12: =(VLOOKUP(H12,INFRACASHshares2025,25,0)-BJ12) -> 40200 | BM12: =BJ12 -> 0 | BP12: =(BM12-BN12)*0.05 -> 0 | BQ12: =IF(BO12>0,BO12*0.1,0) -> 0 | BS12: =(BM12-BN12+BO12+BP12+BQ12+BR12) -> 0 | BT12: =(VLOOKUP(H12,INFRACASHshares2025,25,0)-BS12) -> 40200 | BV12: =BS12 -> 0 | BY12: =(BV12-BW12)*0.05 -> 0 | BZ12: =IF(BX12>0,BX12*0.1,0) -> 0 | CB12: =(BV12-BW12+BX12+BY12+BZ12) -> 0 | CC12: =(VLOOKUP(H12,INFRACASHshares2025,25,0)-CB12) -> 40200 | CE12: =CB12 -> 0 | CG12: 11000 | CI12: =(CE12-CF12)*0.05 -> 0 | CJ12: =IF((CG12+CH12)>0,((CG12+CH12)*0.1),0) -> 1100 | CL12: =(CE12-CF12+CG12+CI12+CJ12) -> 12100 | CM12: =(VLOOKUP(H12,INFRACASHshares2025,25,0)-CL12) -> 28100 | CO12: =CL12 -> 12100 | CP12: 1100 | CR12: =((CO12-CP12)*0.05) -> 550 | CS12: =IF(CQ12>0,CQ12*0.1,0) -> 0 | CU12: =(CO12-CP12+CQ12+CR12+CS12) -> 11550 | CV12: =(VLOOKUP(H12,INFRACASHshares2025,25,0)-CU12) -> 28650 | CX12: =CU12 -> 11550 | DA12: =((CX12-CY13)*0.05) -> 577.5 | DB12: =IF(CZ12>0,CZ12*0.1,0) -> 0 | DC12: =(CX12-CY12+CZ12+DA12+DB12) -> 12127.5 | DD12: =(VLOOKUP(H12,INFRACASHshares2025,25,0)-DC12) -> 28072.5
B13: Saving | C13: Loan Application | D13: Loan Repayment | E13: Fines/Penalties | G13: 8 | H13: Kampamba | K13: 600 | L13: =IF(J13>0,(I13-J13)*0.05,0) -> 0 | M13: =IF(K13>0,K13*0.1,0) -> 60 | N13: =I13-J13+K13+L13+M13 -> 660 | O13: =(VLOOKUP(H13,INFRACASHshares2025,25,0)-N13) -> 21540 | Q13: =N13 -> 660 | R13: 1 | T13: =IF(R13>0,(Q13-R13)*0.05,0) -> 32.95 | U13: =IF(S13>0,S13*0.1,0) -> 0 | V13: =(Q13-R13+S13+T13+U13) -> 691.95 | W13: =(VLOOKUP(H13,INFRACASHshares2025,25,0)-V13) -> 21508.05 | Y13: =V13 -> 691.95 | AB13: =((Y13-Z13)*0.05) -> 34.5975 | AC13: =IF(AA13>0,AA13*0.1,0) -> 0 | AD13: =(Y13-Z13+AA13+AB13+AC13) -> 726.5475 | AE13: =(VLOOKUP(H13,INFRACASHshares2025,25,0)-AD13) -> 21473.452 | AG13: =AD13 -> 726.5475 | AJ13: =((AG13-AH13)*0.05) -> 36.327375 | AK13: =IF(AI13>0,AI13*0.1,0) -> 0 | AL13: =(AG13-AH13+AI13+AJ13+AK13) -> 762.87487 | AM13: =(VLOOKUP(H13,INFRACASHshares2025,25,0)-AL13) -> 21437.125 | AO13: =AL13 -> 762.87487 | AR13: =((AO13-AP13)*0.05) -> 38.143744 | AS13: =IF(AQ13>0,AQ13*0.1,0) -> 0 | AT13: =(AO13-AP13+AQ13+AR13+AS13) -> 801.01862 | AU13: =(VLOOKUP(H13,INFRACASHshares2025,25,0)-AT13) -> 21398.981 | AW13: =AT13 -> 801.01862 | AY13: 17500 | AZ13: =((AW13-AX13)*0.05) -> 40.050931 | BA13: =IF(AY13>0,AY13*0.1,0) -> 1750 | BB13: =(AW13-AX13+AY13+AZ13+BA13) -> 20091.07 | BC13: =(VLOOKUP(H13,INFRACASHshares2025,25,0)-BB13) -> 2108.9305 | BE13: =BB13 -> 20091.07 | BF13: 2000 | BH13: =(BE13-BF13)*0.05 -> 904.55348 | BI13: =IF(BG13>0,BG13*0.1,0) -> 0 | BJ13: =(BE13-BF13+BG13+BH13+BI13) -> 18995.623 | BK13: =(VLOOKUP(H13,INFRACASHshares2025,25,0)-BJ13) -> 3204.377 | BM13: =BJ13 -> 18995.623 | BN13: 2000 | BP13: =(BM13-BN13)*0.05 -> 849.78115 | BQ13: =IF(BO13>0,BO13*0.1,0) -> 0 | BS13: =(BM13-BN13+BO13+BP13+BQ13+BR13) -> 17845.404 | BT13: =(VLOOKUP(H13,INFRACASHshares2025,25,0)-BS13) -> 4354.5958 | BV13: =BS13 -> 17845.404 | BW13: 2000 | BY13: =(BV13-BW13)*0.05 -> 792.27021 | BZ13: =IF(BX13>0,BX13*0.1,0) -> 0 | CB13: =(BV13-BW13+BX13+BY13+BZ13) -> 16637.674 | CC13: =(VLOOKUP(H13,INFRACASHshares2025,25,0)-CB13) -> 5562.3256 | CE13: =CB13 -> 16637.674 | CF13: 2600 | CH13: 1217.8865 | CI13: =(CE13-CF13)*0.05 -> 701.88372 | CJ13: =IF((CG13+CH13)>0,((CG13+CH13)*0.1),0) -> 121.78865 | CL13: =(CE13-CF13+CG13+CI13+CJ13) -> 14861.347 | CM13: =(VLOOKUP(H13,INFRACASHshares2025,25,0)-CL13) -> 7338.6532 | CO13: =CL13 -> 14861.347 | CP13: 2621.79 | CR13: =((CO13-CP13)*0.05) -> 611.97784 | CS13: =IF(CQ13>0,CQ13*0.1,0) -> 0 | CU13: =(CO13-CP13+CQ13+CR13+CS13) -> 12851.535 | CV13: =(VLOOKUP(H13,INFRACASHshares2025,25,0)-CU13) -> 9348.4654 | CX13: =CU13 -> 12851.535 | DA13: =((CX13-CY14)*0.05) -> 642.57673 | DB13: =IF(CZ13>0,CZ13*0.1,0) -> 0 | DC13: =(CX13-CY13+CZ13+DA13+DB13) -> 13494.111 | DD13: =(VLOOKUP(H13,INFRACASHshares2025,25,0)-DC13) -> 8705.8887
B14: Saving | C14: Loan Application | D14: Loan Repayment | E14: Fines/Penalties | G14: 9 | H14: Karen Mwinga | L14: =IF(J14>0,(I14-J14)*0.05,0) -> 0 | M14: =IF(K14>0,K14*0.1,0) -> 0 | N14: =I14-J14+K14+L14+M14 -> 0 | O14: =(VLOOKUP(H14,INFRACASHshares2025,25,0)-N14) -> 15600 | Q14: =N14 -> 0 | T14: =IF(R14>0,(Q14-R14)*0.05,0) -> 0 | U14: =IF(S14>0,S14*0.1,0) -> 0 | V14: =(Q14-R14+S14+T14+U14) -> 0 | W14: =(VLOOKUP(H14,INFRACASHshares2025,25,0)-V14) -> 15600 | Y14: =V14 -> 0 | AA14: 11300 | AB14: =IF(Z14>0,(Y14-Z14)*0.05,0) -> 0 | AC14: =IF(AA14>0,AA14*0.1,0) -> 1130 | AD14: =(Y14-Z14+AA14+AB14+AC14) -> 12430 | AE14: =(VLOOKUP(H14,INFRACASHshares2025,25,0)-AD14) -> 3170 | AG14: =AD14 -> 12430 | AH14: 1200 | AJ14: =((AG14-AH14)*0.05) -> 561.5 | AK14: =IF(AI14>0,AI14*0.1,0) -> 0 | AL14: =(AG14-AH14+AI14+AJ14+AK14) -> 11791.5 | AM14: =(VLOOKUP(H14,INFRACASHshares2025,25,0)-AL14) -> 3808.5 | AO14: =AL14 -> 11791.5 | AP14: 1000 | AR14: =((AO14-AP14)*0.05) -> 539.575 | AS14: =IF(AQ14>0,AQ14*0.1,0) -> 0 | AT14: =(AO14-AP14+AQ14+AR14+AS14) -> 11331.075 | AU14: =(VLOOKUP(H14,INFRACASHshares2025,25,0)-AT14) -> 4268.925 | AW14: =AT14 -> 11331.075 | AX14: 5000 | AZ14: =((AW14-AX14)*0.05) -> 316.55375 | BA14: =IF(AY14>0,AY14*0.1,0) -> 0 | BB14: =(AW14-AX14+AY14+AZ14+BA14) -> 6647.6288 | BC14: =(VLOOKUP(H14,INFRACASHshares2025,25,0)-BB14) -> 8952.3713 | BE14: =BB14 -> 6647.6288 | BF14: 2000 | BH14: =(BE14-BF14)*0.05 -> 232.38144 | BI14: =IF(BG14>0,BG14*0.1,0) -> 0 | BJ14: =(BE14-BF14+BG14+BH14+BI14) -> 4880.0102 | BK14: =(VLOOKUP(H14,INFRACASHshares2025,25,0)-BJ14) -> 10719.99 | BM14: =BJ14 -> 4880.0102 | BN14: 2000 | BO14: 50000 | BP14: =(BM14-BN14)*0.05 -> 144.00051 | BQ14: =IF(BO14>0,BO14*0.1,0) -> 5000 | BS14: =(BM14-BN14+BO14+BP14+BQ14+BR14) -> 58024.011 | BT14: =(VLOOKUP(H14,INFRACASHshares2025,25,0)-BS14) -> -42424.011 | BV14: =BS14 -> 58024.011 | BW14: 4000 | BY14: =(BV14-BW14)*0.05 -> 2701.2005 | BZ14: =IF(BX14>0,BX14*0.1,0) -> 0 | CB14: =(BV14-BW14+BX14+BY14+BZ14) -> 56725.211 | CC14: =(VLOOKUP(H14,INFRACASHshares2025,25,0)-CB14) -> -41125.211 | CE14: =CB14 -> 56725.211 | CF14: 10000 | CH14: 855.81213 | CI14: =(CE14-CF14)*0.05 -> 2336.2606 | CJ14: =IF((CG14+CH14)>0,((CG14+CH14)*0.1),0) -> 85.581213 | CL14: =(CE14-CF14+CG14+CI14+CJ14) -> 49147.053 | CM14: =(VLOOKUP(H14,INFRACASHshares2025,25,0)-CL14) -> -33547.053 | CO14: =CL14 -> 49147.053 | CP14: 44750 | CR14: =((CO14-CP14)*0.05) -> 219.85265 | CS14: =IF(CQ14>0,CQ14*0.1,0) -> 0 | CU14: =(CO14-CP14+CQ14+CR14+CS14) -> 4616.9057 | CV14: =(VLOOKUP(H14,INFRACASHshares2025,25,0)-CU14) -> 10983.094 | CX14: =CU14 -> 4616.9057 | DA14: =((CX14-CY15)*0.05) -> 230.84528 | DB14: =IF(CZ14>0,CZ14*0.1,0) -> 0 | DC14: =(CX14-CY14+CZ14+DA14+DB14) -> 4847.7509 | DD14: =(VLOOKUP(H14,INFRACASHshares2025,25,0)-DC14) -> 10752.249
