Workbook

Sheet SHARES
C1: http://villagebankapplication.test/login | J1: 45717 | Q1: 45748 | X1: 45778 | AE1: 45809 | AL1: 45839 | AS1: 45870 | AZ1: 45901 | BG1: 45931 | BN1: 45962 | BQ1: 45992 | BT1: 46023 | BV1: INVESTMENT | BW1: INSURANCE | BZ1: SHARES | CA1: LOAN REPAYMENT | CB1: TOTAL BORROWED | CC1: MAX BORROW
A2: NAMES | B2: NUMBER | C2: INSURANCE | D2: INVESTED | E2: LOAN REP | F2: TOTAL | G2: INS-SHARE | H2: SHARES | I2: LOAN | J2: INSURANCE | K2: INVESTED | L2: LOAN REP | M2: TOTAL | N2: INS-SHARE | O2: SHARES | P2: LOAN | Q2: INSURANCE | R2: INVESTED | S2: LOAN REP | T2: TOTAL | U2: INS-SHARE | V2: SHARES | W2: LOAN | X2: INSURANCE | Y2: INVESTED | Z2: LOAN REP | AA2: TOTAL | AB2: INS-SHARE | AC2: SHARES | AD2: LOAN | AE2: INSURANCE | AF2: INVESTED | AG2: LOAN REP | AH2: TOTAL | AI2: INS-SHARE | AJ2: SHARES | AK2: LOAN | AL2: INSURANCE | AM2: INVESTED | AN2: LOAN REP | AO2: TOTAL | AP2: INS-SHARE | AQ2: SHARES | AR2: LOAN AP | AS2: INSURANCE | AT2: INVESTED | AU2: LOAN REP | AV2: TOTAL | AW2: INS-SHARE | AX2: SHARES | AY2: LOAN | AZ2: INSURANCE | BA2: INVESTED | BB2: LOAN REP | BC2: TOTAL | BD2: INS-SHARE | BE2: SHARES | BF2: LOAN | BG2: INSURANCE | BH2: INVESTED | BI2: LOAN REP | BJ2: TOTAL | BK2: INS-SHARE | BL2: SHARES | BM2: LOAN | BN2: LOAN REP | BO2: INVESTMENT | BP2: TOTAL | BQ2: LOAN REP | BR2: INVESTMENT | BS2: TOTAL | BT2: LOAN REP | BU2: TOTAL | BV2: TOTAL | BW2: TOTAL | BX2: TOTAL AMOUNT | BY2: INS-SHARES | BZ2: TOTAL | CA2: TOTAL | CB2: TOTAL
A3: shubart Nyimbili | B3: 979780593 | C3: 100 | D3: 200 | F3: =SUM(C3,D3,E3) -> 300 | G3: =C3/200 -> 0.5 | H3: =D3/200 -> 1 | J3: 100 | K3: 400 | M3: =SUM(J3,K3,L3) -> 500 | N3: =J3/200 -> 0.5 | O3: =K3/200 -> 2 | P3: 1100 | Q3: 100 | R3: 200 | S3: 200 | T3: =SUM(Q3,R3,S3) -> 500 | U3: =Q3/200 -> 0.5 | V3: =R3/200 -> 1 | X3: 100 | Y3: 200 | Z3: 200 | AA3: =SUM(X3,Y3,Z3) -> 500 | AB3: =X3/200 -> 0.5 | AC3: =Y3/200 -> 1 | AE3: 100 | AF3: 200 | AG3: 200 | AH3: =SUM(AE3,AF3,AG3) -> 500 | AI3: =AE3/200 -> 0.5 | AJ3: =AF3/200 -> 1 | AL3: 100 | AM3: 200 | AN3: 200 | AO3: =SUM(AL3,AM3,AN3) -> 500 | AP3: =AL3/200 -> 0.5 | AQ3: =AM3/200 -> 1 | AV3: =SUM(AS3,AT3,AU3) -> 0 | AW3: =AS3/200 -> 0 | AX3: =AT3/200 -> 0 | AZ3: 0 | BA3: 0 | BB3: 0 | BC3: =SUM(AZ3,BA3,BB3) -> 0 | BD3: =AZ3/200 -> 0 | BE3: =BA3/200 -> 0 | BG3: 100 | BH3: 200 | BI3: 623.61 | BJ3: =SUM(BG3,BH3,BI3) -> 923.61 | BK3: =BG3/200 -> 0.5 | BL3: =BH3/200 -> 1 | BM3: 7556.61 | BN3: 2000 | BP3: =SUM(BN3) -> 2000 | BQ3: 1000 | BS3: =SUM(BQ3) -> 1000 | BT3: 0 | BU3: =SUM(BT3) -> 0 | BV3: =SUM(BH3,BA3,AT3,AM3,AF3,Y3,R3,K3,D3) -> 1600 | BW3: =SUM(BG3,AZ3,AS3,AL3,AE3,X3,Q3,J3,C3) -> 700 | BX3: =SUM(BV3,BW3) -> 2300 | BY3: =SUM(BK3,BD3,AW3,AP3,AI3,AB3,U3,N3,G3) -> 3.5 | BZ3: =SUM(BL3,BE3,AX3,AQ3,AJ3,AC3,V3,O3,H3) -> 8 | CA3: =SUM(BT3,BQ3,BN3,BI3,BB3,AU3,AN3,AG3,Z3,S3,L3,E3) -> 4423.61 | CB3: =SUM(I3,P3,W3,AD3,AK3,AR3,AY3,BF3,BM3) -> 8656.61 | CC3: =3*BV3 -> 4800
A4: Peter Njovu | B4: 978958789 | C4: 100 | D4: 500 | F4: =SUM(C4,D4,E4) -> 600 | G4: =C4/200 -> 0.5 | H4: =D4/200 -> 2.5 | J4: 100 | K4: 400 | M4: =SUM(J4,K4,L4) -> 500 | N4: =J4/200 -> 0.5 | O4: =K4/200 -> 2 | Q4: 100 | R4: 400 | T4: =SUM(Q4,R4,S4) -> 500 | U4: =Q4/200 -> 0.5 | V4: =R4/200 -> 2 | X4: 100 | Y4: 200 | Z4: 0 | AA4: =SUM(X4,Y4,Z4) -> 300 | AB4: =X4/200 -> 0.5 | AC4: =Y4/200 -> 1 | AE4: 100 | AF4: 400 | AH4: =SUM(AE4,AF4,AG4) -> 500 | AI4: =AE4/200 -> 0.5 | AJ4: =AF4/200 -> 2 | AL4: 100 | AM4: 600 | AO4: =SUM(AL4,AM4,AN4) -> 700 | AP4: =AL4/200 -> 0.5 | AQ4: =AM4/200 -> 3 | AS4: 100 | AT4: 400 | AV4: =SUM(AS4,AT4,AU4) -> 500 | AW4: =AS4/200 -> 0.5 | AX4: =AT4/200 -> 2 | AZ4: 100 | BA4: 600 | BC4: =SUM(AZ4,BA4,BB4) -> 700 | BD4: =AZ4/200 -> 0.5 | BE4: =BA4/200 -> 3 | BG4: 100 | BH4: 400 | BI4: 0 | BJ4: =SUM(BG4,BH4,BI4) -> 500 | BK4: =BG4/200 -> 0.5 | BL4: =BH4/200 -> 2 | BN4: 0 | BO4: 500 | BP4: =SUM(BN4,BO4) -> 500 | BQ4: 0 | BR4: 500 | BS4: =SUM(BQ4) -> 0 | BT4: 0 | BU4: =SUM(BT4) -> 0 | BV4: =SUM(BH4,BA4,AT4,AM4,AF4,Y4,R4,K4,D4, BO4) -> 4400 | BW4: =SUM(BG4,AZ4,AS4,AL4,AE4,X4,Q4,J4,C4) -> 900 | BX4: =SUM(BV4,BW4) -> 5300 | BY4: =SUM(BK4,BD4,AW4,AP4,AI4,AB4,U4,N4,G4) -> 4.5 | BZ4: =SUM(BL4,BE4,AX4,AQ4,AJ4,AC4,V4,O4,H4) -> 19.5 | CA4: =SUM(BT4,BQ4,BN4,BI4,BB4,AU4,AN4,AG4,Z4,S4,L4,E4) -> 0 | CB4: =SUM(I4,P4,W4,AD4,AK4,AR4,AY4,BF4,BM4) -> 0 | CC4: =3*BV4 -> 13200
A5: Jailos Daka | B5: 973097114 | C5: 100 | D5: 200 | F5: =SUM(C5,D5,E5) -> 300 | G5: =C5/200 -> 0.5 | H5: =D5/200 -> 1 | J5: 100 | K5: 200 | M5: =SUM(J5,K5,L5) -> 300 | N5: =J5/200 -> 0.5 | O5: =K5/200 -> 1 | Q5: 100 | R5: 200 | T5: =SUM(Q5,R5,S5) -> 300 | U5: =Q5/200 -> 0.5 | V5: =R5/200 -> 1 | W5: 1000 | X5: 100 | Y5: 200 | Z5: 200 | AA5: =SUM(X5,Y5,Z5) -> 500 | AB5: =X5/200 -> 0.5 | AC5: =Y5/200 -> 1 | AE5: 100 | AF5: 200 | AG5: 200 | AH5: =SUM(AE5,AF5,AG5) -> 500 | AI5: =AE5/200 -> 0.5 | AJ5: =AF5/200 -> 1 | AL5: 100 | AM5: 200 | AN5: 200 | AO5: =SUM(AL5,AM5,AN5) -> 500 | AP5: =AL5/200 -> 0.5 | AQ5: =AM5/200 -> 1 | AR5: 1500 | AS5: 100 | AT5: 400 | AU5: 500 | AV5: =SUM(AS5,AT5,AU5) -> 1000 | AW5: =AS5/200 -> 0.5 | AX5: =AT5/200 -> 2 | AZ5: 100 | BA5: 200 | BB5: 200 | BC5: =SUM(AZ5,BA5,BB5) -> 500 | BD5: =AZ5/200 -> 0.5 | BE5: =BA5/200 -> 1 | BF5: 500 | BG5: 100 | BH5: 200 | BI5: 200 | BJ5: =SUM(BG5,BH5,BI5) -> 500 | BK5: =BG5/200 -> 0.5 | BL5: =BH5/200 -> 1 | BN5: 500 | BP5: =SUM(BN5) -> 500 | BQ5: 0 | BR5: 500 | BS5: =SUM(BQ5) -> 0 | BT5: 0 | BU5: =SUM(BT5) -> 0 | BV5: =SUM(BH5,BA5,AT5,AM5,AF5,Y5,R5,K5,D5) -> 2000 | BW5: =SUM(BG5,AZ5,AS5,AL5,AE5,X5,Q5,J5,C5) -> 900 | BX5: =SUM(BV5,BW5) -> 2900 | BY5: =SUM(BK5,BD5,AW5,AP5,AI5,AB5,U5,N5,G5) -> 4.5 | BZ5: =SUM(BL5,BE5,AX5,AQ5,AJ5,AC5,V5,O5,H5) -> 10 | CA5: =SUM(BT5,BQ5,BN5,BI5,BB5,AU5,AN5,AG5,Z5,S5,L5,E5) -> 2000 | CB5: =SUM(I5,P5,W5,AD5,AK5,AR5,AY5,BF5,BM5) -> 3000 | CC5: =3*BV5 -> 6000
A6: Gabriel nyimbili | B6: 974498509 | C6: 0 | D6: 0 | F6: =SUM(C6,D6,E6) -> 0 | G6: =C6/200 -> 0 | H6: =D6/200 -> 0 | J6: 100 | K6: 200 | M6: =SUM(J6,K6,L6) -> 300 | N6: =J6/200 -> 0.5 | O6: =K6/200 -> 1 | P6: 1000 | Q6: 100 | R6: 200 | S6: 200 | T6: =SUM(Q6,R6,S6) -> 500 | U6: =Q6/200 -> 0.5 | V6: =R6/200 -> 1 | X6: 100 | Y6: 200 | Z6: 200 | AA6: =SUM(X6,Y6,Z6) -> 500 | AB6: =X6/200 -> 0.5 | AC6: =Y6/200 -> 1 | AE6: 100 | AF6: 200 | AG6: 500 | AH6: =SUM(AE6,AF6,AG6) -> 800 | AI6: =AE6/200 -> 0.5 | AJ6: =AF6/200 -> 1 | AL6: 100 | AM6: 400 | AN6: 300 | AO6: =SUM(AL6,AM6,AN6) -> 800 | AP6: =AL6/200 -> 0.5 | AQ6: =AM6/200 -> 2 | AS6: 100 | AT6: 500 | AV6: =SUM(AS6,AT6,AU6) -> 600 | AW6: =AS6/200 -> 0.5 | AX6: =AT6/200 -> 2.5 | AZ6: 100 | BA6: 400 | BB6: 0 | BC6: =SUM(AZ6,BA6,BB6) -> 500 | BD6: =AZ6/200 -> 0.5 | BE6: =BA6/200 -> 2 | BG6: 100 | BH6: 400 | BI6: 0 | BJ6: =SUM(BG6,BH6,BI6) -> 500 | BK6: =BG6/200 -> 0.5 | BL6: =BH6/200 -> 2 | BN6: 0 | BP6: =SUM(BN6) -> 0 | BQ6: 0 | BS6: =SUM(BQ6) -> 0 | BT6: 0 | BU6: =SUM(BT6) -> 0 | BV6: =SUM(BH6,BA6,AT6,AM6,AF6,Y6,R6,K6,D6) -> 2500 | BW6: =SUM(BG6,AZ6,AS6,AL6,AE6,X6,Q6,J6,C6) -> 800 | BX6: =SUM(BV6,BW6) -> 3300 | BY6: =SUM(BK6,BD6,AW6,AP6,AI6,AB6,U6,N6,G6) -> 4 | BZ6: =SUM(BL6,BE6,AX6,AQ6,AJ6,AC6,V6,O6,H6) -> 12.5 | CA6: =SUM(BT6,BQ6,BN6,BI6,BB6,AU6,AN6,AG6,Z6,S6,L6,E6) -> 1200 | CB6: =SUM(I6,P6,W6,AD6,AK6,AR6,AY6,BF6,BM6) -> 1000 | CC6: =3*BV6 -> 7500
A7: Daniel Banda | B7: 978647507 | C7: 100 | D7: 200 | F7: =SUM(C7,D7,E7) -> 300 | G7: =C7/200 -> 0.5 | H7: =D7/200 -> 1 | I7: 800 | J7: 100 | K7: 200 | M7: =SUM(J7,K7,L7) -> 300 | N7: =J7/200 -> 0.5 | O7: =K7/200 -> 1 | Q7: 100 | R7: 200 | T7: =SUM(Q7,R7,S7) -> 300 | U7: =Q7/200 -> 0.5 | V7: =R7/200 -> 1 | X7: 100 | Y7: 200 | Z7: 0 | AA7: =SUM(X7,Y7,Z7) -> 300 | AB7: =X7/200 -> 0.5 | AC7: =Y7/200 -> 1 | AE7: 100 | AF7: 200 | AH7: 200 | AI7: =AE7/200 -> 0.5 | AJ7: =AF7/200 -> 1 | AK7: 2000 | AL7: 100 | AM7: 400 | AN7: 400 | AO7: =SUM(AL7,AM7,AN7) -> 900 | AP7: =AL7/200 -> 0.5 | AQ7: =AM7/200 -> 2 | AS7: 100 | AT7: 200 | AV7: =SUM(AS7,AT7,AU7) -> 300 | AW7: =AS7/200 -> 0.5 | AX7: =AT7/200 -> 1 | AZ7: 100 | BA7: 200 | BB7: 0 | BC7: =SUM(AZ7,BA7,BB7) -> 300 | BD7: =AZ7/200 -> 0.5 | BE7: =BA7/200 -> 1 | BF7: 2300 | BG7: 100 | BH7: 200 | BI7: 400 | BJ7: =SUM(BG7,BH7,BI7) -> 700 | BK7: =BG7/200 -> 0.5 | BL7: =BH7/200 -> 1 | BN7: 700 | BP7: =SUM(BN7) -> 700 | BQ7: 1300 | BS7: =SUM(BQ7) -> 1300 | BU7: =SUM(BT7) -> 0 | BV7: =SUM(BH7,BA7,AT7,AM7,AF7,Y7,R7,K7,D7) -> 2000 | BW7: =SUM(BG7,AZ7,AS7,AL7,AE7,X7,Q7,J7,C7) -> 900 | BX7: =SUM(BV7,BW7) -> 2900 | BY7: =SUM(BK7,BD7,AW7,AP7,AI7,AB7,U7,N7,G7) -> 4.5 | BZ7: =SUM(BL7,BE7,AX7,AQ7,AJ7,AC7,V7,O7,H7) -> 10 | CA7: =SUM(BT7,BQ7,BN7,BI7,BB7,AU7,AN7,AG7,Z7,S7,L7,E7) -> 2800 | CB7: =SUM(I7,P7,W7,AD7,AK7,AR7,AY7,BF7,BM7) -> 5100 | CC7: =3*BV7 -> 6000
A8: Faides Nyimbili | B8: 971817434 | C8: 100 | D8: 200 | F8: =SUM(C8,D8,E8) -> 300 | G8: =C8/200 -> 0.5 | H8: =D8/200 -> 1 | I8: 1000 | J8: 100 | K8: 200 | M8: =SUM(J8,K8,L8) -> 300 | N8: =J8/200 -> 0.5 | O8: =K8/200 -> 1 | Q8: 0 | R8: 0 | S8: 0 | T8: =SUM(Q8,R8,S8) -> 0 | U8: =Q8/200 -> 0 | V8: =R8/200 -> 0 | X8: 100 | Y8: 200 | Z8: 200 | AA8: =SUM(X8,Y8,Z8) -> 500 | AB8: =X8/200 -> 0.5 | AC8: =Y8/200 -> 1 | AE8: 100 | AF8: 200 | AG8: 200 | AH8: =SUM(AE8,AF8,AG8) -> 500 | AI8: =AE8/200 -> 0.5 | AJ8: =AF8/200 -> 1 | AL8: 100 | AM8: 200 | AN8: 200 | AO8: =SUM(AL8,AM8,AN8) -> 500 | AP8: =AL8/200 -> 0.5 | AQ8: =AM8/200 -> 1 | AS8: 100 | AT8: 200 | AV8: =SUM(AS8,AT8,AU8) -> 300 | AW8: =AS8/200 -> 0.5 | AX8: =AT8/200 -> 1 | AY8: 3000 | AZ8: 0 | BA8: 0 | BB8: 0 | BC8: =SUM(AZ8,BA8,BB8) -> 0 | BD8: =AZ8/200 -> 0 | BE8: =BA8/200 -> 0 | BG8: 100 | BH8: 200 | BI8: 700 | BJ8: =SUM(BG8,BH8,BI8) -> 1000 | BK8: =BG8/200 -> 0.5 | BL8: =BH8/200 -> 1 | BN8: 1000 | BP8: =SUM(BN8) -> 1000 | BQ8: 0 | BS8: =SUM(BQ8) -> 0 | BT8: 0 | BU8: =SUM(BT8) -> 0 | BV8: =SUM(BH8,BA8,AT8,AM8,AF8,Y8,R8,K8,D8) -> 1400 | BW8: =SUM(BG8,AZ8,AS8,AL8,AE8,X8,Q8,J8,C8) -> 700 | BX8: =SUM(BV8,BW8) -> 2100 | BY8: =SUM(BK8,BD8,AW8,AP8,AI8,AB8,U8,N8,G8) -> 3.5 | BZ8: =SUM(BL8,BE8,AX8,AQ8,AJ8,AC8,V8,O8,H8) -> 7 | CA8: =SUM(BT8,BQ8,BN8,BI8,BB8,AU8,AN8,AG8,Z8,S8,L8,E8) -> 2300 | CB8: =SUM(I8,P8,W8,AD8,AK8,AR8,AY8,BF8,BM8) -> 4000 | CC8: =3*BV8 -> 4200
A9: Clera Mashonga | B9: 977516128 | C9: 100 | D9: 200 | F9: =SUM(C9,D9,E9) -> 300 | G9: =C9/200 -> 0.5 | H9: =D9/200 -> 1 | J9: 100 | K9: 200 | M9: =SUM(J9,K9,L9) -> 300 | N9: =J9/200 -> 0.5 | O9: =K9/200 -> 1 | Q9: 100 | R9: 200 | T9: =SUM(Q9,R9,S9) -> 300 | U9: =Q9/200 -> 0.5 | V9: =R9/200 -> 1 | W9: 1800 | X9: 100 | Y9: 200 | Z9: 180 | AA9: =SUM(X9,Y9,Z9) -> 480 | AB9: =X9/200 -> 0.5 | AC9: =Y9/200 -> 1 | AE9: 100 | AF9: 200 | AG9: 2528 | AH9: =SUM(AE9,AF9,AG9) -> 2828 | AI9: =AE9/200 -> 0.5 | AJ9: =AF9/200 -> 1 | AK9: 1528 | AL9: 100 | AM9: 200 | AN9: 200 | AO9: =SUM(AL9,AM9,AN9) -> 500 | AP9: =AL9/200 -> 0.5 | AQ9: =AM9/200 -> 1 | AS9: 100 | AT9: 200 | AU9: 851.45 | AV9: =SUM(AS9,AT9,AU9) -> 1151.45 | AW9: =AS9/200 -> 0.5 | AX9: =AT9/200 -> 1 | AY9: 3151.45 | AZ9: 0 | BA9: 0 | BB9: 0 | BC9: =SUM(AZ9,BA9,BB9) -> 0 | BD9: =AZ9/200 -> 0 | BE9: =BA9/200 -> 0 | BG9: 100 | BH9: 0 | BI9: 300 | BJ9: =SUM(BG9,BH9,BI9) -> 400 | BK9: =BG9/200 -> 0.5 | BL9: =BH9/200 -> 0 | BN9: 2600 | BP9: =SUM(BN9) -> 2600 | BQ9: 300 | BS9: =SUM(BQ9) -> 300 | BT9: 0 | BU9: =SUM(BT9) -> 0 | BV9: =SUM(BH9,BA9,AT9,AM9,AF9,Y9,R9,K9,D9) -> 1400 | BW9: =SUM(BG9,AZ9,AS9,AL9,AE9,X9,Q9,J9,C9) -> 800 | BX9: =SUM(BV9,BW9) -> 2200 | BY9: =SUM(BK9,BD9,AW9,AP9,AI9,AB9,U9,N9,G9) -> 4 | BZ9: =SUM(BL9,BE9,AX9,AQ9,AJ9,AC9,V9,O9,H9) -> 7 | CA9: =SUM(BT9,BQ9,BN9,BI9,BB9,AU9,AN9,AG9,Z9,S9,L9,E9) -> 6959.45 | CB9: =SUM(I9,P9,W9,AD9,AK9,AR9,AY9,BF9,BM9) -> 6479.45 | CC9: =3*BV9 -> 4200
A10: Maureen Daka | B10: 976663626 | C10: 0 | D10: 0 | F10: =SUM(C10,D10,E10) -> 0 | G10: =C10/200 -> 0 | H10: =D10/200 -> 0 | J10: 0 | K10: 0 | M10: =SUM(J10,K10,L10) -> 0 | N10: =J10/200 -> 0 | O10: =K10/200 -> 0 | Q10: 100 | R10: 200 | T10: =SUM(Q10,R10,S10) -> 300 | U10: =Q10/200 -> 0.5 | V10: =R10/200 -> 1 | X10: 100 | Y10: 800 | Z10: 0 | AA10: =SUM(X10,Y10,Z10) -> 900 | AB10: =X10/200 -> 0.5 | AC10: =Y10/200 -> 4 | AD10: 3900 | AE10: 100 | AF10: 400 | AG10: 1500 | AH10: =SUM(AE10,AF10,AG10) -> 2000 | AI10: =AE10/200 -> 0.5 | AJ10: =AF10/200 -> 2 | AK10: 1300 | AL10: 100 | AN10: 200 | AO10: =SUM(AL10,AM10,AN10) -> 300 | AP10: =AL10/200 -> 0.5 | AQ10: =AM10/200 -> 0 | AU10: 300 | AV10: =SUM(AS10,AT10,AU10) -> 300 | AW10: =AS10/200 -> 0 | AX10: =AT10/200 -> 0 | AZ10: 0 | BA10: 0 | BB10: 0 | BC10: =SUM(AZ10,BA10,BB10) -> 0 | BD10: =AZ10/200 -> 0 | BE10: =BA10/200 -> 0 | BG10: 100 | BH10: 400 | BI10: 1000 | BJ10: =SUM(BG10,BH10,BI10) -> 1500 | BK10: =BG10/200 -> 0.5 | BL10: =BH10/200 -> 2 | BN10: 0 | BP10: =SUM(BN10) -> 0 | BQ10: 647 | BS10: =SUM(BQ10) -> 647 | BT10: 0 | BU10: =SUM(BT10) -> 0 | BV10: =SUM(BH10,BA10,AT10,AM10,AF10,Y10,R10,K10,D10) -> 1800 | BW10: =SUM(BG10,AZ10,AS10,AL10,AE10,X10,Q10,J10,C10) -> 500 | BX10: =SUM(BV10,BW10) -> 2300 | BY10: =SUM(BK10,BD10,AW10,AP10,AI10,AB10,U10,N10,G10) -> 2.5 | BZ10: =SUM(BL10,BE10,AX10,AQ10,AJ10,AC10,V10,O10,H10) -> 9 | CA10: =SUM(BT10,BQ10,BN10,BI10,BB10,AU10,AN10,AG10,Z10,S10,L10,E10) -> 3647 | CB10: =SUM(I10,P10,W10,AD10,AK10,AR10,AY10,BF10,BM10) -> 5200 | CC10: =3*BV10 -> 5400
A11: Lesa Chisanga | B11: 973274443 | C11: 0 | D11: 0 | F11: =SUM(C11,D11,E11) -> 0 | G11: =C11/200 -> 0 | H11: =D11/200 -> 0 | J11: 100 | K11: 200 | M11: =SUM(J11,K11,L11) -> 300 | N11: =J11/200 -> 0.5 | O11: =K11/200 -> 1 | P11: 900 | Q11: 0 | R11: 0 | S11: 0 | T11: =SUM(Q11,R11,S11) -> 0 | U11: =Q11/200 -> 0 | V11: =R11/200 -> 0 | X11: 100 | Y11: 200 | Z11: 200 | AA11: =SUM(X11,Y11,Z11) -> 500 | AB11: =X11/200 -> 0.5 | AC11: =Y11/200 -> 1 | AD11: 580 | AE11: 100 | AF11: 200 | AG11: 200 | AH11: =SUM(AE11,AF11,AG11) -> 500 | AI11: =AE11/200 -> 0.5 | AJ11: =AF11/200 -> 1 | AL11: 100 | AM11: 200 | AN11: 200 | AO11: =SUM(AL11,AM11,AN11) -> 500 | AP11: =AL11/200 -> 0.5 | AQ11: =AM11/200 -> 1 | AR11: 3000 | AS11: 100 | AT11: 200 | AU11: 500 | AV11: =SUM(AS11,AT11,AU11) -> 800 | AW11: =AS11/200 -> 0.5 | AX11: =AT11/200 -> 1 | AZ11: 100 | BA11: 200 | BB11: 200 | BC11: =SUM(AZ11,BA11,BB11) -> 500 | BD11: =AZ11/200 -> 0.5 | BE11: =BA11/200 -> 1 | BF11: 500 | BG11: 100 | BH11: 200 | BI11: 200 | BJ11: =SUM(BG11,BH11,BI11) -> 500 | BK11: =BG11/200 -> 0.5 | BL11: =BH11/200 -> 1 | BN11: 500 | BP11: =SUM(BN11) -> 500 | BQ11: 1000 | BS11: =SUM(BQ11) -> 1000 | BT11: 0 | BU11: =SUM(BT11) -> 0 | BV11: =SUM(BH11,BA11,AT11,AM11,AF11,Y11,R11,K11,D11) -> 1400 | BW11: =SUM(BG11,AZ11,AS11,AL11,AE11,X11,Q11,J11,C11) -> 700 | BX11: =SUM(BV11,BW11) -> 2100 | BY11: =SUM(BK11,BD11,AW11,AP11,AI11,AB11,U11,N11,G11) -> 3.5 | BZ11: =SUM(BL11,BE11,AX11,AQ11,AJ11,AC11,V11,O11,H11) -> 7 | CA11: =SUM(BT11,BQ11,BN11,BI11,BB11,AU11,AN11,AG11,Z11,S11,L11,E11) -> 3000 | CB11: =SUM(I11,P11,W11,AD11,AK11,AR11,AY11,BF11,BM11) -> 4980 | CC11: =3*BV11 -> 4200
A12: Michelle Nangandu | B12: 971585569 | C12: 0 | D12: 0 | F12: =SUM(C12,D12,E12) -> 0 | G12: =C12/200 -> 0 | H12: =D12/200 -> 0 | J12: 0 | K12: 0 | M12: =SUM(J12,K12,L12) -> 0 | N12: =J12/200 -> 0 | O12: =K12/200 -> 0 | Q12: 0 | R12: 0 | T12: =SUM(Q12,R12,S12) -> 0 | U12: =Q12/200 -> 0 | V12: =R12/200 -> 0 | X12: 0 | Y12: 0 | AA12: =SUM(X12,Y12,Z12) -> 0 | AB12: =X12/200 -> 0 | AC12: =Y12/200 -> 0 | AE12: 100 | AF12: 1000 | AH12: =SUM(AE12,AF12,AG12) -> 1100 | AI12: =AE12/200 -> 0.5 | AJ12: =AF12/200 -> 5 | AK12: 5000 | AL12: 100 | AM12: 200 | AN12: 200 | AO12: =SUM(AL12,AM12,AN12) -> 500 | AP12: =AL12/200 -> 0.5 | AQ12: =AM12/200 -> 1 | AV12: =SUM(AS12,AT12,AU12) -> 0 | AW12: =AS12/200 -> 0 | AX12: =AT12/200 -> 0 | AZ12: 0 | BA12: 0 | BB12: 1000 | BC12: =SUM(AZ12,BA12,BB12) -> 1000 | BD12: =AZ12/200 -> 0 | BE12: =BA12/200 -> 0 | BG12: 100 | BH12: 0 | BI12: 400 | BJ12: =SUM(BG12,BH12,BI12) -> 500 | BK12: =BG12/200 -> 0.5 | BL12: =BH12/200 -> 0 | BN12: 0 | BP12: =SUM(BN12) -> 0 | BQ12: 2950 | BS12: =SUM(BQ12) -> 2950 | BT12: 0 | BU12: =SUM(BT12) -> 0 | BV12: =SUM(BH12,BA12,AT12,AM12,AF12,Y12,R12,K12,D12) -> 1200 | BW12: =SUM(BG12,AZ12,AS12,AL12,AE12,X12,Q12,J12,C12) -> 300 | BX12: =SUM(BV12,BW12) -> 1500 | BY12: =SUM(BK12,BD12,AW12,AP12,AI12,AB12,U12,N12,G12) -> 1.5 | BZ12: =SUM(BL12,BE12,AX12,AQ12,AJ12,AC12,V12,O12,H12) -> 6 | CA12: =SUM(BT12,BQ12,BN12,BI12,BB12,AU12,AN12,AG12,Z12,S12,L12,E12) -> 4550 | CB12: =SUM(I12,P12,W12,AD12,AK12,AR12,AY12,BF12,BM12) -> 5000 | CC12: =3*BV12 -> 3600
A13: Rosemary Kalikoga | B13: 773472923 | C13: 0 | D13: 0 | F13: =SUM(C13,D13,E13) -> 0 | G13: =C13/200 -> 0 | H13: =D13/200 -> 0 | J13: 0 | K13: 0 | M13: =SUM(J13,K13,L13) -> 0 | N13: =J13/200 -> 0 | O13: =K13/200 -> 0 | Q13: 0 | R13: 0 | T13: =SUM(Q13,R13,S13) -> 0 | U13: =Q13/200 -> 0 | V13: =R13/200 -> 0 | X13: 0 | Y13: 0 | AA13: =SUM(X13,Y13,Z13) -> 0 | AB13: =X13/200 -> 0 | AC13: =Y13/200 -> 0 | AE13: 100 | AF13: 200 | AH13: =SUM(AE13,AF13,AG13) -> 300 | AI13: =AE13/200 -> 0.5 | AJ13: =AF13/200 -> 1 | AL13: 100 | AM13: 200 | AO13: =SUM(AL13,AM13,AN13) -> 300 | AP13: =AL13/200 -> 0.5 | AQ13: =AM13/200 -> 1 | AR13: 1500 | AS13: 100 | AT13: 200 | AU13: 500 | AV13: =SUM(AS13,AT13,AU13) -> 800 | AW13: =AS13/200 -> 0.5 | AX13: =AT13/200 -> 1 | AZ13: 0 | BA13: 0 | BB13: 0 | BC13: =SUM(AZ13,BA13,BB13) -> 0 | BD13: =AZ13/200 -> 0 | BE13: =BA13/200 -> 0 | BG13: 100 | BH13: 200 | BI13: 633 | BJ13: =SUM(BG13,BH13,BI13) -> 933 | BK13: =BG13/200 -> 0.5 | BL13: =BH13/200 -> 1 | BN13: 770 | BO13: 200 | BP13: =SUM(BN13,BO13) -> 970 | BQ13: 0 | BS13: =SUM(BQ13) -> 0 | BT13: 0 | BU13: =SUM(BT13) -> 0 | BV13: =SUM(BH13,BA13,AT13,AM13,AF13,Y13,R13,K13,D13) -> 800 | BW13: =SUM(BG13,AZ13,AS13,AL13,AE13,X13,Q13,J13,C13) -> 400 | BX13: =SUM(BV13,BW13) -> 1200 | BY13: =SUM(BK13,BD13,AW13,AP13,AI13,AB13,U13,N13,G13) -> 2 | BZ13: =SUM(BL13,BE13,AX13,AQ13,AJ13,AC13,V13,O13,H13) -> 4 | CA13: =SUM(BT13,BQ13,BN13,BI13,BB13,AU13,AN13,AG13,Z13,S13,L13,E13) -> 1903 | CB13: =SUM(I13,P13,W13,AD13,AK13,AR13,AY13,BF13,BM13) -> 1500 | CC13: =3*BV13 -> 2400
A14: Osward | B14: 976941466 | F14: =SUM(C14,D14,E14) -> 0 | G14: =C14/200 -> 0 | H14: =D14/200 -> 0 | M14: =SUM(J14,K14,L14) -> 0 | N14: =J14/200 -> 0 | O14: =K14/200 -> 0 | T14: =SUM(Q14,R14,S14) -> 0 | U14: =Q14/200 -> 0 | V14: =R14/200 -> 0 | AA14: =SUM(X14,Y14,Z14) -> 0 | AB14: =X14/200 -> 0 | AC14: =Y14/200 -> 0 | AH14: =SUM(AE14,AF14,AG14) -> 0 | AI14: =AE14/200 -> 0 | AJ14: =AF14/200 -> 0 | AO14: =SUM(AL14,AM14,AN14) -> 0 | AP14: =AL14/200 -> 0 | AQ14: =AM14/200 -> 0 | AV14: =SUM(AS14,AT14,AU14) -> 0 | AW14: =AS14/200 -> 0 | AX14: =AT14/200 -> 0 | AZ14: 0 | BA14: 0 | BB14: 0 | BC14: =SUM(AZ14,BA14,BB14) -> 0 | BD14: =AZ14/200 -> 0 | BE14: =BA14/200 -> 0 | BG14: 100 | BH14: 200 | BI14: 0 | BJ14: =SUM(BG14,BH14,BI14) -> 300 | BK14: =BG14/200 -> 0.5 | BL14: =BH14/200 -> 1 | BN14: 0 | BP14: =SUM(BN14) -> 0 | BQ14: 0 | BS14: =SUM(BQ14) -> 0 | BT14: 0 | BU14: =SUM(BT14) -> 0 | BV14: =SUM(BH14,BA14,AT14,AM14,AF14,Y14,R14,K14,D14) -> 200 | BW14: =SUM(BG14,AZ14,AS14,AL14,AE14,X14,Q14,J14,C14) -> 100 | BX14: =SUM(BV14,BW14) -> 300 | BY14: =SUM(BK14,BD14,AW14,AP14,AI14,AB14,U14,N14,G14) -> 0.5 | BZ14: =SUM(BL14,BE14,AX14,AQ14,AJ14,AC14,V14,O14,H14) -> 1 | CA14: =SUM(BT14,BQ14,BN14,BI14,BB14,AU14,AN14,AG14,Z14,S14,L14,E14) -> 0 | CB14: =SUM(I14,P14,W14,AD14,AK14,AR14,AY14,BF14,BM14) -> 0 | CC14: =3*BV14 -> 600
A15: TOTAL | F15: =SUM(F3:F14) -> 2100 | G15: =C15/200 -> 0 | H15: =SUM(H3:H14) -> 7.5 | I15: =SUM(I1:I14) -> 1800 | J15: =SUM(J3:J14) -> 800 | K15: =SUM(K3:K14) -> 2000 | L15: =SUM(L3:L14) -> 0 | M15: =SUM(M3:M14) -> 2800 | N15: =J15/200 -> 4 | O15: =SUM(O3:O14) -> 10 | P15: =SUM(P3:P14) -> 3000 | Q15: =SUM(Q3:Q14) -> 700 | R15: =SUM(R3:R14) -> 1600 | S15: =SUM(S3:S14) -> 400 | T15: =SUM(T3:T14) -> 2700 | U15: =Q15/200 -> 3.5 | V15: =SUM(V3:V14) -> 8 | W15: =SUM(W3:W14) -> 2800 | X15: =SUM(X3:X14) -> 900 | Y15: =SUM(Y3:Y14) -> 2400 | Z15: =sum(Z3:Z14) -> 1180 | AA15: =SUM(AA3:AA14) -> 4480 | AB15: =X15/200 -> 4.5 | AC15: =SUM(AC3:AC14) -> 12 | AD15: =sum(AD3:AD14) -> 4480 | AE15: =SUM(AE3:AE14) -> 1100 | AF15: =SUM(AF3:AF14) -> 3400 | AG15: =SUM(AG3:AG14) -> 5328 | AH15: =SUM(AH3:AH14) -> 9728 | AI15: =AE15/200 -> 5.5 | AJ15: =SUM(AJ3:AJ14) -> 17 | AK15: =sum(AK3:AK14) -> 9828 | AO15: =SUM(AO3:AO14) -> 6000 | AP15: =AL15/200 -> 0 | AQ15: =SUM(AQ3:AQ14) -> 14 | AR15: =SUM(AR3:AR14) -> 6000 | AV15: =SUM(AV3:AV14) -> 5751.45 | AW15: =AS15/200 -> 0 | AX15: =SUM(AX3:AX14) -> 11.5 | AY15: =SUM(AY3:AY14) -> 6151.45 | AZ15: =SUM(AZ3:AZ14) -> 500 | BA15: =SUM(BA3:BA14) -> 1600 | BB15: =SUM(BB3:BB14) -> 1400 | BC15: =SUM(BC3:BC14) -> 3500 | BD15: =AZ15/200 -> 2.5 | BE15: =SUM(BE3:BE14) -> 8 | BF15: =SUM(BF3:BF14) -> 3300 | BG15: =SUM(BG3:BG14) -> 1200 | BH15: =SUM(BH3:BH14) -> 2600 | BI15: =SUM(BI3:BI14) -> 4456.61 | BJ15: =SUM(BJ3:BJ14) -> 8256.61 | BK15: =SUM(BK3:BK14) -> 6 | BL15: =SUM(BL3:BL14) -> 13 | ... BQ15: =SUM(BQ3:BQ14) -> 7197 | BS15: =SUM(BS3:BS14) -> 7197 | BT15: =SUM(BT3:BT14) -> 0 | BU15: =SUM(BU3:BU14) -> 0 | BV15: =SUM(BH15,BA15,AT15,AM15,AF15,Y15,R15,K15,D15) -> 13600 | BW15: =SUM(BG15,AZ15,AS15,AL15,AE15,X15,Q15,J15,C15) -> 5200 | BX15: =SUM(BV15,BW15) -> 18800 | BY15: =SUM(BK15,BD15,AW15,AP15,AI15,AB15,U15,N15,G15) -> 26 | BZ15: =SUM(BL15,BE15,AX15,AQ15,AJ15,AC15,V15,O15,H15) -> 101 | CA15: =SUM(BT15,BQ15,BN15,BI15,BB15,AU15,AN15,AG15,Z15,S15,L15,E15) -> 28031.61 | CB15: =SUM(I15,P15,W15,AD15,AK15,AR15,AY15,BF15,BM15) -> 44916.06 | CC15: =3*BV15 -> 40800

Sheet LOAN BALANCES
B1: VILLAGE BANK 2025
B2: LOAN TRANSACTIONS | X2: APRIL
B3: 1 | C3: 2 | D3: 3 | E3: 4 | F3: 5 | G3: 6 | I3: 7 | J3: 8 | K3: 9 | L3: 10 | M3: 11 | N3: 12 | O3: 13 | P3: 14 | R3: 15 | S3: 16 | T3: 17 | U3: 18 | V3: 19 | W3: 20 | X3: 21 | Y3: 22 | AA3: 23 | AB3: 24 | AC3: 25 | AD3: 26 | AE3: 27 | AF3: 28 | AG3: 29 | AH3: 30 | AJ3: 31 | AK3: 32 | AL3: 33 | AM3: 34 | AN3: 35 | AO3: 36 | AP3: 37 | AQ3: 38 | AS3: 39 | AT3: 40 | AU3: 41 | AV3: 42 | AW3: 43 | AX3: 44 | AY3: 45 | AZ3: 46 | BB3: 47 | BC3: 48 | BD3: 49 | BE3: 50 | BF3: 51 | BG3: 52 | BH3: 53 | BI3: 54 | BK3: 55 | BL3: 56 | BM3: 57 | BN3: 58 | BO3: 59 | BP3: 60 | BQ3: 61 | BR3: 62 | BT3: 63 | BU3: 64 | BV3: 65 | BX3: 67 | BY3: 68 | BZ3: 69 | CA3: 70 | CC3: 71 | CD3: 72 | CE3: 73 | CF3: 74 | CG3: 75 | CH3: 76 | CJ3: 77 | CK3: 78 | CM3: 79 | CN3: 80 | CO3: 81 | CP3: 82 | CQ3: 83 | CR3: 84 | CS3: 85 | CT3: 86 | CV3: 87 | CW3: 88 | CX3: 89 | CY3: 90 | CZ3: 91 | DA3: 92 | DB3: 93 | DC3: 94 | DE3: 95
C4: FEBRUARY | L4: MARCH | U4: APRIL | AD4: MAY | AM4: JUNE | AV4: JULY | BE4: AUGUST | BN4: SEPTEMBER | BW4: OCTOBER | CF4: NOVEMBER | CP4: DECEMBER | CY4: JANUARY
B5: Member ID | C5: Opening Loan Balance | D5: Loan repayment | E5: Loan Application | F5: Interest 5% | G5: Interest 10% | H5: Penalty | I5: Closing Loan Balance | J5: Credit Limit | L5: Opening Loan Balance | M5: Loan repayment | N5: Loan Application | O5: Interest 5% | P5: Interest 10% | Q5: Penalty | R5: Closing Loan Balance | S5: Credit Limit | U5: Opening Loan Balance | V5: Loan repayment | W5: Loan Application | X5: Interest 5% | Y5: Interest 10% | Z5: Penalty | AA5: Closing Loan Balance | AB5: Credit Limit | AD5: Opening Loan Balance | AE5: Loan repayment | AF5: Loan Application | AG5: Interest 5% | AH5: Interest 10% | AI5: Penalty | AJ5: Closing Loan Balance | AK5: Credit Limit | AM5: Opening Loan Balance | AN5: Loan repayment | AO5: Loan Application | AP5: Interest 5% | AQ5: Interest 10% | AR5: Penalty | AS5: Closing Loan Balance | AT5: Credit Limit | AV5: Opening Loan Balance | AW5: Loan repayment | AX5: Loan Application | AY5: Interest 5% | AZ5: Interest 10% | BA5: Penalty | BB5: Closing Loan Balance | BC5: Credit Limit | BE5: Opening Loan Balance | BF5: Loan repayment | BG5: Loan Application | BH5: Interest 5% | BI5: Interest 10% | BJ5: Penalty | BK5: Closing Loan Balance | BL5: Credit Limit | BN5: Opening Loan Balance | BO5: Loan repayment | BP5: Loan Application | BQ5: Interest 5% | BR5: Interest 10% | BS5: Penalt | BT5: Closing Loan Balance | BU5: Credit Limit | BW5: Opening Loan Balance | BX5: Loan repayment | BY5: Loan Application | BZ5: Interest 5% | CA5: Interest 10% | CB5: Penalt | CC5: Closing Loan Balance | CD5: Credit Limit | CF5: Opening Loan Balance | CG5: Loan repayment | CH5: Loan Application | CI5: Forced Loan | CJ5: Interest 5% | CK5: Interest 10% | CL5: Penalt | CM5: Closing Loan Balance | CN5: Credit Limit | CP5: Opening Loan Balance | CQ5: Loan repayment | CR5: Loan Application | CS5: Interest 5% | CT5: Interest 10% | CU5: Penalty | CV5: Closing Loan Balance | CW5: Credit Limit | CY5: Opening Loan Balance | CZ5: Loan repayment | DA5: Loan Application | DB5: Interest 5% | DC5: Interest 10% | DD5: Penalty | DE5: Closing Loan Balance | DF5: Credit Limit
A6: 1 | B6: shubart Nyimbili | C6: 0 | D6: =SHARES!E3 | E6: =SHARES!I3 | F6: =0.05*(C6-D6) -> 0 | G6: =0.1*(E6) -> 0 | I6: =( (C6 -D6) + F6) + (E6 + G6 ) + SUM(H6) -> 0 | J6: =SHARES!CC3 -> 4800 | L6: =I6 -> 0 | M6: =SHARES!L3 | N6: =SHARES!P3 -> 1100 | O6: =0.05*(L6-M6) -> 0 | P6: =0.1*(N6) -> 110 | R6: =( (L6 -M6) + O6) + (N6 + P6 ) + SUM(Q6) -> 1210 | S6: =SHARES!CC3 -> 4800 | U6: =R6 -> 1210 | V6: =SHARES!S3 -> 200 | W6: =SHARES!W3 | X6: =0.05*(U6-V6) -> 50.5 | Y6: =0.1*(W6) -> 0 | AA6: =( (U6 -V6) + X6) + (W6 + Y6 ) + SUM(Z6) -> 1060.5 | AB6: =SHARES!CC3 -> 4800 | AD6: =AA6 -> 1060.5 | AE6: =SHARES!Z3 -> 200 | AF6: =SHARES!AD3 | AG6: =0.05*(AD6-AE6) -> 43.025 | AH6: =0.1*(AF6) -> 0 | AJ6: =( (AD6 -AE6) + AG6) + (AF6 + AH6 ) + SUM(AI6) -> 903.525 | AK6: =SHARES!CC3 -> 4800 | AM6: =AJ6 -> 903.525 | AN6: =SHARES!AG3 -> 200 | AO6: =SHARES!AK3 | AP6: =0.05*(AM6-AN6) -> 35.17625 | AQ6: =0.1*(AO6) -> 0 | AS6: =( (AM6 -AN6) + AP6) + (AO6 + AQ6 ) + SUM(AR6) -> 738.70125 | AT6: =SHARES!CC3 -> 4800 | AV6: =AS6 -> 738.70125 | AW6: =SHARES!AN3 -> 200 | AX6: =SHARES!AR3 | AY6: =0.05*(AV6-AW6) -> 26.935063 | AZ6: =0.1*(AX6) -> 0 | BB6: =( (AV6 -AW6) + AY6) + (AX6 + AZ6 ) + SUM(BA6) -> 565.63631 | BC6: =SHARES!CC3 -> 4800 | BE6: =BB6 -> 565.63631 | BF6: =SHARES!AU3 | BG6: =SHARES!AY3 | BH6: =0.05*(BE6-BF6) -> 28.281816 | BI6: =0.1*(BG6) -> 0 | BK6: =( (BE6 -BF6) + BH6) + (BG6 + BI6 ) + SUM(BJ6) -> 593.91813 | BL6: =SHARES!CC3 -> 4800 | BN6: =BK6 -> 593.91813 | BO6: =SHARES!BB3 -> 0 | BP6: =SHARES!BF3 | BQ6: =0.05*(BN6-BO6) -> 29.695906 | BR6: =0.1*(BP6) -> 0 | BT6: =( (BN6 -BO6) + BQ6) + (BP6 + BR6 ) + SUM(BS6) -> 623.61403 | BU6: =SHARES!CC3 -> 4800 | BW6: =BT6 -> 623.61403 | BX6: =SHARES!BI3 -> 623.61 | BY6: =SHARES!BM3 -> 7556.61 | BZ6: =0.05*(BW6-BX6) -> 0.00020172656 | CA6: =0.1*(BY6) -> 755.661 | CC6: =( (BW6 -BX6) + BZ6) + (BY6 + CA6 ) + SUM(CB6) -> 8312.2752 | CD6: =SHARES!CC3 -> 4800 | CF6: =CC6 -> 8312.2752 | CG6: =SHARES!BN3 -> 2000 | CH6: 0 | CI6: 0 | CJ6: 0 | CK6: =0.1*(CH6) -> 0 | CM6: =( (CF6 -CG6) + CJ6) + (CH6 + CJ6 + CK6 ) + SUM(CL6) -> 6312.2752 | CN6: =SHARES!CC3 -> 4800 | CP6: =CM6 -> 6312.2752 | CQ6: =SHARES!BQ3 -> 1000 | CS6: 0 | CT6: =0.1*(CR6) -> 0 | CV6: =( (CP6 -CQ6) + CS6) + (CR6 + CT6 ) + SUM(CU6) -> 5312.2752 | CW6: =SHARES!CC3 -> 4800 | CY6: =CV6 -> 5312.2752 | CZ6: =SHARES!BT3 -> 0 | DB6: 0 | DC6: =0.1*(DA6) -> 0 | DE6: =( (CY6 -CZ6) + DB6) + (DA6 + DC6 ) + SUM(DD6) -> 5312.2752 | DF6: =SHARES!CC3 -> 4800
A7: 2 | B7: Peter Njovu | C7: 0 | D7: =SHARES!E4 | E7: =SHARES!I4 | F7: =0.05*(C7-D7) -> 0 | G7: =0.1*(E7) -> 0 | I7: =( (C7 -D7) + F7) + (E7 + G7 ) + SUM(H7) -> 0 | J7: =SHARES!CC4 -> 13200 | L7: =I7 -> 0 | M7: =SHARES!L4 | N7: =SHARES!P4 | O7: =0.05*(L7-M7) -> 0 | P7: =0.1*(N7) -> 0 | R7: =( (L7 -M7) + O7) + (N7 + P7 ) + SUM(Q7) -> 0 | S7: =SHARES!CC4 -> 13200 | U7: =R7 -> 0 | V7: =SHARES!S4 | W7: =SHARES!W4 | X7: =0.05*(U7-V7) -> 0 | Y7: =0.1*(W7) -> 0 | AA7: =( (U7 -V7) + X7) + (W7 + Y7 ) + SUM(Z7) -> 0 | AB7: =SHARES!CC4 -> 13200 | AD7: =AA7 -> 0 | AE7: =SHARES!Z4 -> 0 | AF7: =SHARES!AD4 | AG7: =0.05*(AD7-AE7) -> 0 | AH7: =0.1*(AF7) -> 0 | AJ7: =( (AD7 -AE7) + AG7) + (AF7 + AH7 ) + SUM(AI7) -> 0 | AK7: =SHARES!CC4 -> 13200 | AM7: =AJ7 -> 0 | AN7: =SHARES!AG4 | AO7: =SHARES!AK4 | AP7: =0.05*(AM7-AN7) -> 0 | AQ7: =0.1*(AO7) -> 0 | AS7: =( (AM7 -AN7) + AP7) + (AO7 + AQ7 ) + SUM(AR7) -> 0 | AT7: =SHARES!CC4 -> 13200 | AV7: =AS7 -> 0 | AW7: =SHARES!AN4 | AX7: =SHARES!AR4 | AY7: =0.05*(AV7-AW7) -> 0 | AZ7: =0.1*(AX7) -> 0 | BB7: =( (AV7 -AW7) + AY7) + (AX7 + AZ7 ) + SUM(BA7) -> 0 | BC7: =SHARES!CC4 -> 13200 | BE7: =BB7 -> 0 | BF7: =SHARES!AU4 | BG7: =SHARES!AY4 | BH7: =0.05*(BE7-BF7) -> 0 | BI7: =0.1*(BG7) -> 0 | BK7: =( (BE7 -BF7) + BH7) + (BG7 + BI7 ) + SUM(BJ7) -> 0 | BL7: =SHARES!CC4 -> 13200 | BN7: =BK7 -> 0 | BO7: =SHARES!BB4 | BP7: =SHARES!BF4 | BQ7: =0.05*(BN7-BO7) -> 0 | BR7: =0.1*(BP7) -> 0 | BT7: =( (BN7 -BO7) + BQ7) + (BP7 + BR7 ) + SUM(BS7) -> 0 | BU7: =SHARES!CC4 -> 13200 | BW7: =BT7 -> 0 | BX7: =SHARES!BI4 -> 0 | BY7: =SHARES!BM4 | BZ7: =0.05*(BW7-BX7) -> 0 | CA7: =0.1*(BY7) -> 0 | CC7: =( (BW7 -BX7) + BZ7) + (BY7 + CA7 ) + SUM(CB7) -> 0 | CD7: =SHARES!CC4 -> 13200 | CF7: =CC7 -> 0 | CG7: =SHARES!BN4 -> 0 | CH7: 0 | CI7: 0 | CJ7: 0 | CK7: =0.1*(CH7) -> 0 | CM7: =( (CF7 -CG7) + CJ7) + (CH7 + CJ7 + CK7 ) + SUM(CL7) -> 0 | CN7: =SHARES!CC4 -> 13200 | CP7: =CM7 -> 0 | CQ7: =SHARES!BQ4 -> 0 | CS7: 0 | CT7: =0.1*(CR7) -> 0 | CV7: =( (CP7 -CQ7) + CS7) + (CR7 + CT7 ) + SUM(CU7) -> 0 | CW7: =SHARES!CC4 -> 13200 | CY7: =CV7 -> 0 | CZ7: =SHARES!BT4 -> 0 | DB7: 0 | DC7: =0.1*(DA7) -> 0 | DE7: =( (CY7 -CZ7) + DB7) + (DA7 + DC7 ) + SUM(DD7) -> 0 | DF7: =SHARES!CC4 -> 13200
A8: 2 | B8: Jailos Daka | C8: 0 | D8: =SHARES!E5 | E8: =SHARES!I5 | F8: =0.05*(C8-D8) -> 0 | G8: =0.1*(E8) -> 0 | I8: =( (C8 -D8) + F8) + (E8 + G8 ) + SUM(H8) -> 0 | J8: =SHARES!CC5 -> 6000 | L8: =I8 -> 0 | M8: =SHARES!L5 | N8: =SHARES!P5 | O8: =0.05*(L8-M8) -> 0 | P8: =0.1*(N8) -> 0 | R8: =( (L8 -M8) + O8) + (N8 + P8 ) + SUM(Q8) -> 0 | S8: =SHARES!CC5 -> 6000 | U8: =R8 -> 0 | V8: =SHARES!S5 | W8: =SHARES!W5 -> 1000 | X8: =0.05*(U8-V8) -> 0 | Y8: =0.1*(W8) -> 100 | AA8: =( (U8 -V8) + X8) + (W8 + Y8 ) + SUM(Z8) -> 1100 | AB8: =SHARES!CC5 -> 6000 | AD8: =AA8 -> 1100 | AE8: =SHARES!Z5 -> 200 | AF8: =SHARES!AD5 | AG8: =0.05*(AD8-AE8) -> 45 | AH8: =0.1*(AF8) -> 0 | AJ8: =( (AD8 -AE8) + AG8) + (AF8 + AH8 ) + SUM(AI8) -> 945 | AK8: =SHARES!CC5 -> 6000 | AM8: =AJ8 -> 945 | AN8: =SHARES!AG5 -> 200 | AO8: =SHARES!AK5 | AP8: =0.05*(AM8-AN8) -> 37.25 | AQ8: =0.1*(AO8) -> 0 | AS8: =( (AM8 -AN8) + AP8) + (AO8 + AQ8 ) + SUM(AR8) -> 782.25 | AT8: =SHARES!CC5 -> 6000 | AV8: =AS8 -> 782.25 | AW8: =SHARES!AN5 -> 200 | AX8: =SHARES!AR5 -> 1500 | AY8: =0.05*(AV8-AW8) -> 29.1125 | AZ8: =0.1*(AX8) -> 150 | BB8: =( (AV8 -AW8) + AY8) + (AX8 + AZ8 ) + SUM(BA8) -> 2261.3625 | BC8: =SHARES!CC5 -> 6000 | BE8: =BB8 -> 2261.3625 | BF8: =SHARES!AU5 -> 500 | BG8: =SHARES!AY5 | BH8: =0.05*(BE8-BF8) -> 88.068125 | BI8: =0.1*(BG8) -> 0 | BK8: =( (BE8 -BF8) + BH8) + (BG8 + BI8 ) + SUM(BJ8) -> 1849.4306 | BL8: =SHARES!CC5 -> 6000 | BN8: =BK8 -> 1849.4306 | BO8: =SHARES!BB5 -> 200 | BP8: =SHARES!BF5 -> 500 | BQ8: =0.05*(BN8-BO8) -> 82.471531 | BR8: =0.1*(BP8) -> 50 | BT8: =( (BN8 -BO8) + BQ8) + (BP8 + BR8 ) + SUM(BS8) -> 2281.9022 | BU8: =SHARES!CC5 -> 6000 | BW8: =BT8 -> 2281.9022 | BX8: =SHARES!BI5 -> 200 | BY8: =SHARES!BM5 | BZ8: =0.05*(BW8-BX8) -> 104.09511 | CA8: =0.1*(BY8) -> 0 | CC8: =( (BW8 -BX8) + BZ8) + (BY8 + CA8 ) + SUM(CB8) -> 2185.9973 | CD8: =SHARES!CC5 -> 6000 | CF8: =CC8 -> 2185.9973 | CG8: =SHARES!BN5 -> 500 | CH8: 0 | CI8: 0 | CJ8: 0 | CK8: =0.1*(CH8) -> 0 | CM8: =( (CF8 -CG8) + CJ8) + (CH8 + CJ8 + CK8 ) + SUM(CL8) -> 1685.9973 | CN8: =SHARES!CC5 -> 6000 | CP8: =CM8 -> 1685.9973 | CQ8: 0 | CS8: 0 | CT8: =0.1*(CR8) -> 0 | CV8: =( (CP8 -CQ8) + CS8) + (CR8 + CT8 ) + SUM(CU8) -> 1685.9973 | CW8: =SHARES!CC5 -> 6000 | CY8: =CV8 -> 1685.9973 | CZ8: =SHARES!BT5 -> 0 | DB8: 0 | DC8: =0.1*(DA8) -> 0 | DE8: =( (CY8 -CZ8) + DB8) + (DA8 + DC8 ) + SUM(DD8) -> 1685.9973 | DF8: =SHARES!CC5 -> 6000
A9: 3 | B9: Gabriel Nyimbili | C9: 0 | D9: =SHARES!E6 | E9: =SHARES!I6 | F9: =0.05*(C9-D9) -> 0 | G9: =0.1*(E9) -> 0 | I9: =( (C9 -D9) + F9) + (E9 + G9 ) + SUM(H9) -> 0 | J9: =SHARES!CC6 -> 7500 | L9: =I9 -> 0 | M9: =SHARES!L6 | N9: =SHARES!P6 -> 1000 | O9: =0.05*(L9-M9) -> 0 | P9: =0.1*(N9) -> 100 | R9: =( (L9 -M9) + O9) + (N9 + P9 ) + SUM(Q9) -> 1100 | S9: =SHARES!CC6 -> 7500 | U9: =R9 -> 1100 | V9: =SHARES!S6 -> 200 | W9: =SHARES!W6 | X9: =0.05*(U9-V9) -> 45 | Y9: =0.1*(W9) -> 0 | AA9: =( (U9 -V9) + X9) + (W9 + Y9 ) + SUM(Z9) -> 945 | AB9: =SHARES!CC6 -> 7500 | AD9: =AA9 -> 945 | AE9: =SHARES!Z6 -> 200 | AF9: =SHARES!AD6 | AG9: =0.05*(AD9-AE9) -> 37.25 | AH9: =0.1*(AF9) -> 0 | AJ9: =( (AD9 -AE9) + AG9) + (AF9 + AH9 ) + SUM(AI9) -> 782.25 | AK9: =SHARES!CC6 -> 7500 | AM9: =AJ9 -> 782.25 | AN9: =SHARES!AG6 -> 500 | AO9: =SHARES!AK6 | AP9: =0.05*(AM9-AN9) -> 14.1125 | AQ9: =0.1*(AO9) -> 0 | AS9: =( (AM9 -AN9) + AP9) + (AO9 + AQ9 ) + SUM(AR9) -> 296.3625 | AT9: =SHARES!CC6 -> 7500 | AV9: =AS9 -> 296.3625 | AW9: =SHARES!AN6 -> 300 | AX9: =SHARES!AR6 | AY9: =0.05*(AV9-AW9) -> -0.181875 | AZ9: =0.1*(AX9) -> 0 | BB9: =( (AV9 -AW9) + AY9) + (AX9 + AZ9 ) + SUM(BA9) -> -3.819375 | BC9: =SHARES!CC6 -> 7500 | BE9: =BB9 -> -3.819375 | BF9: =SHARES!AU6 | BG9: =SHARES!AY6 | BH9: =0.05*(BE9-BF9) -> -0.19096875 | BI9: =0.1*(BG9) -> 0 | BK9: =( (BE9 -BF9) + BH9) + (BG9 + BI9 ) + SUM(BJ9) -> -4.0103437 | BL9: =SHARES!CC6 -> 7500 | BN9: =BK9 -> -4.0103437 | BO9: =SHARES!BB6 -> 0 | BP9: =SHARES!BF6 | BQ9: =0.05*(BN9-BO9) -> -0.20051719 | BR9: =0.1*(BP9) -> 0 | BT9: =( (BN9 -BO9) + BQ9) + (BP9 + BR9 ) + SUM(BS9) -> -4.2108609 | BU9: =SHARES!CC6 -> 7500 | BW9: =BT9 -> -4.2108609 | BX9: =SHARES!BI6 -> 0 | BY9: =SHARES!BM6 | BZ9: =0.05*(BW9-BX9) -> -0.21054305 | CA9: =0.1*(BY9) -> 0 | CC9: =( (BW9 -BX9) + BZ9) + (BY9 + CA9 ) + SUM(CB9) -> -4.421404 | CD9: =SHARES!CC6 -> 7500 | CF9: =CC9 -> -4.421404 | CG9: =SHARES!BN6 -> 0 | CH9: 0 | CI9: 0 | CJ9: 0 | CK9: =0.1*(CH9) -> 0 | CM9: =( (CF9 -CG9) + CJ9) + (CH9 + CJ9 + CK9 ) + SUM(CL9) -> -4.421404 | CN9: =SHARES!CC6 -> 7500 | CP9: =CM9 -> -4.421404 | CQ9: 0 | CS9: 0 | CT9: =0.1*(CR9) -> 0 | CV9: =( (CP9 -CQ9) + CS9) + (CR9 + CT9 ) + SUM(CU9) -> -4.421404 | CW9: =SHARES!CC6 -> 7500 | CY9: =CV9 -> -4.421404 | CZ9: =SHARES!BT6 -> 0 | DB9: 0 | DC9: =0.1*(DA9) -> 0 | DE9: =( (CY9 -CZ9) + DB9) + (DA9 + DC9 ) + SUM(DD9) -> -4.421404 | DF9: =SHARES!CC6 -> 7500
A10: 4 | B10: Daniel Banda | C10: 0 | D10: =SHARES!E7 | E10: =SHARES!I7 -> 800 | F10: =0.05*(C10-D10) -> 0 | G10: =0.1*(E10) -> 80 | I10: =( (C10 -D10) + F10) + (E10 + G10 ) + SUM(H10) -> 880 | J10: =SHARES!CC7 -> 6000 | L10: =I10 -> 880 | M10: =SHARES!L7 | N10: =SHARES!P7 | O10: =0.05*(L10-M10) -> 44 | P10: =0.1*(N10) -> 0 | R10: =( (L10 -M10) + O10) + (N10 + P10 ) + SUM(Q10) -> 924 | S10: =SHARES!CC7 -> 6000 | U10: =R10 -> 924 | V10: =SHARES!S7 | W10: =SHARES!W7 | X10: =0.05*(U10-V10) -> 46.2 | Y10: =0.1*(W10) -> 0 | AA10: =( (U10 -V10) + X10) + (W10 + Y10 ) + SUM(Z10) -> 970.2 | AB10: =SHARES!CC7 -> 6000 | AD10: =AA10 -> 970.2 | AE10: =SHARES!Z7 -> 0 | AF10: =SHARES!AD7 | AG10: =0.05*(AD10-AE10) -> 48.51 | AH10: =0.1*(AF10) -> 0 | AJ10: =( (AD10 -AE10) + AG10) + (AF10 + AH10 ) + SUM(AI10) -> 1018.71 | AK10: =SHARES!CC7 -> 6000 | AM10: =AJ10 -> 1018.71 | AN10: =SHARES!AG7 | AO10: =SHARES!AK7 -> 2000 | AP10: =0.05*(AM10-AN10) -> 50.9355 | AQ10: =0.1*(AO10) -> 200 | AS10: =( (AM10 -AN10) + AP10) + (AO10 + AQ10 ) + SUM(AR10) -> 3269.6455 | AT10: =SHARES!CC7 -> 6000 | AV10: =AS10 -> 3269.6455 | AW10: =SHARES!AN7 -> 400 | AX10: =SHARES!AR7 | AY10: =0.05*(AV10-AW10) -> 143.48227 | AZ10: =0.1*(AX10) -> 0 | BB10: =( (AV10 -AW10) + AY10) + (AX10 + AZ10 ) + SUM(BA10) -> 3013.1278 | BC10: =SHARES!CC7 -> 6000 | BE10: =BB10 -> 3013.1278 | BF10: =SHARES!AU7 | BG10: =SHARES!AY7 | BH10: =0.05*(BE10-BF10) -> 150.65639 | BI10: =0.1*(BG10) -> 0 | BK10: =( (BE10 -BF10) + BH10) + (BG10 + BI10 ) + SUM(BJ10) -> 3163.7842 | BL10: =SHARES!CC7 -> 6000 | BN10: =BK10 -> 3163.7842 | BO10: =SHARES!BB7 -> 0 | BP10: =SHARES!BF7 -> 2300 | BQ10: =0.05*(BN10-BO10) -> 158.18921 | BR10: =0.1*(BP10) -> 230 | BT10: =( (BN10 -BO10) + BQ10) + (BP10 + BR10 ) + SUM(BS10) -> 5851.9734 | BU10: =SHARES!CC7 -> 6000 | BW10: =BT10 -> 5851.9734 | BX10: =SHARES!BI7 -> 400 | BY10: =SHARES!BM7 | BZ10: =0.05*(BW10-BX10) -> 272.59867 | CA10: =0.1*(BY10) -> 0 | CC10: =( (BW10 -BX10) + BZ10) + (BY10 + CA10 ) + SUM(CB10) -> 5724.572 | CD10: =SHARES!CC7 -> 6000 | CF10: =CC10 -> 5724.572 | CG10: =SHARES!BN7 -> 700 | CH10: 0 | CI10: 0 | CJ10: 0 | CK10: =0.1*(CH10) -> 0 | CM10: =( (CF10 -CG10) + CJ10) + (CH10 + CJ10 + CK10 ) + SUM(CL10) -> 5024.572 | CN10: =SHARES!CC7 -> 6000 | CP10: =CM10 -> 5024.572 | CQ10: =SHARES!BQ7 -> 1300 | CS10: 0 | CT10: =0.1*(CR10) -> 0 | CV10: =( (CP10 -CQ10) + CS10) + (CR10 + CT10 ) + SUM(CU10) -> 3724.572 | CW10: =SHARES!CC7 -> 6000 | CY10: =CV10 -> 3724.572 | CZ10: =SHARES!BT7 | DB10: 0 | DC10: =0.1*(DA10) -> 0 | DE10: =( (CY10 -CZ10) + DB10) + (DA10 + DC10 ) + SUM(DD10) -> 3724.572 | DF10: =SHARES!CC7 -> 6000
A11: 6 | B11: Faides Nyimbili | C11: 0 | D11: =SHARES!E8 | E11: =SHARES!I8 -> 1000 | F11: =0.05*(C11-D11) -> 0 | G11: =0.1*(E11) -> 100 | I11: =( (C11 -D11) + F11) + (E11 + G11 ) + SUM(H11) -> 1100 | J11: =SHARES!CC8 -> 4200 | L11: =I11 -> 1100 | M11: =SHARES!L8 | N11: =SHARES!P8 | O11: =0.05*(L11-M11) -> 55 | P11: =0.1*(N11) -> 0 | R11: =( (L11 -M11) + O11) + (N11 + P11 ) + SUM(Q11) -> 1155 | S11: =SHARES!CC8 -> 4200 | U11: =R11 -> 1155 | V11: =SHARES!S8 -> 0 | W11: =SHARES!W8 | X11: =0.05*(U11-V11) -> 57.75 | Y11: =0.1*(W11) -> 0 | AA11: =( (U11 -V11) + X11) + (W11 + Y11 ) + SUM(Z11) -> 1212.75 | AB11: =SHARES!CC8 -> 4200 | AD11: =AA11 -> 1212.75 | AE11: =SHARES!Z8 -> 200 | AF11: =SHARES!AD8 | AG11: =0.05*(AD11-AE11) -> 50.6375 | AH11: =0.1*(AF11) -> 0 | AJ11: =( (AD11 -AE11) + AG11) + (AF11 + AH11 ) + SUM(AI11) -> 1063.3875 | AK11: =SHARES!CC8 -> 4200 | AM11: =AJ11 -> 1063.3875 | AN11: =SHARES!AG8 -> 200 | AO11: =SHARES!AK8 | AP11: =0.05*(AM11-AN11) -> 43.169375 | AQ11: =0.1*(AO11) -> 0 | AS11: =( (AM11 -AN11) + AP11) + (AO11 + AQ11 ) + SUM(AR11) -> 906.55687 | AT11: =SHARES!CC8 -> 4200 | AV11: =AS11 -> 906.55687 | AW11: =SHARES!AN8 -> 200 | AX11: =SHARES!AR8 | AY11: =0.05*(AV11-AW11) -> 35.327844 | AZ11: =0.1*(AX11) -> 0 | BB11: =( (AV11 -AW11) + AY11) + (AX11 + AZ11 ) + SUM(BA11) -> 741.88472 | BC11: =SHARES!CC8 -> 4200 | BE11: =BB11 -> 741.88472 | BF11: =SHARES!AU8 | BG11: =SHARES!AY8 -> 3000 | BH11: =0.05*(BE11-BF11) -> 37.094236 | BI11: =0.1*(BG11) -> 300 | BK11: =( (BE11 -BF11) + BH11) + (BG11 + BI11 ) + SUM(BJ11) -> 4078.979 | BL11: =SHARES!CC8 -> 4200 | BN11: =BK11 -> 4078.979 | BO11: =SHARES!BB8 -> 0 | BP11: =SHARES!BF8 | BQ11: =0.05*(BN11-BO11) -> 203.94895 | BR11: =0.1*(BP11) -> 0 | BT11: =( (BN11 -BO11) + BQ11) + (BP11 + BR11 ) + SUM(BS11) -> 4282.9279 | BU11: =SHARES!CC8 -> 4200 | BW11: =BT11 -> 4282.9279 | BX11: =SHARES!BI8 -> 700 | BY11: =SHARES!BM8 | BZ11: =0.05*(BW11-BX11) -> 179.1464 | CA11: =0.1*(BY11) -> 0 | CC11: =( (BW11 -BX11) + BZ11) + (BY11 + CA11 ) + SUM(CB11) -> 3762.0743 | CD11: =SHARES!CC8 -> 4200 | CF11: =CC11 -> 3762.0743 | CG11: =SHARES!BN8 -> 1000 | CH11: 0 | CI11: 0 | CJ11: 0 | CK11: =0.1*(CH11) -> 0 | CM11: =( (CF11 -CG11) + CJ11) + (CH11 + CJ11 + CK11 ) + SUM(CL11) -> 2762.0743 | CN11: =SHARES!CC8 -> 4200 | CP11: =CM11 -> 2762.0743 | CQ11: =SHARES!BQ8 -> 0 | CS11: 0 | CT11: =0.1*(CR11) -> 0 | CV11: =( (CP11 -CQ11) + CS11) + (CR11 + CT11 ) + SUM(CU11) -> 2762.0743 | CW11: =SHARES!CC8 -> 4200 | CY11: =CV11 -> 2762.0743 | CZ11: =SHARES!BT8 -> 0 | DB11: 0 | DC11: =0.1*(DA11) -> 0 | DE11: =( (CY11 -CZ11) + DB11) + (DA11 + DC11 ) + SUM(DD11) -> 2762.0743 | DF11: =SHARES!CC8 -> 4200
A12: 7 | B12: Clera Mashonga | C12: 0 | D12: =SHARES!E9 | E12: =SHARES!I9 | F12: =0.05*(C12-D12) -> 0 | G12: =0.1*(E12) -> 0 | I12: =( (C12 -D12) + F12) + (E12 + G12 ) + SUM(H12) -> 0 | J12: =SHARES!CC9 -> 4200 | L12: =I12 -> 0 | M12: =SHARES!L9 | N12: =SHARES!P9 | O12: =0.05*(L12-M12) -> 0 | P12: =0.1*(N12) -> 0 | R12: =( (L12 -M12) + O12) + (N12 + P12 ) + SUM(Q12) -> 0 | S12: =SHARES!CC9 -> 4200 | U12: =R12 -> 0 | V12: =SHARES!S9 | W12: =SHARES!W9 -> 1800 | X12: =0.05*(U12-V12) -> 0 | Y12: =0.1*(W12) -> 180 | AA12: =( (U12 -V12) + X12) + (W12 + Y12 ) + SUM(Z12) -> 1980 | AB12: =SHARES!CC9 -> 4200 | AD12: =AA12 -> 1980 | AE12: =SHARES!Z9 -> 180 | AF12: =SHARES!AD9 | AG12: =0.05*(AD12-AE12) -> 90 | AH12: =0.1*(AF12) -> 0 | AJ12: =( (AD12 -AE12) + AG12) + (AF12 + AH12 ) + SUM(AI12) -> 1890 | AK12: =SHARES!CC9 -> 4200 | AM12: =AJ12 -> 1890 | AN12: =SHARES!AG9 -> 2528 | AO12: =SHARES!AK9 -> 1528 | AP12: =0.05*(AM12-AN12) -> -31.9 | AQ12: =0.1*(AO12) -> 152.8 | AS12: =( (AM12 -AN12) + AP12) + (AO12 + AQ12 ) + SUM(AR12) -> 1010.9 | AT12: =SHARES!CC9 -> 4200 | AV12: =AS12 -> 1010.9 | AW12: =SHARES!AN9 -> 200 | AX12: =SHARES!AR9 | AY12: =0.05*(AV12-AW12) -> 40.545 | AZ12: =0.1*(AX12) -> 0 | BB12: =( (AV12 -AW12) + AY12) + (AX12 + AZ12 ) + SUM(BA12) -> 851.445 | BC12: =SHARES!CC9 -> 4200 | BE12: =BB12 -> 851.445 | BF12: =SHARES!AU9 -> 851.45 | BG12: =SHARES!AY9 -> 3151.45 | BH12: =0.05*(BE12-BF12) -> -0.00025 | BI12: =0.1*(BG12) -> 315.145 | BK12: =( (BE12 -BF12) + BH12) + (BG12 + BI12 ) + SUM(BJ12) -> 3466.5898 | BL12: =SHARES!CC9 -> 4200 | BN12: =BK12 -> 3466.5898 | BO12: =SHARES!BB9 -> 0 | BP12: =SHARES!BF9 | BQ12: =0.05*(BN12-BO12) -> 173.32949 | BR12: =0.1*(BP12) -> 0 | BT12: =( (BN12 -BO12) + BQ12) + (BP12 + BR12 ) + SUM(BS12) -> 3639.9192 | BU12: =SHARES!CC9 -> 4200 | BW12: =BT12 -> 3639.9192 | BX12: =SHARES!BI9 -> 300 | BY12: =SHARES!BM9 | BZ12: =0.05*(BW12-BX12) -> 166.99596 | CA12: =0.1*(BY12) -> 0 | CC12: =( (BW12 -BX12) + BZ12) + (BY12 + CA12 ) + SUM(CB12) -> 3506.9152 | CD12: =SHARES!CC9 -> 4200 | CF12: =CC12 -> 3506.9152 | CG12: =SHARES!BN9 -> 2600 | CH12: 0 | CI12: 0 | CJ12: 0 | CK12: =0.1*(CH12) -> 0 | CM12: =( (CF12 -CG12) + CJ12) + (CH12 + CJ12 + CK12 ) + SUM(CL12) -> 906.9152 | CN12: =SHARES!CC9 -> 4200 | CP12: =CM12 -> 906.9152 | CQ12: =SHARES!BQ9 -> 300 | CS12: 0 | CT12: =0.1*(CR12) -> 0 | CV12: =( (CP12 -CQ12) + CS12) + (CR12 + CT12 ) + SUM(CU12) -> 606.9152 | CW12: =SHARES!CC9 -> 4200 | CY12: =CV12 -> 606.9152 | CZ12: =SHARES!BT9 -> 0 | DB12: 0 | DC12: =0.1*(DA12) -> 0 | DE12: =( (CY12 -CZ12) + DB12) + (DA12 + DC12 ) + SUM(DD12) -> 606.9152 | DF12: =SHARES!CC9 -> 4200
A13: 8 | B13: Maureen Daka | C13: 0 | D13: =SHARES!E10 | E13: =SHARES!I10 | F13: =0.05*(C13-D13) -> 0 | G13: =0.1*(E13) -> 0 | I13: =( (C13 -D13) + F13) + (E13 + G13 ) + SUM(H13) -> 0 | J13: =SHARES!CC10 -> 5400 | L13: =I13 -> 0 | M13: =SHARES!L10 | N13: =SHARES!P10 | O13: =0.05*(L13-M13) -> 0 | P13: =0.1*(N13) -> 0 | R13: =( (L13 -M13) + O13) + (N13 + P13 ) + SUM(Q13) -> 0 | S13: =SHARES!CC10 -> 5400 | U13: =R13 -> 0 | V13: =SHARES!S10 | W13: =SHARES!W10 | X13: =0.05*(U13-V13) -> 0 | Y13: =0.1*(W13) -> 0 | AA13: =( (U13 -V13) + X13) + (W13 + Y13 ) + SUM(Z13) -> 0 | AB13: =SHARES!CC10 -> 5400 | AD13: =AA13 -> 0 | AE13: =SHARES!Z10 -> 0 | AF13: =SHARES!AD10 -> 3900 | AG13: =0.05*(AD13-AE13) -> 0 | AH13: =0.1*(AF13) -> 390 | AJ13: =( (AD13 -AE13) + AG13) + (AF13 + AH13 ) + SUM(AI13) -> 4290 | AK13: =SHARES!CC10 -> 5400 | AM13: =AJ13 -> 4290 | AN13: =SHARES!AG10 -> 1500 | AO13: =SHARES!AK10 -> 1300 | AP13: =0.05*(AM13-AN13) -> 139.5 | AQ13: =0.1*(AO13) -> 130 | AS13: =( (AM13 -AN13) + AP13) + (AO13 + AQ13 ) + SUM(AR13) -> 4359.5 | AT13: =SHARES!CC10 -> 5400 | AV13: =AS13 -> 4359.5 | AW13: =SHARES!AN10 -> 200 | AX13: =SHARES!AR10 | AY13: =0.05*(AV13-AW13) -> 207.975 | AZ13: =0.1*(AX13) -> 0 | BB13: =( (AV13 -AW13) + AY13) + (AX13 + AZ13 ) + SUM(BA13) -> 4367.475 | BC13: =SHARES!CC10 -> 5400 | BE13: =BB13 -> 4367.475 | BF13: =SHARES!AU10 -> 300 | BG13: =SHARES!AY10 | BH13: =0.05*(BE13-BF13) -> 203.37375 | BI13: =0.1*(BG13) -> 0 | BK13: =( (BE13 -BF13) + BH13) + (BG13 + BI13 ) + SUM(BJ13) -> 4270.8488 | BL13: =SHARES!CC10 -> 5400 | BN13: =BK13 -> 4270.8488 | BO13: =SHARES!BB10 -> 0 | BP13: =SHARES!BF10 | BQ13: =0.05*(BN13-BO13) -> 213.54244 | BR13: =0.1*(BP13) -> 0 | BT13: =( (BN13 -BO13) + BQ13) + (BP13 + BR13 ) + SUM(BS13) -> 4484.3912 | BU13: =SHARES!CC10 -> 5400 | BW13: =BT13 -> 4484.3912 | BX13: =SHARES!BI10 -> 1000 | BY13: =SHARES!BM10 | BZ13: =0.05*(BW13-BX13) -> 174.21956 | CA13: =0.1*(BY13) -> 0 | CC13: =( (BW13 -BX13) + BZ13) + (BY13 + CA13 ) + SUM(CB13) -> 3658.6107 | CD13: =SHARES!CC10 -> 5400 | CF13: =CC13 -> 3658.6107 | CG13: =SHARES!BN10 -> 0 | CH13: 0 | CI13: 0 | CJ13: 0 | CK13: =0.1*(CH13) -> 0 | CM13: =( (CF13 -CG13) + CJ13) + (CH13 + CJ13 + CK13 ) + SUM(CL13) -> 3658.6107 | CN13: =SHARES!CC10 -> 5400 | CP13: =CM13 -> 3658.6107 | CQ13: =SHARES!BQ10 -> 647 | CS13: 0 | CT13: =0.1*(CR13) -> 0 | CV13: =( (CP13 -CQ13) + CS13) + (CR13 + CT13 ) + SUM(CU13) -> 3011.6107 | CW13: =SHARES!CC10 -> 5400 | CY13: =CV13 -> 3011.6107 | CZ13: =SHARES!BT10 -> 0 | DB13: 0 | DC13: =0.1*(DA13) -> 0 | DE13: =( (CY13 -CZ13) + DB13) + (DA13 + DC13 ) + SUM(DD13) -> 3011.6107 | DF13: =SHARES!CC10 -> 5400
A14: 9 | B14: Lesa Chisanga | C14: 0 | D14: =SHARES!E11 | E14: =SHARES!I11 | F14: =0.05*(C14-D14) -> 0 | G14: =0.1*(E14) -> 0 | I14: =( (C14 -D14) + F14) + (E14 + G14 ) + SUM(H14) -> 0 | J14: =SHARES!CC11 -> 4200 | L14: =I14 -> 0 | M14: =SHARES!L11 | N14: =SHARES!P11 -> 900 | O14: =0.05*(L14-M14) -> 0 | P14: =0.1*(N14) -> 90 | R14: =( (L14 -M14) + O14) + (N14 + P14 ) + SUM(Q14) -> 990 | S14: =SHARES!CC11 -> 4200 | U14: =R14 -> 990 | V14: =SHARES!S11 -> 0 | W14: =SHARES!W11 | X14: =0.05*(U14-V14) -> 49.5 | Y14: =0.1*(W14) -> 0 | AA14: =( (U14 -V14) + X14) + (W14 + Y14 ) + SUM(Z14) -> 1039.5 | AB14: =SHARES!CC11 -> 4200 | AD14: =AA14 -> 1039.5 | AE14: =SHARES!Z11 -> 200 | AF14: =SHARES!AD11 -> 580 | AG14: =0.05*(AD14-AE14) -> 41.975 | AH14: =0.1*(AF14) -> 58 | AJ14: =( (AD14 -AE14) + AG14) + (AF14 + AH14 ) + SUM(AI14) -> 1519.475 | AK14: =SHARES!CC11 -> 4200 | AM14: =AJ14 -> 1519.475 | AN14: =SHARES!AG11 -> 200 | AO14: =SHARES!AK11 | AP14: =0.05*(AM14-AN14) -> 65.97375 | AQ14: =0.1*(AO14) -> 0 | AS14: =( (AM14 -AN14) + AP14) + (AO14 + AQ14 ) + SUM(AR14) -> 1385.4488 | AT14: =SHARES!CC11 -> 4200 | AV14: =AS14 -> 1385.4488 | AW14: =SHARES!AN11 -> 200 | AX14: =SHARES!AR11 -> 3000 | AY14: =0.05*(AV14-AW14) -> 59.272438 | AZ14: =0.1*(AX14) -> 300 | BB14: =( (AV14 -AW14) + AY14) + (AX14 + AZ14 ) + SUM(BA14) -> 4544.7212 | BC14: =SHARES!CC11 -> 4200 | BE14: =BB14 -> 4544.7212 | BF14: =SHARES!AU11 -> 500 | BG14: =SHARES!AY11 | BH14: =0.05*(BE14-BF14) -> 202.23606 | BI14: =0.1*(BG14) -> 0 | BK14: =( (BE14 -BF14) + BH14) + (BG14 + BI14 ) + SUM(BJ14) -> 4246.9572 | BL14: =SHARES!CC11 -> 4200 | BN14: =BK14 -> 4246.9572 | BO14: =SHARES!BB11 -> 200 | BP14: =SHARES!BF11 -> 500 | BQ14: =0.05*(BN14-BO14) -> 202.34786 | BR14: =0.1*(BP14) -> 50 | BT14: =( (BN14 -BO14) + BQ14) + (BP14 + BR14 ) + SUM(BS14) -> 4799.3051 | BU14: =SHARES!CC11 -> 4200 | BW14: =BT14 -> 4799.3051 | BX14: =SHARES!BI11 -> 200 | BY14: =SHARES!BM11 | BZ14: =0.05*(BW14-BX14) -> 229.96526 | CA14: =0.1*(BY14) -> 0 | CC14: =( (BW14 -BX14) + BZ14) + (BY14 + CA14 ) + SUM(CB14) -> 4829.2704 | CD14: =SHARES!CC11 -> 4200 | CF14: =CC14 -> 4829.2704 | CG14: =SHARES!BN11 -> 500 | CH14: 0 | CI14: 0 | CJ14: 0 | CK14: =0.1*(CH14) -> 0 | CM14: =( (CF14 -CG14) + CJ14) + (CH14 + CJ14 + CK14 ) + SUM(CL14) -> 4329.2704 | CN14: =SHARES!CC11 -> 4200 | CP14: =CM14 -> 4329.2704 | CQ14: =SHARES!BQ11 -> 1000 | CS14: 0 | CT14: =0.1*(CR14) -> 0 | CV14: =( (CP14 -CQ14) + CS14) + (CR14 + CT14 ) + SUM(CU14) -> 3329.2704 | CW14: =SHARES!CC11 -> 4200 | CY14: =CV14 -> 3329.2704 | CZ14: =SHARES!BT11 -> 0 | DB14: 0 | DC14: =0.1*(DA14) -> 0 | DE14: =( (CY14 -CZ14) + DB14) + (DA14 + DC14 ) + SUM(DD14) -> 3329.2704 | DF14: =SHARES!CC11 -> 4200
A15: 10 | B15: Michelle Nangandu | C15: 0 | D15: =SHARES!E12 | E15: =SHARES!I12 | F15: =0.05*(C15-D15) -> 0 | G15: =0.1*(E15) -> 0 | I15: =( (C15 -D15) + F15) + (E15 + G15 ) + SUM(H15) -> 0 | J15: =SHARES!CC12 -> 3600 | L15: =I15 -> 0 | M15: =SHARES!L12 | N15: =SHARES!P12 | O15: =0.05*(L15-M15) -> 0 | P15: =0.1*(N15) -> 0 | R15: =( (L15 -M15) + O15) + (N15 + P15 ) + SUM(Q15) -> 0 | S15: =SHARES!CC12 -> 3600 | U15: =R15 -> 0 | V15: =SHARES!S12 | W15: =SHARES!W12 | X15: =0.05*(U15-V15) -> 0 | Y15: =0.1*(W15) -> 0 | AA15: =( (U15 -V15) + X15) + (W15 + Y15 ) + SUM(Z15) -> 0 | AB15: =SHARES!CC12 -> 3600 | AD15: =AA15 -> 0 | AE15: =SHARES!Z12 | AF15: =SHARES!AD12 | AG15: =0.05*(AD15-AE15) -> 0 | AH15: =0.1*(AF15) -> 0 | AJ15: =( (AD15 -AE15) + AG15) + (AF15 + AH15 ) + SUM(AI15) -> 0 | AK15: =SHARES!CC12 -> 3600 | AM15: =AJ15 -> 0 | AN15: =SHARES!AG12 | AO15: =SHARES!AK12 -> 5000 | AP15: =0.05*(AM15-AN15) -> 0 | AQ15: =0.1*(AO15) -> 500 | AS15: =( (AM15 -AN15) + AP15) + (AO15 + AQ15 ) + SUM(AR15) -> 5500 | AT15: =SHARES!CC12 -> 3600 | AV15: =AS15 -> 5500 | AW15: =SHARES!AN12 -> 200 | AX15: =SHARES!AR12 | AY15: =0.05*(AV15-AW15) -> 265 | AZ15: =0.1*(AX15) -> 0 | BB15: =( (AV15 -AW15) + AY15) + (AX15 + AZ15 ) + SUM(BA15) -> 5565 | BC15: =SHARES!CC12 -> 3600 | BE15: =BB15 -> 5565 | BF15: =SHARES!AU12 | BG15: =SHARES!AY12 | BH15: =0.05*(BE15-BF15) -> 278.25 | BI15: =0.1*(BG15) -> 0 | BK15: =( (BE15 -BF15) + BH15) + (BG15 + BI15 ) + SUM(BJ15) -> 5843.25 | BL15: =SHARES!CC12 -> 3600 | BN15: =BK15 -> 5843.25 | BO15: =SHARES!BB12 -> 1000 | BP15: =SHARES!BF12 | BQ15: =0.05*(BN15-BO15) -> 242.1625 | BR15: =0.1*(BP15) -> 0 | BT15: =( (BN15 -BO15) + BQ15) + (BP15 + BR15 ) + SUM(BS15) -> 5085.4125 | BU15: =SHARES!CC12 -> 3600 | BW15: =BT15 -> 5085.4125 | BX15: =SHARES!BI12 -> 400 | BY15: =SHARES!BM12 | BZ15: =0.05*(BW15-BX15) -> 234.27062 | CA15: =0.1*(BY15) -> 0 | CC15: =( (BW15 -BX15) + BZ15) + (BY15 + CA15 ) + SUM(CB15) -> 4919.6831 | CD15: =SHARES!CC12 -> 3600 | CF15: =CC15 -> 4919.6831 | CG15: =SHARES!BN12 -> 0 | CH15: 0 | CI15: 0 | CJ15: 0 | CK15: =0.1*(CH15) -> 0 | CM15: =( (CF15 -CG15) + CJ15) + (CH15 + CJ15 + CK15 ) + SUM(CL15) -> 4919.6831 | CN15: =SHARES!CC12 -> 3600 | CP15: =CM15 -> 4919.6831 | CQ15: =SHARES!BQ12 -> 2950 | CS15: 0 | CT15: =0.1*(CR15) -> 0 | CV15: =( (CP15 -CQ15) + CS15) + (CR15 + CT15 ) + SUM(CU15) -> 1969.6831 | CW15: =SHARES!CC12 -> 3600 | CY15: =CV15 -> 1969.6831 | CZ15: =SHARES!BT12 -> 0 | DB15: 0 | DC15: =0.1*(DA15) -> 0 | DE15: =( (CY15 -CZ15) + DB15) + (DA15 + DC15 ) + SUM(DD15) -> 1969.6831 | DF15: =SHARES!CC12 -> 3600
A16: 11 | B16: Rosemary Kalikoga | C16: 0 | D16: =SHARES!E13 | E16: =SHARES!I13 | F16: =0.05*(C16-D16) -> 0 | G16: =0.1*(E16) -> 0 | I16: =( (C16 -D16) + F16) + (E16 + G16 ) + SUM(H16) -> 0 | J16: =SHARES!CC13 -> 2400 | L16: =I16 -> 0 | M16: =SHARES!L13 | N16: =SHARES!P13 | O16: =0.05*(L16-M16) -> 0 | P16: =0.1*(N16) -> 0 | R16: =( (L16 -M16) + O16) + (N16 + P16 ) + SUM(Q16) -> 0 | S16: =SHARES!CC13 -> 2400 | U16: =R16 -> 0 | V16: =SHARES!S13 | W16: =SHARES!W13 | X16: =0.05*(U16-V16) -> 0 | Y16: =0.1*(W16) -> 0 | AA16: =( (U16 -V16) + X16) + (W16 + Y16 ) + SUM(Z16) -> 0 | AB16: =SHARES!CC13 -> 2400 | AD16: =AA16 -> 0 | AE16: =SHARES!Z13 | AF16: =SHARES!AD13 | AG16: =0.05*(AD16-AE16) -> 0 | AH16: =0.1*(AF16) -> 0 | AJ16: =( (AD16 -AE16) + AG16) + (AF16 + AH16 ) + SUM(AI16) -> 0 | AK16: =SHARES!CC13 -> 2400 | AM16: =AJ16 -> 0 | AN16: =SHARES!AG13 | AO16: =SHARES!AK13 | AP16: =0.05*(AM16-AN16) -> 0 | AQ16: =0.1*(AO16) -> 0 | AS16: =( (AM16 -AN16) + AP16) + (AO16 + AQ16 ) + SUM(AR16) -> 0 | AT16: =SHARES!CC13 -> 2400 | AV16: =AS16 -> 0 | AW16: =SHARES!AN13 | AX16: =SHARES!AR13 -> 1500 | AY16: =0.05*(AV16-AW16) -> 0 | AZ16: =0.1*(AX16) -> 150 | BB16: =( (AV16 -AW16) + AY16) + (AX16 + AZ16 ) + SUM(BA16) -> 1650 | BC16: =SHARES!CC13 -> 2400 | BE16: =BB16 -> 1650 | BF16: =SHARES!AU13 -> 500 | BG16: =SHARES!AY13 | BH16: =0.05*(BE16-BF16) -> 57.5 | BI16: =0.1*(BG16) -> 0 | BK16: =( (BE16 -BF16) + BH16) + (BG16 + BI16 ) + SUM(BJ16) -> 1207.5 | BL16: =SHARES!CC13 -> 2400 | BN16: =BK16 -> 1207.5 | BO16: =SHARES!BB13 -> 0 | BP16: =SHARES!BF13 | BQ16: =0.05*(BN16-BO16) -> 60.375 | BR16: =0.1*(BP16) -> 0 | BT16: =( (BN16 -BO16) + BQ16) + (BP16 + BR16 ) + SUM(BS16) -> 1267.875 | BU16: =SHARES!CC13 -> 2400 | BW16: =BT16 -> 1267.875 | BX16: =SHARES!BI13 -> 633 | BY16: =SHARES!BM13 | BZ16: =0.05*(BW16-BX16) -> 31.74375 | CA16: =0.1*(BY16) -> 0 | CC16: =( (BW16 -BX16) + BZ16) + (BY16 + CA16 ) + SUM(CB16) -> 666.61875 | CD16: =SHARES!CC13 -> 2400 | CF16: =CC16 -> 666.61875 | CG16: =SHARES!BN13 -> 770 | CH16: 0 | CI16: 0 | CJ16: 0 | CK16: =0.1*(CH16) -> 0 | CM16: =( (CF16 -CG16) + CJ16) + (CH16 + CJ16 + CK16 ) + SUM(CL16) -> -103.38125 | CN16: =SHARES!CC13 -> 2400 | CP16: =CM16 -> -103.38125 | CQ16: =SHARES!BQ13 -> 0 | CS16: 0 | CT16: =0.1*(CR16) -> 0 | CV16: =( (CP16 -CQ16) + CS16) + (CR16 + CT16 ) + SUM(CU16) -> -103.38125 | CW16: =SHARES!CC13 -> 2400 | CY16: =CV16 -> -103.38125 | CZ16: =SHARES!BT13 -> 0 | DB16: 0 | DC16: =0.1*(DA16) -> 0 | DE16: =( (CY16 -CZ16) + DB16) + (DA16 + DC16 ) + SUM(DD16) -> -103.38125 | DF16: =SHARES!CC13 -> 2400
A17: 12 | D17: =SHARES!E14 | E17: =SHARES!I14 | F17: =0.05*(C17-D17) -> 0 | G17: =0.1*(E17) -> 0 | I17: =( (C17 -D17) + F17) + (E17 + G17 ) + SUM(H17) -> 0 | J17: =SHARES!CC14 -> 600 | L17: =I17 -> 0 | M17: =SHARES!L14 | N17: =SHARES!P14 | O17: =0.05*(L17-M17) -> 0 | P17: =0.1*(N17) -> 0 | R17: =( (L17 -M17) + O17) + (N17 + P17 ) + SUM(Q17) -> 0 | S17: =SHARES!CC14 -> 600 | U17: =R17 -> 0 | V17: =SHARES!S14 | W17: =SHARES!W14 | X17: =0.05*(U17-V17) -> 0 | Y17: =0.1*(W17) -> 0 | AA17: =( (U17 -V17) + X17) + (W17 + Y17 ) + SUM(Z17) -> 0 | AB17: =SHARES!CC14 -> 600 | AD17: =AA17 -> 0 | AE17: =SHARES!Z14 | AF17: =SHARES!AD14 | AG17: =0.05*(AD17-AE17) -> 0 | AH17: =0.1*(AF17) -> 0 | AJ17: =( (AD17 -AE17) + AG17) + (AF17 + AH17 ) + SUM(AI17) -> 0 | AK17: =SHARES!CC14 -> 600 | AM17: =AJ17 -> 0 | AN17: =SHARES!AG14 | AO17: =SHARES!AK14 | AP17: =0.05*(AM17-AN17) -> 0 | AQ17: =0.1*(AO17) -> 0 | AS17: =( (AM17 -AN17) + AP17) + (AO17 + AQ17 ) + SUM(AR17) -> 0 | AT17: =SHARES!CC14 -> 600 | AV17: =AS17 -> 0 | AW17: =SHARES!AN14 | AX17: =SHARES!AR14 | AY17: =0.05*(AV17-AW17) -> 0 | AZ17: =0.1*(AX17) -> 0 | BB17: =( (AV17 -AW17) + AY17) + (AX17 + AZ17 ) + SUM(BA17) -> 0 | BC17: =SHARES!CC14 -> 600 | BE17: =BB17 -> 0 | BF17: =SHARES!AU14 | BG17: =SHARES!AY14 | BH17: =0.05*(BE17-BF17) -> 0 | BI17: =0.1*(BG17) -> 0 | BK17: =( (BE17 -BF17) + BH17) + (BG17 + BI17 ) + SUM(BJ17) -> 0 | BL17: =SHARES!CC14 -> 600 | BN17: =BK17 -> 0 | BO17: =SHARES!BB14 -> 0 | BP17: =SHARES!BF14 | BQ17: =0.05*(BN17-BO17) -> 0 | BR17: =0.1*(BP17) -> 0 | BT17: =( (BN17 -BO17) + BQ17) + (BP17 + BR17 ) + SUM(BS17) -> 0 | BU17: =SHARES!CC14 -> 600 | BW17: =BT17 -> 0 | BX17: =SHARES!BI14 -> 0 | BY17: =SHARES!BM14 | BZ17: =0.05*(BW17-BX17) -> 0 | CA17: =0.1*(BY17) -> 0 | CC17: =( (BW17 -BX17) + BZ17) + (BY17 + CA17 ) + SUM(CB17) -> 0 | CD17: =SHARES!CC14 -> 600 | CF17: =CC17 -> 0 | CG17: =SHARES!BN14 -> 0 | CH17: 0 | CI17: 0 | CJ17: 0 | CK17: =0.1*(CH17) -> 0 | CM17: =( (CF17 -CG17) + CJ17) + (CH17 + CJ17 + CK17 ) + SUM(CL17) -> 0 | CN17: =SHARES!CC14 -> 600 | CP17: =CM17 -> 0 | CQ17: =SHARES!BQ14 -> 0 | CS17: 0 | CT17: =0.1*(CR17) -> 0 | CV17: =( (CP17 -CQ17) + CS17) + (CR17 + CT17 ) + SUM(CU17) -> 0 | CW17: =SHARES!CC14 -> 600 | CY17: =CV17 -> 0 | CZ17: =SHARES!BT14 -> 0 | DB17: 0 | DC17: =0.1*(DA17) -> 0 | DE17: =( (CY17 -CZ17) + DB17) + (DA17 + DC17 ) + SUM(DD17) -> 0 | DF17: =SHARES!CC14 -> 600
C18: 0 | E18: =SUM(E6:E17) -> 1800 | F18: =SUM(F6:F17) -> 0 | G18: =SUM(G6:G17) -> 180 | I18: =SUM(I6:I17) -> 1980 | J18: =SUM(J6:J17) -> 62100 | K18: =SUM(K6:K17) -> 0 | L18: =SUM(L6:L17) -> 1980 | M18: =SUM(M6:M17) -> 0 | N18: =SUM(N6:N17) -> 3000 | O18: =SUM(O6:O17) -> 99 | P18: =SUM(P6:P17) -> 300 | R18: =SUM(R6:R17) -> 5379 | S18: =SUM(S6:S17) -> 62100 | T18: =SUM(T6:T17) -> 0 | U18: =SUM(U6:U17) -> 5379 | V18: =SUM(V6:V17) -> 400 | W18: =SUM(W6:W17) -> 2800 | X18: =SUM(X6:X17) -> 248.95 | Y18: =SUM(Y6:Y17) -> 280 | AA18: =SUM(AA6:AA17) -> 8307.95 | AB18: =SUM(AB6:AB17) -> 62100 | AC18: =SUM(AC6:AC17) -> 0 | AD18: =SUM(AD6:AD17) -> 8307.95 | AE18: =SUM(AE6:AE17) -> 1180 | AF18: =SUM(AF6:AF17) -> 4480 | AG18: =SUM(AG6:AG17) -> 356.3975 | AH18: =SUM(AH6:AH17) -> 448 | AJ18: =SUM(AJ6:AJ17) -> 12412.347 | AK18: =SUM(AK6:AK17) -> 62100 | AL18: =SUM(AL6:AL17) -> 0 | AM18: =SUM(AM6:AM17) -> 12412.347 | AN18: =SUM(AN6:AN17) -> 5328 | AO18: =SUM(AO6:AO17) -> 9828 | AP18: =SUM(AP6:AP17) -> 354.21738 | AQ18: =SUM(AQ6:AQ17) -> 982.8 | AS18: =SUM(AS6:AS17) -> 18249.365 | AT18: =SUM(AT6:AT17) -> 62100 | AU18: =SUM(AU6:AU17) -> 0 | AV18: =SUM(AV6:AV17) -> 18249.365 | AW18: =SUM(AW6:AW17) -> 2100 | AX18: =SUM(AX6:AX17) -> 6000 | AY18: =SUM(AY6:AY17) -> 807.46824 | AZ18: =SUM(AZ6:AZ17) -> 600 | BB18: =SUM(BB6:BB17) -> 23556.833 | BC18: =SUM(BC6:BC17) -> 62100 | BD18: =SUM(BD6:BD17) -> 0 | BE18: =SUM(BE6:BE17) -> 23556.833 | BF18: =SUM(BF6:BF17) -> 2651.45 | BG18: =SUM(BG6:BG17) -> 6151.45 | BH18: =SUM(BH6:BH17) -> 1045.2692 | BI18: =SUM(BI6:BI17) -> 615.145 | BK18: =SUM(BK6:BK17) -> 28717.247 | BL18: =SUM(BL6:BL17) -> 62100 | BM18: =SUM(BM6:BM17) -> 0 | BN18: =SUM(BN6:BN17) -> 28717.247 | BO18: =SUM(BO6:BO17) -> 1400 | BP18: =SUM(BP6:BP17) -> 3300 | BQ18: =SUM(BQ6:BQ17) -> 1365.8624 | BR18: =SUM(BR6:BR17) -> 330 | ... CI18: =SUM(CI6:CI17) -> 0 | CJ18: 0 | CK18: =SUM(CK6:CK17) -> 0 | CL18: =SUM(CL6:CL17) -> 0 | CM18: =SUM(CM6:CM17) -> 29491.596 | CN18: =SUM(CN6:CN17) -> 62100 | CO18: =SUM(CO6:CO17) -> 0 | CP18: =SUM(CP6:CP17) -> 29491.596 | CQ18: =SUM(CQ6:CQ17) -> 7197 | CR18: =SUM(CR6:CR17) -> 0 | ... CW18: =SUM(CW6:CW17) -> 62100 | CX18: =CZ20 | CY18: =SUM(CY6:CY17) -> 22294.596 | CZ18: =SUM(CZ6:CZ17) -> 0 | DA18: =SUM(DA6:DA17) -> 0 | DB18: =SUM(DB6:DB17) -> 0 | DC18: =SUM(DC6:DC17) -> 0 | DE18: =SUM(DE6:DE17) -> 22294.596 | DF18: =SUM(DF6:DF17) -> 62100

Sheet INVESTMENT
E1: SHUBART N | I1: PETER | M1: JAILOS D | Q1: GABRIEL N | U1: DANIEL B | Y1: FAIDES N | AC1: CLARA M | AG1: MAUREEN L | AK1: LESA | AO1: NANGANDU M | AS1: ROSEMARY K | AW1: OSWARD N
F2: Vbank24 | G2: Interest | J2: Vbank24 | K2: Interest | N2: Vbank24 | O2: Interest | R2: Vbank24 | S2: Interest | V2: Vbank24 | W2: Interest | Z2: Vbank24 | AA2: Interest | AD2: Vbank24 | AE2: Interest | AH2: Vbank24 | AI2: Interest | AL2: Vbank24 | AM2: Interest | AP2: Vbank24 | AQ2: Interest | AT2: Vbank24 | AU2: Interest | AX2: Vbank24 | AY2: Interest
E4: FEBRUARY | F4: =SHARES!D3 -> 200 | I4: FEBRUARY | J4: =SHARES!D4 -> 500 | M4: FEBRUARY | N4: =SHARES!D5 -> 200 | Q4: FEBRUARY | R4: =SHARES!D6 -> 0 | U4: FEBRUARY | V4: =SHARES!D7 -> 200 | Y4: FEBRUARY | Z4: =SHARES!D8 -> 200 | AC4: FEBRUARY | AD4: =SHARES!D9 -> 200 | AG4: MARCH | AH4: =SHARES!D10 -> 0 | AK4: MARCH | AL4: =SHARES!D11 -> 0 | AO4: MARCH | AP4: =SHARES!D12 -> 0 | AS4: MARCH | AT4: =SHARES!D13 -> 0 | AW4: MARCH | AX4: =SHARES!D14
E5: MARCH | F5: =F4*1.1 -> 220 | G5: =F4*0.1 -> 20 | I5: MARCH | J5: =J4*1.1 -> 550 | K5: =J4*0.1 -> 50 | M5: MARCH | N5: =N4*1.1 -> 220 | O5: =N4*0.1 -> 20 | Q5: MARCH | R5: =R4*1.1 -> 0 | S5: =R4*0.1 -> 0 | U5: MARCH | V5: =V4*1.1 -> 220 | W5: =V4*0.1 -> 20 | Y5: MARCH | Z5: =Z4*1.1 -> 220 | AA5: =Z4*0.1 -> 20 | AC5: MARCH | AD5: =AD4*1.1 -> 220 | AE5: =AD4*0.1 -> 20 | AG5: APRIL | AH5: =AH4*1.1 -> 0 | AI5: =AH4*0.1 -> 0 | AK5: APRIL | AL5: =AL4*1.1 -> 0 | AM5: =AL4*0.1 -> 0 | AO5: APRIL | AP5: =AP4*1.1 -> 0 | AQ5: =AP4*0.1 -> 0 | AS5: APRIL | AT5: =AT4*1.1 -> 0 | AU5: =AT4*0.1 -> 0 | AW5: APRIL | AX5: =AX4*1.1 -> 0 | AY5: =AX4*0.1 -> 0
E6: APRIL | F6: =F5*1.05 -> 231 | G6: =F5*0.05 -> 11 | I6: APRIL | J6: =J5*1.05 -> 577.5 | K6: =J5*0.05 -> 27.5 | M6: APRIL | N6: =N5*1.05 -> 231 | O6: =N5*0.05 -> 11 | Q6: APRIL | R6: =R5*1.05 -> 0 | S6: =R5*0.05 -> 0 | U6: APRIL | V6: =V5*1.05 -> 231 | W6: =V5*0.05 -> 11 | Y6: APRIL | Z6: =Z5*1.05 -> 231 | AA6: =Z5*0.05 -> 11 | AC6: APRIL | AD6: =AD5*1.05 -> 231 | AE6: =AD5*0.05 -> 11 | AG6: MAY | AH6: =AH5*1.05 -> 0 | AI6: =AH5*0.05 -> 0 | AK6: MAY | AL6: =AL5*1.05 -> 0 | AM6: =AL5*0.05 -> 0 | AO6: MAY | AP6: =AP5*1.05 -> 0 | AQ6: =AP5*0.05 -> 0 | AS6: MAY | AT6: =AT5*1.05 -> 0 | AU6: =AT5*0.05 -> 0 | AW6: MAY | AX6: =AX5*1.05 -> 0 | AY6: =AX5*0.05 -> 0
